<?xml version='1.0' encoding='utf-8'?>
<robot name="h1_5">

  <!-- [CAUTION] uncomment when convert to mujoco -->
  <!-- <link name="world"></link>
  <joint name="floating_base_joint" type="floating">
    <parent link="world"/>
    <child link="pelvis"/>
  </joint> -->

  <link name="pelvis">
    <inertial>
      <origin xyz="-0.0004 3.7E-05 -0.046864" rpy="0 0 0" />
      <mass value="5.983" />
      <inertia ixx="49168.411E-06" ixy="-19.869E-06" ixz="-48.460E-06" iyy="9025.844E-06" iyz="3.431E-06" izz="53155.891E-06" />
    </inertial>
    </link>

  <!-- L Leg -->
  <link name="left_hip_yaw_link">
    <inertial>
      <origin xyz="0 -0.026197 0.006647" rpy="0 0 0" />
      <mass value="2.829" />
      <inertia ixx="4553.605E-06" ixy="0.005E-06" ixz="0.817E-06" iyy="5688.730E-06" iyz="-345.157E-06" izz="3548.907E-06" />
    </inertial>
    </link>
  <joint name="left_hip_yaw_joint" type="revolute">
    <origin xyz="0 0.0875 -0.1632" rpy="0 0 0" />
    <parent link="pelvis" />
    <child link="left_hip_yaw_link" />
    <axis xyz="0 0 1" />
    <limit lower="-0.43" upper="0.43" effort="200" velocity="23" />
  </joint>
  <link name="left_hip_pitch_link">
    <inertial>
      <origin xyz="-0.00781 -0.004724 -0.000063" rpy="0 0 0" />
      <mass value="2.920" />
      <inertia ixx="5594.7E-06" ixy="143.308E-06" ixz="-11.847E-06" iyy="3862.581E-06" iyz="-9.607E-06" izz="4450.563E-06" />
    </inertial>
    </link>
  <joint name="left_hip_pitch_joint" type="revolute">
    <origin xyz="0 0.0755 0" rpy="0 0 0" />
    <parent link="left_hip_yaw_link" />
    <child link="left_hip_pitch_link" />
    <axis xyz="0 1 0" />
    <limit lower="-3.14" upper="2.5" effort="200" velocity="23" />
  </joint>
  <link name="left_hip_roll_link">
    <inertial>
      <origin xyz="0.004171 -0.008576 -0.194509" rpy="0 0 0" />
      <mass value="4.962" />
      <inertia ixx="46305.869E-06" ixy="-322.626E-06" ixz="-1199.703E-06" iyy="47955.402E-06" iyz="288.147E-06" izz="8914.518E-06" />
    </inertial>
    </link>
  <joint name="left_hip_roll_joint" type="revolute">
    <origin xyz="0 0 0" rpy="0 0 0" />
    <parent link="left_hip_pitch_link" />
    <child link="left_hip_roll_link" />
    <axis xyz="1 0 0" />
    <limit lower="-0.43" upper="3.14" effort="200" velocity="23" />
  </joint>
  <link name="left_knee_link">
    <inertial>
      <origin xyz="0.000179 0.000121 -0.168936" rpy="0 0 0" />
      <mass value="3.839" />
      <inertia ixx="39002.363e-6" ixy="-72.364e-6" ixz="-794.506e-6" iyy="39042.376e-6" iyz="-18.663e-6" izz="5029.829e-6" />
    </inertial>
    </link>
  <joint name="left_knee_joint" type="revolute">
    <origin xyz="0 0 -0.4" rpy="0 0 0" />
    <parent link="left_hip_roll_link" />
    <child link="left_knee_link" />
    <axis xyz="0 1 0" />
    <limit lower="-0.26" upper="2.05" effort="300" velocity="14" />
  </joint>
  <link name="left_ankle_pitch_link">
    <inertial>
      <origin xyz="-0.000294 0 -0.010794" rpy="0 0 0" />
      <mass value="0.102" />
      <inertia ixx="0.000023944" ixy="0" ixz="0.000000121" iyy="0.000021837" iyz="0" izz="0.000013414" />
    </inertial>
    </link>
  <joint name="left_ankle_pitch_joint" type="revolute">
    <origin xyz="0 0 -0.4" rpy="0 0 0" />
    <parent link="left_knee_link" />
    <child link="left_ankle_pitch_link" />
    <axis xyz="0 1 0" />
    <limit lower="-0.897334" upper="0.523598" effort="60" velocity="9" />
  </joint>
  <link name="left_ankle_roll_link">
    <inertial>
      <origin xyz="0.029589 0 -0.015973" rpy="0 0 0" />
      <mass value="0.747" />
      <inertia ixx="648.830e-6" ixy="0" ixz="158.380e-6" iyy="3435.339e-6" iyz="0" izz="3583.259e-6" />
    </inertial>
    </link>
  <joint name="left_ankle_roll_joint" type="revolute">
    <origin xyz="0 0 -0.02" rpy="0 0 0" />
    <parent link="left_ankle_pitch_link" />
    <child link="left_ankle_roll_link" />
    <axis xyz="1 0 0" />
    <limit lower="-0.261799" upper="0.261799" effort="40" velocity="9" />
  </joint>

  <!-- R Leg -->
  <link name="right_hip_yaw_link">
    <inertial>
      <origin xyz="0 0.026197 0.006647" rpy="0 0 0" />
      <mass value="2.829" />
      <inertia ixx="4553.605E-06" ixy="-0.005E-06" ixz="0.817E-06" iyy="5688.730E-06" iyz="345.157E-06" izz="3548.907E-06" />
    </inertial>
    </link>
  <joint name="right_hip_yaw_joint" type="revolute">
    <origin xyz="0 -0.0875 -0.1632" rpy="0 0 0" />
    <parent link="pelvis" />
    <child link="right_hip_yaw_link" />
    <axis xyz="0 0 1" />
    <limit lower="-0.43" upper="0.43" effort="200" velocity="23" />
  </joint>
  <link name="right_hip_pitch_link">
    <inertial>
      <origin xyz="-0.00781 0.004724 -0.000063" rpy="0 0 0" />
      <mass value="2.920" />
      <inertia ixx="5594.7E-06" ixy="-143.308E-06" ixz="-11.847E-06" iyy="3862.581E-06" iyz="9.607E-06" izz="4450.563E-06" />
    </inertial>
    </link>
  <joint name="right_hip_pitch_joint" type="revolute">
    <origin xyz="0 -0.0755 0" rpy="0 0 0" />
    <parent link="right_hip_yaw_link" />
    <child link="right_hip_pitch_link" />
    <axis xyz="0 1 0" />
    <limit lower="-3.14" upper="2.5" effort="200" velocity="23" />
  </joint>
  <link name="right_hip_roll_link">
    <inertial>
      <origin xyz="0.004171 0.008576 -0.194509" rpy="0 0 0" />
      <mass value="4.962" />
      <inertia ixx="46305.869E-06" ixy="322.626E-06" ixz="-1199.703E-06" iyy="47955.402E-06" iyz="-288.147E-06" izz="8914.518E-06" />
    </inertial>
    </link>
  <joint name="right_hip_roll_joint" type="revolute">
    <origin xyz="0 0 0" rpy="0 0 0" />
    <parent link="right_hip_pitch_link" />
    <child link="right_hip_roll_link" />
    <axis xyz="1 0 0" />
    <limit lower="-3.14" upper="0.43" effort="200" velocity="23" />
  </joint>
  <link name="right_knee_link">
    <inertial>
      <origin xyz="0.000179 -0.000121 -0.168936" rpy="0 0 0" />
      <mass value="3.839" />
      <inertia ixx="39002.363e-6" ixy="72.364e-6" ixz="-794.506e-6" iyy="39042.376e-6" iyz="18.663e-6" izz="5029.829e-6" />
    </inertial>
    </link>
  <joint name="right_knee_joint" type="revolute">
    <origin xyz="0 0 -0.4" rpy="0 0 0" />
    <parent link="right_hip_roll_link" />
    <child link="right_knee_link" />
    <axis xyz="0 1 0" />
    <limit lower="-0.26" upper="2.05" effort="300" velocity="14" />
  </joint>
  <link name="right_ankle_pitch_link">
    <inertial>
      <origin xyz="-0.000294 0 -0.010794" rpy="0 0 0" />
      <mass value="0.102" />
      <inertia ixx="0.000023944" ixy="0" ixz="0.000000121" iyy="0.000021837" iyz="0" izz="0.000013414" />
    </inertial>
    </link>
  <joint name="right_ankle_pitch_joint" type="revolute">
    <origin xyz="0 0 -0.4" rpy="0 0 0" />
    <parent link="right_knee_link" />
    <child link="right_ankle_pitch_link" />
    <axis xyz="0 1 0" />
    <limit lower="-0.897334" upper="0.523598" effort="60" velocity="9" />
  </joint>
  <link name="right_ankle_roll_link">
    <inertial>
      <origin xyz="0.029589 0 -0.015973" rpy="0 0 0" />
      <mass value="0.747" />
      <inertia ixx="648.830e-6" ixy="0" ixz="158.380e-6" iyy="3435.339e-6" iyz="0" izz="3583.259e-6" />
    </inertial>
    </link>
  <joint name="right_ankle_roll_joint" type="revolute">
    <origin xyz="0 0 -0.02" rpy="0 0 0" />
    <parent link="right_ankle_pitch_link" />
    <child link="right_ankle_roll_link" />
    <axis xyz="1 0 0" />
    <limit lower="-0.261799" upper="0.261799" effort="40" velocity="9" />
  </joint>

  <!-- Torso -->
  <link name="torso_link">
    <inertial>
      <origin xyz="0.000489 0.002797 0.20484" rpy="0 0 0" />
      <mass value="17.789" />
      <inertia ixx="0.4873" ixy="-0.00053763" ixz="0.0020276" iyy="0.40963" iyz="-0.00074582" izz="0.12785" />
    </inertial>
    </link>
  <joint name="torso_joint" type="revolute">
    <origin xyz="0 0 0" rpy="0 0 0" />
    <parent link="pelvis" />
    <child link="torso_link" />
    <axis xyz="0 0 1" />
    <limit lower="-2.35" upper="2.35" effort="200" velocity="23" />
  </joint>

  <!-- L arm -->
  <link name="left_shoulder_pitch_link">
    <inertial>
      <origin xyz="0.003053 0.06042 -0.0059" rpy="0 0 0" />
      <mass value="1.327" />
      <inertia ixx="0.00058661" ixy="-2.0157E-05" ixz="2.985E-06" iyy="0.0003989" iyz="2.238E-05" izz="0.00052936" />
    </inertial>
    </link>
  <joint name="left_shoulder_pitch_joint" type="revolute">
    <origin xyz="0 0.14806 0.42333" rpy="0.2618 0 0" />
    <parent link="torso_link" />
    <child link="left_shoulder_pitch_link" />
    <axis xyz="0 1 0" />
    <limit lower="-3.14" upper="1.57" effort="40" velocity="9" />
  </joint>
  <link name="left_shoulder_roll_link">
    <inertial>
      <origin xyz="-0.030932 -1E-06 -0.10609" rpy="0 0 0" />
      <mass value="1.393" />
      <inertia ixx="0.0018408" ixy="3.98E-07" ixz="-0.00048324" iyy="0.001934638" iyz="1.61E-07" izz="0.000617733" />
    </inertial>
    </link>
  <joint name="left_shoulder_roll_joint" type="revolute">
    <origin xyz="0.0342 0.061999 -0.0060011" rpy="-0.2618 0 0" />
    <parent link="left_shoulder_pitch_link" />
    <child link="left_shoulder_roll_link" />
    <axis xyz="1 0 0" />
    <limit lower="-0.38" upper="3.4" effort="40" velocity="9" />
  </joint>
  <link name="left_shoulder_yaw_link">
    <inertial>
      <origin xyz="0.004583 0.001128 -0.001128" rpy="0 0 0" />
      <mass value="1.505" />
      <inertia ixx="0.004199" ixy="-1.7786E-05" ixz="0.00018372" iyy="0.0043139" iyz="9.278E-05" izz="0.00065755" />
    </inertial>
    </link>
  <joint name="left_shoulder_yaw_joint" type="revolute">
    <origin xyz="-0.0342 0 -0.1456" rpy="0 0 0" />
    <parent link="left_shoulder_roll_link" />
    <child link="left_shoulder_yaw_link" />
    <axis xyz="0 0 1" />
    <limit lower="-2.66" upper="3.01" effort="18" velocity="20" />
  </joint>
  <link name="left_elbow_pitch_link">
    <inertial>
      <origin xyz="0.077092 -0.028751 -0.009714 " rpy="0 0 0" />
      <mass value="0.691" />
      <inertia ixx="0.000318491" ixy="0.000224554" ixz="6.62076E-05" iyy="0.000861224" iyz="-2.3329E-05" izz="0.000897899" />
    </inertial>
    </link>
  <joint name="left_elbow_pitch_joint" type="revolute">
    <origin xyz="0.006 0.0329 -0.182" rpy="0 0 0" />
    <parent link="left_shoulder_yaw_link" />
    <child link="left_elbow_pitch_link" />
    <axis xyz="0 1 0" />
    <limit lower="-0.95" upper="3.18" effort="18" velocity="20" />
  </joint>

  <link name="left_elbow_roll_link">
    <inertial>
      <origin xyz="0.035281 -0.002320 0.000337" rpy="0 0 0" />
      <mass value="0.683" />
      <inertia ixx="0.000313275" ixy="0.000016521" ixz="-0.000002501" iyy="0.000310412" iyz="0.000005435" izz="0.000345998" />
    </inertial>
    </link>
  <joint name="left_elbow_roll_joint" type="revolute">
    <origin xyz="0.121 -0.0329 -0.011" rpy="0 0 0" />
    <parent link="left_elbow_pitch_link" />
    <child link="left_elbow_roll_link" />
    <axis xyz="1 0 0" />
    <limit lower="-3.01" upper="2.75" effort="19" velocity="31.4" />
  </joint>

  <link name="left_wrist_pitch_link">
    <inertial>
      <origin xyz="0.020395 0.000036 -0.002973" rpy="0 0 0" />
      <mass value="0.484" />
      <inertia ixx="0.000071364" ixy="0.000000308" ixz="0.000001485" iyy="0.000069915" iyz="-0.000000088" izz="0.000070702" />
    </inertial>
    </link>
  <joint name="left_wrist_pitch_joint" type="revolute">
    <origin xyz="0.085 0 0" rpy="0 0 0" />
    <parent link="left_elbow_roll_link" />
    <child link="left_wrist_pitch_link" />
    <axis xyz="0 1 0" />
    <limit lower="-0.47" upper="0.47" effort="19" velocity="31.4" />
  </joint>
  <link name="left_wrist_yaw_link">
    <inertial>
      <origin xyz="0.027967 0.000096 0.000739" rpy="0 0 0" />
      <mass value="0.124" />
      <inertia ixx="137.3e-6" ixy="-0.171e-6" ixz="2.942e-6" iyy="169.998e-6" iyz="-0.025e-6" izz="84.808e-6" />
    </inertial>
    <!-- <collision>
      <origin xyz="0 0 0" rpy="0 0 0"/>
      <geometry>
        <mesh filename="meshes/wrist_yaw_link.STL"/>
      </geometry>
    </collision> -->
  </link>
  <joint name="left_wrist_yaw_joint" type="revolute">
    <origin xyz="0.020 0 0" rpy="0 0 0" />
    <parent link="left_wrist_pitch_link" />
    <child link="left_wrist_yaw_link" />
    <axis xyz="0 0 1" />
    <limit lower="-1.27" upper="1.27" effort="19" velocity="31.4" />
  </joint>

  <!-- R arm -->
  <link name="right_shoulder_pitch_link">
    <inertial>
      <origin xyz="0.003053 -0.06042 -0.0059" rpy="0 0 0" />
      <mass value="1.327" />
      <inertia ixx="0.00058661" ixy="2.0157E-05" ixz="2.985E-06" iyy="0.0003989" iyz="-2.238E-05" izz="0.00052936" />
    </inertial>
    </link>
  <joint name="right_shoulder_pitch_joint" type="revolute">
    <origin xyz="0 -0.14806 0.42333" rpy="-0.2618 0 0" />
    <parent link="torso_link" />
    <child link="right_shoulder_pitch_link" />
    <axis xyz="0 1 0" />
    <limit lower="-3.14" upper="1.57" effort="40" velocity="9" />
  </joint>
  <link name="right_shoulder_roll_link">
    <inertial>
      <origin xyz="-0.030932 1E-06 -0.10609" rpy="0 0 0" />
      <mass value="1.393" />
      <inertia ixx="0.0018408" ixy="-3.98E-07" ixz="-0.00048324" iyy="0.001934638" iyz="-1.61E-07" izz="0.000617733" />
    </inertial>
    </link>
  <joint name="right_shoulder_roll_joint" type="revolute">
    <origin xyz="0.0342 -0.061999 -0.0060011" rpy="0.2618 0 0" />
    <parent link="right_shoulder_pitch_link" />
    <child link="right_shoulder_roll_link" />
    <axis xyz="1 0 0" />
    <limit lower="-3.4" upper="0.38" effort="40" velocity="9" />
  </joint>
  <link name="right_shoulder_yaw_link">
    <inertial>
      <origin xyz="0.004583 -0.001128 -0.001128" rpy="0 0 0" />
      <mass value="1.505" />
      <inertia ixx="0.004199" ixy="1.7786E-05" ixz="0.00018372" iyy="0.0043139" iyz="-9.278E-05" izz="0.00065755" />

    </inertial>
    </link>
  <joint name="right_shoulder_yaw_joint" type="revolute">
    <origin xyz="-0.0342 0 -0.1456" rpy="0 0 0" />
    <parent link="right_shoulder_roll_link" />
    <child link="right_shoulder_yaw_link" />
    <axis xyz="0 0 1" />
    <limit lower="-3.01" upper="2.66" effort="18" velocity="20" />
  </joint>
  <link name="right_elbow_pitch_link">
    <inertial>
      <origin xyz="0.077092 0.028751 -0.009714 " rpy="0 0 0" />
      <mass value="0.691" />
      <inertia ixx="0.000318491" ixy="-0.000224554" ixz="6.62076E-05" iyy="0.000861224" iyz="2.3329E-05" izz="0.000897899" />
    </inertial>
    </link>
  <joint name="right_elbow_pitch_joint" type="revolute">
    <origin xyz="0.006 -0.0329 -0.182" rpy="0 0 0" />
    <parent link="right_shoulder_yaw_link" />
    <child link="right_elbow_pitch_link" />
    <axis xyz="0 1 0" />
    <limit lower="-0.95" upper="3.18" effort="18" velocity="20" />
  </joint>

  <link name="right_elbow_roll_link">
    <inertial>
      <origin xyz="0.035281 -0.002320 0.000337" rpy="0 0 0" />
      <mass value="0.683" />
      <inertia ixx="0.000313275" ixy="0.000016521" ixz="-0.000002501" iyy="0.000310412" iyz="0.000005435" izz="0.000345998" />
    </inertial>
    </link>
  <joint name="right_elbow_roll_joint" type="revolute">
    <origin xyz="0.121 0.0329 -0.011" rpy="0 0 0" />
    <parent link="right_elbow_pitch_link" />
    <child link="right_elbow_roll_link" />
    <axis xyz="1 0 0" />
    <limit lower="-2.75" upper="3.01" effort="19" velocity="31.4" />
  </joint>

  <link name="right_wrist_pitch_link">
    <inertial>
      <origin xyz="0.020395 0.000036 -0.002973" rpy="0 0 0" />
      <mass value="0.484" />
      <inertia ixx="0.000071364" ixy="0.000000308" ixz="0.000001485" iyy="0.000069915" iyz="-0.000000088" izz="0.000070702" />
    </inertial>
    </link>
  <joint name="right_wrist_pitch_joint" type="revolute">
    <origin xyz="0.085 0 0" rpy="0 0 0" />
    <parent link="right_elbow_roll_link" />
    <child link="right_wrist_pitch_link" />
    <axis xyz="0 1 0" />
    <limit lower="-0.47" upper="0.47" effort="19" velocity="31.4" />
  </joint>
  <link name="right_wrist_yaw_link">
    <inertial>
      <origin xyz="0.027967 -0.000096 0.000739" rpy="0 0 0" />
      <mass value="0.124" />
      <inertia ixx="137.3e-6" ixy="0.171e-6" ixz="2.942e-6" iyy="169.998e-6" iyz="0.025e-6" izz="84.808e-6" />
    </inertial>
    <!-- <collision>
      <origin xyz="0 0 0" rpy="0 0 0"/>
      <geometry>
        <mesh filename="meshes/wrist_yaw_link.STL"/>
      </geometry>
    </collision> -->
  </link>
  <joint name="right_wrist_yaw_joint" type="revolute">
    <origin xyz="0.020 0 0" rpy="0 0 0" />
    <parent link="right_wrist_pitch_link" />
    <child link="right_wrist_yaw_link" />
    <axis xyz="0 0 1" />
    <limit lower="-1.27" upper="1.27" effort="19" velocity="31.4" />
  </joint>

  <!-- LOGO -->
  <link name="logo_link">
    </link>
  <joint name="logo_joint" type="fixed">
    <origin xyz="0 0 0" rpy="0 0 0" />
    <parent link="torso_link" />
    <child link="logo_link" />
    <axis xyz="0 0 0" />
  </joint>

  <!-- IMU -->
  <link name="imu_link" />
  <joint name="imu_joint" type="fixed">
    <origin xyz="-0.04233868314 0.00166 0.152067" rpy="0 0 0" />
    <parent link="torso_link" />
    <child link="imu_link" />
  </joint>

  <!-- L Gripper -->
  <joint name="L_base_link_joint" type="fixed">
    <origin xyz="0.054 0 0" rpy="0 0 1.5707963267948966192313216916398" />
    <parent link="left_wrist_yaw_link" />
    <child link="L_hand_base_link" />
  </joint>
  <link name="L_hand_base_link">
    <inertial>
      <origin xyz="-0.002551 -0.066047 -0.0019357" rpy="0 0 0" />
      <mass value="0.14143" />
      <inertia ixx="0.0001234" ixy="2.1995E-06" ixz="-1.7694E-06" iyy="8.3835E-05" iyz="1.5968E-06" izz="7.7231E-05" />
    </inertial>
    </link>
  <link name="L_thumb_proximal_base">
    <inertial>
      <origin xyz="0.0048817 0.00038782 -0.00722" rpy="0 0 0" />
      <mass value="0.0018869" />
      <inertia ixx="5.5158E-08" ixy="-1.1803E-08" ixz="-4.6743E-09" iyy="8.2164E-08" iyz="-1.3521E-09" izz="6.7434E-08" />
    </inertial>
    </link>
  <joint name="L_thumb_proximal_yaw_joint" type="revolute">
    <origin xyz="-0.01696 -0.0691 0.02045" rpy="1.5708 -1.5708 0" />
    <parent link="L_hand_base_link" />
    <child link="L_thumb_proximal_base" />
    <axis xyz="0 0 1" />
    <limit lower="-0.1" upper="1.3" effort="1" velocity="0.5" />
  </joint>
  <link name="L_thumb_proximal">
    <inertial>
      <origin xyz="0.021936 -0.01279 -0.0080386" rpy="0 0 0" />
      <mass value="0.0066101" />
      <inertia ixx="1.5693E-06" ixy="7.8339E-07" ixz="8.5959E-10" iyy="1.7356E-06" iyz="1.0378E-09" izz="2.787E-06" />
    </inertial>
    </link>
  <joint name="L_thumb_proximal_pitch_joint" type="revolute">
    <origin xyz="0.0099867 0.0098242 -0.0089" rpy="-1.5708 0 0.16939" />
    <parent link="L_thumb_proximal_base" />
    <child link="L_thumb_proximal" />
    <axis xyz="0 0 -1" />
    <limit lower="-0.1" upper="0.6" effort="1" velocity="0.5" />
  </joint>
  <link name="L_thumb_intermediate">
    <inertial>
      <origin xyz="0.0095531 0.0016282 -0.0072002" rpy="0 0 0" />
      <mass value="0.0037844" />
      <inertia ixx="3.6981E-07" ixy="9.8603E-08" ixz="-2.8173E-12" iyy="3.2395E-07" iyz="-2.8028E-12" izz="4.6532E-07" />
    </inertial>
    </link>
  <joint name="L_thumb_intermediate_joint" type="revolute">
    <origin xyz="0.04407 -0.034553 -0.0008" rpy="0 0 0" />
    <parent link="L_thumb_proximal" />
    <child link="L_thumb_intermediate" />
    <axis xyz="0 0 -1" />
    <limit lower="0" upper="0.8" effort="1" velocity="0.5" />
    <mimic joint="L_thumb_proximal_pitch_joint" multiplier="1.6" offset="0" />
  </joint>
  <link name="L_thumb_distal">
    <inertial>
      <origin xyz="0.0092888 -0.004953 -0.0060033" rpy="0 0 0" />
      <mass value="0.003344" />
      <inertia ixx="1.3632E-07" ixy="5.6787E-08" ixz="-9.1939E-11" iyy="1.4052E-07" iyz="1.2145E-10" izz="2.0026E-07" />
    </inertial>
    </link>
  <joint name="L_thumb_distal_joint" type="revolute">
    <origin xyz="0.020248 -0.010156 -0.0012" rpy="0 0 0" />
    <parent link="L_thumb_intermediate" />
    <child link="L_thumb_distal" />
    <axis xyz="0 0 -1" />
    <limit lower="0" upper="1.2" effort="1" velocity="0.5" />
    <mimic joint="L_thumb_proximal_pitch_joint" multiplier="2.4" offset="0" />
  </joint>
  <link name="L_index_proximal">
    <inertial>
      <origin xyz="0.0012971 -0.011934 -0.0059998" rpy="0 0 0" />
      <mass value="0.0042405" />
      <inertia ixx="6.6215E-07" ixy="1.8442E-08" ixz="1.3746E-12" iyy="2.1167E-07" iyz="-1.4773E-11" izz="6.9402E-07" />
    </inertial>
    </link>
  <joint name="L_index_proximal_joint" type="revolute">
    <origin xyz="0.00028533 -0.13653 0.032268" rpy="-0.034907 0 0" />
    <parent link="L_hand_base_link" />
    <child link="L_index_proximal" />
    <axis xyz="0 0 -1" />
    <limit lower="0" upper="1.7" effort="1" velocity="0.5" />
  </joint>
  <link name="L_index_intermediate">
    <inertial>
      <origin xyz="0.0021753 -0.019567 -0.005" rpy="0 0 0" />
      <mass value="0.0045682" />
      <inertia ixx="7.6284E-07" ixy="-8.063E-08" ixz="3.6797E-13" iyy="9.4308E-08" iyz="1.5743E-13" izz="7.8176E-07" />
    </inertial>
    </link>
  <joint name="L_index_intermediate_joint" type="revolute">
    <origin xyz="-0.0024229 -0.032041 -0.001" rpy="0 0 0" />
    <parent link="L_index_proximal" />
    <child link="L_index_intermediate" />
    <axis xyz="0 0 -1" />
    <limit lower="0" upper="1.7" effort="1" velocity="0.5" />
    <mimic joint="L_index_proximal_joint" multiplier="1" offset="0" />
  </joint>
  <link name="L_middle_proximal">
    <inertial>
      <origin xyz="0.0012971 -0.011934 -0.0059999" rpy="0 0 0" />
      <mass value="0.0042405" />
      <inertia ixx="6.6215E-07" ixy="1.8442E-08" ixz="1.2299E-12" iyy="2.1167E-07" iyz="-1.4484E-11" izz="6.9402E-07" />
    </inertial>
    </link>
  <joint name="L_middle_proximal_joint" type="revolute">
    <origin xyz="0.00028533 -0.1371 0.01295" rpy="0 0 0" />
    <parent link="L_hand_base_link" />
    <child link="L_middle_proximal" />
    <axis xyz="0 0 -1" />
    <limit lower="0" upper="1.7" effort="1" velocity="0.5" />
  </joint>
  <link name="L_middle_intermediate">
    <inertial>
      <origin xyz="0.001921 -0.020796 -0.0049999" rpy="0 0 0" />
      <mass value="0.0050397" />
      <inertia ixx="9.5823E-07" ixy="-1.1425E-07" ixz="-2.4186E-12" iyy="1.0646E-07" iyz="3.6974E-12" izz="9.8385E-07" />
    </inertial>
    </link>
  <joint name="L_middle_intermediate_joint" type="revolute">
    <origin xyz="-0.0024229 -0.032041 -0.001" rpy="0 0 0" />
    <parent link="L_middle_proximal" />
    <child link="L_middle_intermediate" />
    <axis xyz="0 0 -1" />
    <limit lower="0" upper="1.7" effort="1" velocity="0.5" />
    <mimic joint="L_middle_proximal_joint" multiplier="1" offset="0" />
  </joint>
  <link name="L_ring_proximal">
    <inertial>
      <origin xyz="0.0012971 -0.011934 -0.0059999" rpy="0 0 0" />
      <mass value="0.0042405" />
      <inertia ixx="6.6215E-07" ixy="1.8442E-08" ixz="9.6052E-13" iyy="2.1167E-07" iyz="-1.4124E-11" izz="6.9402E-07" />
    </inertial>
    </link>
  <joint name="L_ring_proximal_joint" type="revolute">
    <origin xyz="0.00028533 -0.13691 -0.0062872" rpy="0.05236 0 0" />
    <parent link="L_hand_base_link" />
    <child link="L_ring_proximal" />
    <axis xyz="0 0 -1" />
    <limit lower="0" upper="1.7" effort="1" velocity="0.5" />
  </joint>
  <link name="L_ring_intermediate">
    <inertial>
      <origin xyz="0.0021753 -0.019567 -0.005" rpy="0 0 0" />
      <mass value="0.0045682" />
      <inertia ixx="7.6285E-07" ixy="-8.0631E-08" ixz="3.3472E-14" iyy="9.4308E-08" iyz="-4.4773E-13" izz="7.8176E-07" />
    </inertial>
    </link>
  <joint name="L_ring_intermediate_joint" type="revolute">
    <origin xyz="-0.0024229 -0.032041 -0.001" rpy="0 0 0" />
    <parent link="L_ring_proximal" />
    <child link="L_ring_intermediate" />
    <axis xyz="0 0 -1" />
    <limit lower="0" upper="1.7" effort="1" velocity="0.5" />
    <mimic joint="L_ring_proximal_joint" multiplier="1" offset="0" />
  </joint>
  <link name="L_pinky_proximal">
    <inertial>
      <origin xyz="0.0012971 -0.011934 -0.0059999" rpy="0 0 0" />
      <mass value="0.0042405" />
      <inertia ixx="6.6215E-07" ixy="1.8442E-08" ixz="1.0279E-12" iyy="2.1167E-07" iyz="-1.4277E-11" izz="6.9402E-07" />
    </inertial>
    </link>
  <joint name="L_pinky_proximal_joint" type="revolute">
    <origin xyz="0.00028533 -0.13571 -0.025488" rpy="0.10472 0 0" />
    <parent link="L_hand_base_link" />
    <child link="L_pinky_proximal" />
    <axis xyz="0 0 -1" />
    <limit lower="0" upper="1.7" effort="1" velocity="0.5" />
  </joint>
  <link name="L_pinky_intermediate">
    <inertial>
      <origin xyz="0.0024788 -0.016208 -0.0050001" rpy="0 0 0" />
      <mass value="0.0036036" />
      <inertia ixx="4.3923E-07" ixy="-4.1355E-08" ixz="1.2263E-12" iyy="7.0315E-08" iyz="3.1311E-12" izz="4.4881E-07" />
    </inertial>
    </link>
  <joint name="L_pinky_intermediate_joint" type="revolute">
    <origin xyz="-0.0024229 -0.032041 -0.001" rpy="0 0 0" />
    <parent link="L_pinky_proximal" />
    <child link="L_pinky_intermediate" />
    <axis xyz="0 0 -1" />
    <limit lower="0" upper="1.7" effort="1" velocity="0.5" />
    <mimic joint="L_pinky_proximal_joint" multiplier="1" offset="0" />
  </joint>

  <!-- R Gripper -->
  <joint name="R_base_link_joint" type="fixed">
    <origin xyz="0.054 0 0" rpy="3.1415926535897932384626433832795 0 -1.5707963267948966192313216916398" />
    <parent link="right_wrist_yaw_link" />
    <child link="R_hand_base_link" />
  </joint>
  <link name="R_hand_base_link">
    <inertial>
      <origin xyz="-0.0025264 -0.066047 0.0019598" rpy="0 0 0" />
      <mass value="0.14143" />
      <inertia ixx="0.00012281" ixy="2.1711E-06" ixz="1.7709E-06" iyy="8.3832E-05" iyz="-1.6551E-06" izz="7.6663E-05" />
    </inertial>
    </link>
  <link name="R_thumb_proximal_base">
    <inertial>
      <origin xyz="-0.0048064 0.0009382 -0.00757" rpy="0 0 0" />
      <mass value="0.0018869" />
      <inertia ixx="5.816E-08" ixy="1.4539E-08" ixz="4.491E-09" iyy="7.9161E-08" iyz="-1.8727E-09" izz="6.7433E-08" />
    </inertial>
    </link>
  <joint name="R_thumb_proximal_yaw_joint" type="revolute">
    <origin xyz="-0.01696 -0.0691 -0.02045" rpy="1.5708 -1.5708 0" />
    <parent link="R_hand_base_link" />
    <child link="R_thumb_proximal_base" />
    <axis xyz="0 0 -1" />
    <limit lower="-0.1" upper="1.3" effort="1" velocity="0.5" />
  </joint>
  <link name="R_thumb_proximal">
    <inertial>
      <origin xyz="0.021932 0.012785 -0.0080386" rpy="0 0 0" />
      <mass value="0.0066075" />
      <inertia ixx="1.5686E-06" ixy="-7.8296E-07" ixz="8.9143E-10" iyy="1.7353E-06" iyz="-1.0191E-09" izz="2.786E-06" />
    </inertial>
    </link>
  <joint name="R_thumb_proximal_pitch_joint" type="revolute">
    <origin xyz="-0.0088099 0.010892 -0.00925" rpy="1.5708 0 2.8587" />
    <parent link="R_thumb_proximal_base" />
    <child link="R_thumb_proximal" />
    <axis xyz="0 0 1" />
    <limit lower="-0.1" upper="0.6" effort="1" velocity="0.5" />
  </joint>
  <link name="R_thumb_intermediate">
    <inertial>
      <origin xyz="0.0095544 -0.0016282 -0.0071997" rpy="0 0 0" />
      <mass value="0.0037847" />
      <inertia ixx="3.6981E-07" ixy="-9.8581E-08" ixz="-4.7469E-12" iyy="3.2394E-07" iyz="1.0939E-12" izz="4.6531E-07" />
    </inertial>
    </link>
  <joint name="R_thumb_intermediate_joint" type="revolute">
    <origin xyz="0.04407 0.034553 -0.0008" rpy="0 0 0" />
    <parent link="R_thumb_proximal" />
    <child link="R_thumb_intermediate" />
    <axis xyz="0 0 1" />
    <limit lower="0" upper="0.8" effort="1" velocity="0.5" />
    <mimic joint="R_thumb_proximal_pitch_joint" multiplier="1.6" offset="0" />
  </joint>
  <link name="R_thumb_distal">
    <inertial>
      <origin xyz="0.0092888 0.0049529 -0.0060033" rpy="0 0 0" />
      <mass value="0.0033441" />
      <inertia ixx="1.3632E-07" ixy="-5.6788E-08" ixz="-9.2764E-11" iyy="1.4052E-07" iyz="-1.2283E-10" izz="2.0026E-07" />
    </inertial>
    </link>
  <joint name="R_thumb_distal_joint" type="revolute">
    <origin xyz="0.020248 0.010156 -0.0012" rpy="0 0 0" />
    <parent link="R_thumb_intermediate" />
    <child link="R_thumb_distal" />
    <axis xyz="0 0 1" />
    <limit lower="0" upper="1.2" effort="1" velocity="0.5" />
    <mimic joint="R_thumb_proximal_pitch_joint" multiplier="2.4" offset="0" />
  </joint>
  <link name="R_index_proximal">
    <inertial>
      <origin xyz="0.0012259 0.011942 -0.0060001" rpy="0 0 0" />
      <mass value="0.0042403" />
      <inertia ixx="6.6232E-07" ixy="-1.5775E-08" ixz="1.8515E-12" iyy="2.1146E-07" iyz="-5.0828E-12" izz="6.9398E-07" />
    </inertial>
    </link>
  <joint name="R_index_proximal_joint" type="revolute">
    <origin xyz="0.00028533 -0.13653 -0.032268" rpy="-3.1067 0 0" />
    <parent link="R_hand_base_link" />
    <child link="R_index_proximal" />
    <axis xyz="0 0 1" />
    <limit lower="0" upper="1.7" effort="1" velocity="0.5" />
  </joint>
  <link name="R_index_intermediate">
    <inertial>
      <origin xyz="0.0019697 0.019589 -0.005" rpy="0 0 0" />
      <mass value="0.0045683" />
      <inertia ixx="7.6111E-07" ixy="8.7637E-08" ixz="-3.7751E-13" iyy="9.6076E-08" iyz="9.9444E-13" izz="7.8179E-07" />
    </inertial>
    </link>
  <joint name="R_index_intermediate_joint" type="revolute">
    <origin xyz="-0.0026138 0.032026 -0.001" rpy="0 0 0" />
    <parent link="R_index_proximal" />
    <child link="R_index_intermediate" />
    <axis xyz="0 0 1" />
    <limit lower="0" upper="1.7" effort="1" velocity="0.5" />
    <mimic joint="R_index_proximal_joint" multiplier="1" offset="0" />
  </joint>
  <link name="R_middle_proximal">
    <inertial>
      <origin xyz="0.001297 0.011934 -0.0060001" rpy="0 0 0" />
      <mass value="0.0042403" />
      <inertia ixx="6.6211E-07" ixy="-1.8461E-08" ixz="1.8002E-12" iyy="2.1167E-07" iyz="-6.6808E-12" izz="6.9397E-07" />
    </inertial>
    </link>
  <joint name="R_middle_proximal_joint" type="revolute">
    <origin xyz="0.00028533 -0.1371 -0.01295" rpy="-3.1416 0 0" />
    <parent link="R_hand_base_link" />
    <child link="R_middle_proximal" />
    <axis xyz="0 0 1" />
    <limit lower="0" upper="1.7" effort="1" velocity="0.5" />
  </joint>
  <link name="R_middle_intermediate">
    <inertial>
      <origin xyz="0.001921 0.020796 -0.005" rpy="0 0 0" />
      <mass value="0.0050396" />
      <inertia ixx="9.5822E-07" ixy="1.1425E-07" ixz="-2.4791E-12" iyy="1.0646E-07" iyz="5.9173E-12" izz="9.8384E-07" />
    </inertial>
    </link>
  <joint name="R_middle_intermediate_joint" type="revolute">
    <origin xyz="-0.0024229 0.032041 -0.001" rpy="0 0 0" />
    <parent link="R_middle_proximal" />
    <child link="R_middle_intermediate" />
    <axis xyz="0 0 1" />
    <limit lower="0" upper="1.7" effort="1" velocity="0.5" />
    <mimic joint="R_middle_proximal_joint" multiplier="1" offset="0" />
  </joint>
  <link name="R_ring_proximal">
    <inertial>
      <origin xyz="0.001297 0.011934 -0.0060002" rpy="0 0 0" />
      <mass value="0.0042403" />
      <inertia ixx="6.6211E-07" ixy="-1.8461E-08" ixz="1.5793E-12" iyy="2.1167E-07" iyz="-6.6868E-12" izz="6.9397E-07" />
    </inertial>
    </link>
  <joint name="R_ring_proximal_joint" type="revolute">
    <origin xyz="0.00028533 -0.13691 0.0062872" rpy="3.0892 0 0" />
    <parent link="R_hand_base_link" />
    <child link="R_ring_proximal" />
    <axis xyz="0 0 1" />
    <limit lower="0" upper="1.7" effort="1" velocity="0.5" />
  </joint>
  <link name="R_ring_intermediate">
    <inertial>
      <origin xyz="0.0021753 0.019567 -0.005" rpy="0 0 0" />
      <mass value="0.0045683" />
      <inertia ixx="7.6286E-07" ixy="8.0635E-08" ixz="-6.1562E-13" iyy="9.431E-08" iyz="5.8619E-13" izz="7.8177E-07" />
    </inertial>
    </link>
  <joint name="R_ring_intermediate_joint" type="revolute">
    <origin xyz="-0.0024229 0.032041 -0.001" rpy="0 0 0" />
    <parent link="R_ring_proximal" />
    <child link="R_ring_intermediate" />
    <axis xyz="0 0 1" />
    <limit lower="0" upper="1.7" effort="1" velocity="0.5" />
    <mimic joint="R_ring_proximal_joint" multiplier="1" offset="0" />
  </joint>
  <link name="R_pinky_proximal">
    <inertial>
      <origin xyz="0.001297 0.011934 -0.0060001" rpy="0 0 0" />
      <mass value="0.0042403" />
      <inertia ixx="6.6211E-07" ixy="-1.8461E-08" ixz="1.6907E-12" iyy="2.1167E-07" iyz="-6.9334E-12" izz="6.9397E-07" />
    </inertial>
    </link>
  <joint name="R_pinky_proximal_joint" type="revolute">
    <origin xyz="0.00028533 -0.13571 0.025488" rpy="3.0369 0 0" />
    <parent link="R_hand_base_link" />
    <child link="R_pinky_proximal" />
    <axis xyz="0 0 1" />
    <limit lower="0" upper="1.7" effort="1" velocity="0.5" />
  </joint>
  <link name="R_pinky_intermediate">
    <inertial>
      <origin xyz="0.0024748 0.016203 -0.0050031" rpy="0 0 0" />
      <mass value="0.0035996" />
      <inertia ixx="4.3913E-07" ixy="4.1418E-08" ixz="3.7168E-11" iyy="7.0247E-08" iyz="5.8613E-11" izz="4.4867E-07" />
    </inertial>
    </link>
  <joint name="R_pinky_intermediate_joint" type="revolute">
    <origin xyz="-0.0024229 0.032041 -0.001" rpy="0 0 0" />
    <parent link="R_pinky_proximal" />
    <child link="R_pinky_intermediate" />
    <axis xyz="0 0 1" />
    <limit lower="0" upper="1.7" effort="1" velocity="0.5" />
    <mimic joint="R_pinky_proximal_joint" multiplier="1" offset="0" />
  </joint>
<link name="pelvis_sphere1"><inertial><origin xyz="0 0 0" rpy="0 0 0" /><mass value="0.01" /><inertia ixx="0.001" ixy="0" ixz="0" iyy="0.001" iyz="0" izz="0.001" /></inertial><visual><origin rpy="0 0 0" xyz="0 0 0" /><geometry><sphere radius="0.0566188208758831" /></geometry><material name="color_pelvis_sphere1_0"><color rgba="0.9 0.1 0.1 1.0" /></material></visual><collision><origin rpy="0 0 0" xyz="0 0 0" /><geometry><sphere radius="0.0566188208758831" /></geometry><drake:proximity_properties><drake:rigid_hydroelastic /><drake:mesh_resolution_hint value="1.5" /><drake:hunt_crossley_dissipation value="1.25" /></drake:proximity_properties></collision></link><joint name="pelvis_to_pelvis_sphere1" type="fixed"><parent link="pelvis" /><child link="pelvis_sphere1" /><origin xyz="-0.0006582838832400739 -0.09225943684577942 -0.042492982000112534" rpy="0 0 0" /></joint><link name="pelvis_sphere2"><inertial><origin xyz="0 0 0" rpy="0 0 0" /><mass value="0.01" /><inertia ixx="0.001" ixy="0" ixz="0" iyy="0.001" iyz="0" izz="0.001" /></inertial><visual><origin rpy="0 0 0" xyz="0 0 0" /><geometry><sphere radius="0.05338418856263161" /></geometry><material name="color_pelvis_sphere2_0"><color rgba="0.9 0.1 0.1 1.0" /></material></visual><collision><origin rpy="0 0 0" xyz="0 0 0" /><geometry><sphere radius="0.05338418856263161" /></geometry><drake:proximity_properties><drake:rigid_hydroelastic /><drake:mesh_resolution_hint value="1.5" /><drake:hunt_crossley_dissipation value="1.25" /></drake:proximity_properties></collision></link><joint name="pelvis_to_pelvis_sphere2" type="fixed"><parent link="pelvis" /><child link="pelvis_sphere2" /><origin xyz="0.022457826882600784 -0.0023631195072084665 -0.03878297284245491" rpy="0 0 0" /></joint><link name="pelvis_sphere3"><inertial><origin xyz="0 0 0" rpy="0 0 0" /><mass value="0.01" /><inertia ixx="0.001" ixy="0" ixz="0" iyy="0.001" iyz="0" izz="0.001" /></inertial><visual><origin rpy="0 0 0" xyz="0 0 0" /><geometry><sphere radius="0.05706167593598366" /></geometry><material name="color_pelvis_sphere3_0"><color rgba="0.9 0.1 0.1 1.0" /></material></visual><collision><origin rpy="0 0 0" xyz="0 0 0" /><geometry><sphere radius="0.05706167593598366" /></geometry><drake:proximity_properties><drake:rigid_hydroelastic /><drake:mesh_resolution_hint value="1.5" /><drake:hunt_crossley_dissipation value="1.25" /></drake:proximity_properties></collision></link><joint name="pelvis_to_pelvis_sphere3" type="fixed"><parent link="pelvis" /><child link="pelvis_sphere3" /><origin xyz="0.00048275734297931194 0.09225258976221085 -0.0420948825776577" rpy="0 0 0" /></joint><link name="pelvis_sphere4"><inertial><origin xyz="0 0 0" rpy="0 0 0" /><mass value="0.01" /><inertia ixx="0.001" ixy="0" ixz="0" iyy="0.001" iyz="0" izz="0.001" /></inertial><visual><origin rpy="0 0 0" xyz="0 0 0" /><geometry><sphere radius="0.05298854783177376" /></geometry><material name="color_pelvis_sphere4_0"><color rgba="0.9 0.1 0.1 1.0" /></material></visual><collision><origin rpy="0 0 0" xyz="0 0 0" /><geometry><sphere radius="0.05298854783177376" /></geometry><drake:proximity_properties><drake:rigid_hydroelastic /><drake:mesh_resolution_hint value="1.5" /><drake:hunt_crossley_dissipation value="1.25" /></drake:proximity_properties></collision></link><joint name="pelvis_to_pelvis_sphere4" type="fixed"><parent link="pelvis" /><child link="pelvis_sphere4" /><origin xyz="-0.02288988046348095 0.0027171848341822624 -0.03924413025379181" rpy="0 0 0" /></joint><link name="torso_link_sphere1"><inertial><origin xyz="0 0 0" rpy="0 0 0" /><mass value="0.01" /><inertia ixx="0.001" ixy="0" ixz="0" iyy="0.001" iyz="0" izz="0.001" /></inertial><visual><origin rpy="0 0 0" xyz="0 0 0" /><geometry><sphere radius="0.11691099405288696" /></geometry><material name="color_torso_link_sphere1_0"><color rgba="0.8 0.3 0.2 1.0" /></material></visual><collision><origin rpy="0 0 0" xyz="0 0 0" /><geometry><sphere radius="0.11691099405288696" /></geometry><drake:proximity_properties><drake:rigid_hydroelastic /><drake:mesh_resolution_hint value="1.5" /><drake:hunt_crossley_dissipation value="1.25" /></drake:proximity_properties></collision></link><joint name="torso_link_to_torso_link_sphere1" type="fixed"><parent link="torso_link" /><child link="torso_link_sphere1" /><origin xyz="0.010826588608324528 -0.0009171374840661883 0.28240811824798584" rpy="0 0 0" /></joint><link name="torso_link_sphere2"><inertial><origin xyz="0 0 0" rpy="0 0 0" /><mass value="0.01" /><inertia ixx="0.001" ixy="0" ixz="0" iyy="0.001" iyz="0" izz="0.001" /></inertial><visual><origin rpy="0 0 0" xyz="0 0 0" /><geometry><sphere radius="0.08996040374040604" /></geometry><material name="color_torso_link_sphere2_0"><color rgba="0.8 0.3 0.2 1.0" /></material></visual><collision><origin rpy="0 0 0" xyz="0 0 0" /><geometry><sphere radius="0.08996040374040604" /></geometry><drake:proximity_properties><drake:rigid_hydroelastic /><drake:mesh_resolution_hint value="1.5" /><drake:hunt_crossley_dissipation value="1.25" /></drake:proximity_properties></collision></link><joint name="torso_link_to_torso_link_sphere2" type="fixed"><parent link="torso_link" /><child link="torso_link_sphere2" /><origin xyz="0.04552965238690376 0.00036791275488212705 0.669076681137085" rpy="0 0 0" /></joint><link name="torso_link_sphere3"><inertial><origin xyz="0 0 0" rpy="0 0 0" /><mass value="0.01" /><inertia ixx="0.001" ixy="0" ixz="0" iyy="0.001" iyz="0" izz="0.001" /></inertial><visual><origin rpy="0 0 0" xyz="0 0 0" /><geometry><sphere radius="0.10513805598020554" /></geometry><material name="color_torso_link_sphere3_0"><color rgba="0.8 0.3 0.2 1.0" /></material></visual><collision><origin rpy="0 0 0" xyz="0 0 0" /><geometry><sphere radius="0.10513805598020554" /></geometry><drake:proximity_properties><drake:rigid_hydroelastic /><drake:mesh_resolution_hint value="1.5" /><drake:hunt_crossley_dissipation value="1.25" /></drake:proximity_properties></collision></link><joint name="torso_link_to_torso_link_sphere3" type="fixed"><parent link="torso_link" /><child link="torso_link_sphere3" /><origin xyz="0.003146003931760788 0.0014351505087688565 0.08999927341938019" rpy="0 0 0" /></joint><link name="torso_link_sphere4"><inertial><origin xyz="0 0 0" rpy="0 0 0" /><mass value="0.01" /><inertia ixx="0.001" ixy="0" ixz="0" iyy="0.001" iyz="0" izz="0.001" /></inertial><visual><origin rpy="0 0 0" xyz="0 0 0" /><geometry><sphere radius="0.11523880064487457" /></geometry><material name="color_torso_link_sphere4_0"><color rgba="0.8 0.3 0.2 1.0" /></material></visual><collision><origin rpy="0 0 0" xyz="0 0 0" /><geometry><sphere radius="0.11523880064487457" /></geometry><drake:proximity_properties><drake:rigid_hydroelastic /><drake:mesh_resolution_hint value="1.5" /><drake:hunt_crossley_dissipation value="1.25" /></drake:proximity_properties></collision></link><joint name="torso_link_to_torso_link_sphere4" type="fixed"><parent link="torso_link" /><child link="torso_link_sphere4" /><origin xyz="0.01870313659310341 0.00013361524906940758 0.5028911232948303" rpy="0 0 0" /></joint><link name="left_shoulder_pitch_link_sphere1"><inertial><origin xyz="0 0 0" rpy="0 0 0" /><mass value="0.01" /><inertia ixx="0.001" ixy="0" ixz="0" iyy="0.001" iyz="0" izz="0.001" /></inertial><visual><origin rpy="0 0 0" xyz="0 0 0" /><geometry><sphere radius="0.02665524184703827" /></geometry><material name="color_left_shoulder_pitch_link_sphere1_0"><color rgba="0.9 0.9 0.1 1.0" /></material></visual><collision><origin rpy="0 0 0" xyz="0 0 0" /><geometry><sphere radius="0.02665524184703827" /></geometry><drake:proximity_properties><drake:rigid_hydroelastic /><drake:mesh_resolution_hint value="1.5" /><drake:hunt_crossley_dissipation value="1.25" /></drake:proximity_properties></collision></link><joint name="left_shoulder_pitch_link_to_left_shoulder_pitch_link_sphere1" type="fixed"><parent link="left_shoulder_pitch_link" /><child link="left_shoulder_pitch_link_sphere1" /><origin xyz="-0.01836504600942135 0.06546575576066971 -0.030149221420288086" rpy="0 0 0" /></joint><link name="left_shoulder_pitch_link_sphere2"><inertial><origin xyz="0 0 0" rpy="0 0 0" /><mass value="0.01" /><inertia ixx="0.001" ixy="0" ixz="0" iyy="0.001" iyz="0" izz="0.001" /></inertial><visual><origin rpy="0 0 0" xyz="0 0 0" /><geometry><sphere radius="0.043117862194776535" /></geometry><material name="color_left_shoulder_pitch_link_sphere2_0"><color rgba="0.9 0.9 0.1 1.0" /></material></visual><collision><origin rpy="0 0 0" xyz="0 0 0" /><geometry><sphere radius="0.043117862194776535" /></geometry><drake:proximity_properties><drake:rigid_hydroelastic /><drake:mesh_resolution_hint value="1.5" /><drake:hunt_crossley_dissipation value="1.25" /></drake:proximity_properties></collision></link><joint name="left_shoulder_pitch_link_to_left_shoulder_pitch_link_sphere2" type="fixed"><parent link="left_shoulder_pitch_link" /><child link="left_shoulder_pitch_link_sphere2" /><origin xyz="-0.0035315481945872307 0.06932560354471207 -0.0005040427204221487" rpy="0 0 0" /></joint><link name="left_shoulder_pitch_link_sphere3"><inertial><origin xyz="0 0 0" rpy="0 0 0" /><mass value="0.01" /><inertia ixx="0.001" ixy="0" ixz="0" iyy="0.001" iyz="0" izz="0.001" /></inertial><visual><origin rpy="0 0 0" xyz="0 0 0" /><geometry><sphere radius="0.03145787864923477" /></geometry><material name="color_left_shoulder_pitch_link_sphere3_0"><color rgba="0.9 0.9 0.1 1.0" /></material></visual><collision><origin rpy="0 0 0" xyz="0 0 0" /><geometry><sphere radius="0.03145787864923477" /></geometry><drake:proximity_properties><drake:rigid_hydroelastic /><drake:mesh_resolution_hint value="1.5" /><drake:hunt_crossley_dissipation value="1.25" /></drake:proximity_properties></collision></link><joint name="left_shoulder_pitch_link_to_left_shoulder_pitch_link_sphere3" type="fixed"><parent link="left_shoulder_pitch_link" /><child link="left_shoulder_pitch_link_sphere3" /><origin xyz="0.006516783032566309 0.0645378977060318 -0.02473437786102295" rpy="0 0 0" /></joint><link name="left_shoulder_pitch_link_sphere4"><inertial><origin xyz="0 0 0" rpy="0 0 0" /><mass value="0.01" /><inertia ixx="0.001" ixy="0" ixz="0" iyy="0.001" iyz="0" izz="0.001" /></inertial><visual><origin rpy="0 0 0" xyz="0 0 0" /><geometry><sphere radius="0.04088401794433594" /></geometry><material name="color_left_shoulder_pitch_link_sphere4_0"><color rgba="0.9 0.9 0.1 1.0" /></material></visual><collision><origin rpy="0 0 0" xyz="0 0 0" /><geometry><sphere radius="0.04088401794433594" /></geometry><drake:proximity_properties><drake:rigid_hydroelastic /><drake:mesh_resolution_hint value="1.5" /><drake:hunt_crossley_dissipation value="1.25" /></drake:proximity_properties></collision></link><joint name="left_shoulder_pitch_link_to_left_shoulder_pitch_link_sphere4" type="fixed"><parent link="left_shoulder_pitch_link" /><child link="left_shoulder_pitch_link_sphere4" /><origin xyz="-0.0048802257515490055 0.029801970347762108 -0.0016688068863004446" rpy="0 0 0" /></joint><link name="left_shoulder_roll_link_sphere1"><inertial><origin xyz="0 0 0" rpy="0 0 0" /><mass value="0.01" /><inertia ixx="0.001" ixy="0" ixz="0" iyy="0.001" iyz="0" izz="0.001" /></inertial><visual><origin rpy="0 0 0" xyz="0 0 0" /><geometry><sphere radius="0.02305985614657402" /></geometry><material name="color_left_shoulder_roll_link_sphere1_0"><color rgba="0.8 0.8 0.2 1.0" /></material></visual><collision><origin rpy="0 0 0" xyz="0 0 0" /><geometry><sphere radius="0.02305985614657402" /></geometry><drake:proximity_properties><drake:rigid_hydroelastic /><drake:mesh_resolution_hint value="1.5" /><drake:hunt_crossley_dissipation value="1.25" /></drake:proximity_properties></collision></link><joint name="left_shoulder_roll_link_to_left_shoulder_roll_link_sphere1" type="fixed"><parent link="left_shoulder_roll_link" /><child link="left_shoulder_roll_link_sphere1" /><origin xyz="-0.05006806179881096 0.021937057375907898 -0.12679605185985565" rpy="0 0 0" /></joint><link name="left_shoulder_roll_link_sphere2"><inertial><origin xyz="0 0 0" rpy="0 0 0" /><mass value="0.01" /><inertia ixx="0.001" ixy="0" ixz="0" iyy="0.001" iyz="0" izz="0.001" /></inertial><visual><origin rpy="0 0 0" xyz="0 0 0" /><geometry><sphere radius="0.045050982385873795" /></geometry><material name="color_left_shoulder_roll_link_sphere2_0"><color rgba="0.8 0.8 0.2 1.0" /></material></visual><collision><origin rpy="0 0 0" xyz="0 0 0" /><geometry><sphere radius="0.045050982385873795" /></geometry><drake:proximity_properties><drake:rigid_hydroelastic /><drake:mesh_resolution_hint value="1.5" /><drake:hunt_crossley_dissipation value="1.25" /></drake:proximity_properties></collision></link><joint name="left_shoulder_roll_link_to_left_shoulder_roll_link_sphere2" type="fixed"><parent link="left_shoulder_roll_link" /><child link="left_shoulder_roll_link_sphere2" /><origin xyz="-0.022787058725953102 -0.00016949420387391 -0.05602818354964256" rpy="0 0 0" /></joint><link name="left_shoulder_roll_link_sphere3"><inertial><origin xyz="0 0 0" rpy="0 0 0" /><mass value="0.01" /><inertia ixx="0.001" ixy="0" ixz="0" iyy="0.001" iyz="0" izz="0.001" /></inertial><visual><origin rpy="0 0 0" xyz="0 0 0" /><geometry><sphere radius="0.03464982286095619" /></geometry><material name="color_left_shoulder_roll_link_sphere3_0"><color rgba="0.8 0.8 0.2 1.0" /></material></visual><collision><origin rpy="0 0 0" xyz="0 0 0" /><geometry><sphere radius="0.03464982286095619" /></geometry><drake:proximity_properties><drake:rigid_hydroelastic /><drake:mesh_resolution_hint value="1.5" /><drake:hunt_crossley_dissipation value="1.25" /></drake:proximity_properties></collision></link><joint name="left_shoulder_roll_link_to_left_shoulder_roll_link_sphere3" type="fixed"><parent link="left_shoulder_roll_link" /><child link="left_shoulder_roll_link_sphere3" /><origin xyz="-0.007730615325272083 0.00046243472024798393 0.004089736379683018" rpy="0 0 0" /></joint><link name="left_shoulder_roll_link_sphere4"><inertial><origin xyz="0 0 0" rpy="0 0 0" /><mass value="0.01" /><inertia ixx="0.001" ixy="0" ixz="0" iyy="0.001" iyz="0" izz="0.001" /></inertial><visual><origin rpy="0 0 0" xyz="0 0 0" /><geometry><sphere radius="0.050470687448978424" /></geometry><material name="color_left_shoulder_roll_link_sphere4_0"><color rgba="0.8 0.8 0.2 1.0" /></material></visual><collision><origin rpy="0 0 0" xyz="0 0 0" /><geometry><sphere radius="0.050470687448978424" /></geometry><drake:proximity_properties><drake:rigid_hydroelastic /><drake:mesh_resolution_hint value="1.5" /><drake:hunt_crossley_dissipation value="1.25" /></drake:proximity_properties></collision></link><joint name="left_shoulder_roll_link_to_left_shoulder_roll_link_sphere4" type="fixed"><parent link="left_shoulder_roll_link" /><child link="left_shoulder_roll_link_sphere4" /><origin xyz="-0.033224161714315414 -0.0005902336561121047 -0.10266612470149994" rpy="0 0 0" /></joint><link name="left_shoulder_yaw_link_sphere1"><inertial><origin xyz="0 0 0" rpy="0 0 0" /><mass value="0.01" /><inertia ixx="0.001" ixy="0" ixz="0" iyy="0.001" iyz="0" izz="0.001" /></inertial><visual><origin rpy="0 0 0" xyz="0 0 0" /><geometry><sphere radius="0.04802717640995979" /></geometry><material name="color_left_shoulder_yaw_link_sphere1_0"><color rgba="0.7 0.7 0.3 1.0" /></material></visual><collision><origin rpy="0 0 0" xyz="0 0 0" /><geometry><sphere radius="0.04802717640995979" /></geometry><drake:proximity_properties><drake:rigid_hydroelastic /><drake:mesh_resolution_hint value="1.5" /><drake:hunt_crossley_dissipation value="1.25" /></drake:proximity_properties></collision></link><joint name="left_shoulder_yaw_link_to_left_shoulder_yaw_link_sphere1" type="fixed"><parent link="left_shoulder_yaw_link" /><child link="left_shoulder_yaw_link_sphere1" /><origin xyz="0.004354390315711498 -0.0034881902392953634 -0.12723785638809204" rpy="0 0 0" /></joint><link name="left_shoulder_yaw_link_sphere2"><inertial><origin xyz="0 0 0" rpy="0 0 0" /><mass value="0.01" /><inertia ixx="0.001" ixy="0" ixz="0" iyy="0.001" iyz="0" izz="0.001" /></inertial><visual><origin rpy="0 0 0" xyz="0 0 0" /><geometry><sphere radius="0.046699728816747665" /></geometry><material name="color_left_shoulder_yaw_link_sphere2_0"><color rgba="0.7 0.7 0.3 1.0" /></material></visual><collision><origin rpy="0 0 0" xyz="0 0 0" /><geometry><sphere radius="0.046699728816747665" /></geometry><drake:proximity_properties><drake:rigid_hydroelastic /><drake:mesh_resolution_hint value="1.5" /><drake:hunt_crossley_dissipation value="1.25" /></drake:proximity_properties></collision></link><joint name="left_shoulder_yaw_link_to_left_shoulder_yaw_link_sphere2" type="fixed"><parent link="left_shoulder_yaw_link" /><child link="left_shoulder_yaw_link_sphere2" /><origin xyz="0.0025237328372895718 -0.0020777841564267874 -0.07483507692813873" rpy="0 0 0" /></joint><link name="left_shoulder_yaw_link_sphere3"><inertial><origin xyz="0 0 0" rpy="0 0 0" /><mass value="0.01" /><inertia ixx="0.001" ixy="0" ixz="0" iyy="0.001" iyz="0" izz="0.001" /></inertial><visual><origin rpy="0 0 0" xyz="0 0 0" /><geometry><sphere radius="0.048022832721471786" /></geometry><material name="color_left_shoulder_yaw_link_sphere3_0"><color rgba="0.7 0.7 0.3 1.0" /></material></visual><collision><origin rpy="0 0 0" xyz="0 0 0" /><geometry><sphere radius="0.048022832721471786" /></geometry><drake:proximity_properties><drake:rigid_hydroelastic /><drake:mesh_resolution_hint value="1.5" /><drake:hunt_crossley_dissipation value="1.25" /></drake:proximity_properties></collision></link><joint name="left_shoulder_yaw_link_to_left_shoulder_yaw_link_sphere3" type="fixed"><parent link="left_shoulder_yaw_link" /><child link="left_shoulder_yaw_link_sphere3" /><origin xyz="0.006270349957048893 -0.004731729160994291 -0.18505337834358215" rpy="0 0 0" /></joint><link name="left_shoulder_yaw_link_sphere4"><inertial><origin xyz="0 0 0" rpy="0 0 0" /><mass value="0.01" /><inertia ixx="0.001" ixy="0" ixz="0" iyy="0.001" iyz="0" izz="0.001" /></inertial><visual><origin rpy="0 0 0" xyz="0 0 0" /><geometry><sphere radius="0.045176077634096146" /></geometry><material name="color_left_shoulder_yaw_link_sphere4_0"><color rgba="0.7 0.7 0.3 1.0" /></material></visual><collision><origin rpy="0 0 0" xyz="0 0 0" /><geometry><sphere radius="0.045176077634096146" /></geometry><drake:proximity_properties><drake:rigid_hydroelastic /><drake:mesh_resolution_hint value="1.5" /><drake:hunt_crossley_dissipation value="1.25" /></drake:proximity_properties></collision></link><joint name="left_shoulder_yaw_link_to_left_shoulder_yaw_link_sphere4" type="fixed"><parent link="left_shoulder_yaw_link" /><child link="left_shoulder_yaw_link_sphere4" /><origin xyz="0.0009800187544897199 -0.0003437544801272452 -0.03247440978884697" rpy="0 0 0" /></joint><link name="left_elbow_pitch_link_sphere1"><inertial><origin xyz="0 0 0" rpy="0 0 0" /><mass value="0.01" /><inertia ixx="0.001" ixy="0" ixz="0" iyy="0.001" iyz="0" izz="0.001" /></inertial><visual><origin rpy="0 0 0" xyz="0 0 0" /><geometry><sphere radius="0.0316377617418766" /></geometry><material name="color_left_elbow_pitch_link_sphere1_0"><color rgba="0.6 0.6 0.4 1.0" /></material></visual><collision><origin rpy="0 0 0" xyz="0 0 0" /><geometry><sphere radius="0.0316377617418766" /></geometry><drake:proximity_properties><drake:rigid_hydroelastic /><drake:mesh_resolution_hint value="1.5" /><drake:hunt_crossley_dissipation value="1.25" /></drake:proximity_properties></collision></link><joint name="left_elbow_pitch_link_to_left_elbow_pitch_link_sphere1" type="fixed"><parent link="left_elbow_pitch_link" /><child link="left_elbow_pitch_link_sphere1" /><origin xyz="-0.008367017842829227 -0.009532607160508633 0.0014037973014637828" rpy="0 0 0" /></joint><link name="left_elbow_pitch_link_sphere2"><inertial><origin xyz="0 0 0" rpy="0 0 0" /><mass value="0.01" /><inertia ixx="0.001" ixy="0" ixz="0" iyy="0.001" iyz="0" izz="0.001" /></inertial><visual><origin rpy="0 0 0" xyz="0 0 0" /><geometry><sphere radius="0.040300652384757996" /></geometry><material name="color_left_elbow_pitch_link_sphere2_0"><color rgba="0.6 0.6 0.4 1.0" /></material></visual><collision><origin rpy="0 0 0" xyz="0 0 0" /><geometry><sphere radius="0.040300652384757996" /></geometry><drake:proximity_properties><drake:rigid_hydroelastic /><drake:mesh_resolution_hint value="1.5" /><drake:hunt_crossley_dissipation value="1.25" /></drake:proximity_properties></collision></link><joint name="left_elbow_pitch_link_to_left_elbow_pitch_link_sphere2" type="fixed"><parent link="left_elbow_pitch_link" /><child link="left_elbow_pitch_link_sphere2" /><origin xyz="0.04616506025195122 -0.025142177939414978 -0.006733270362019539" rpy="0 0 0" /></joint><link name="left_elbow_pitch_link_sphere3"><inertial><origin xyz="0 0 0" rpy="0 0 0" /><mass value="0.01" /><inertia ixx="0.001" ixy="0" ixz="0" iyy="0.001" iyz="0" izz="0.001" /></inertial><visual><origin rpy="0 0 0" xyz="0 0 0" /><geometry><sphere radius="0.0384712889790535" /></geometry><material name="color_left_elbow_pitch_link_sphere3_0"><color rgba="0.6 0.6 0.4 1.0" /></material></visual><collision><origin rpy="0 0 0" xyz="0 0 0" /><geometry><sphere radius="0.0384712889790535" /></geometry><drake:proximity_properties><drake:rigid_hydroelastic /><drake:mesh_resolution_hint value="1.5" /><drake:hunt_crossley_dissipation value="1.25" /></drake:proximity_properties></collision></link><joint name="left_elbow_pitch_link_to_left_elbow_pitch_link_sphere3" type="fixed"><parent link="left_elbow_pitch_link" /><child link="left_elbow_pitch_link_sphere3" /><origin xyz="0.09136710315942764 -0.031052103266119957 -0.009548799134790897" rpy="0 0 0" /></joint><link name="left_elbow_roll_link_sphere1"><inertial><origin xyz="0 0 0" rpy="0 0 0" /><mass value="0.01" /><inertia ixx="0.001" ixy="0" ixz="0" iyy="0.001" iyz="0" izz="0.001" /></inertial><visual><origin rpy="0 0 0" xyz="0 0 0" /><geometry><sphere radius="0.02408323436975479" /></geometry><material name="color_left_elbow_roll_link_sphere1_0"><color rgba="0.5 0.5 0.5 1.0" /></material></visual><collision><origin rpy="0 0 0" xyz="0 0 0" /><geometry><sphere radius="0.02408323436975479" /></geometry><drake:proximity_properties><drake:rigid_hydroelastic /><drake:mesh_resolution_hint value="1.5" /><drake:hunt_crossley_dissipation value="1.25" /></drake:proximity_properties></collision></link><joint name="left_elbow_roll_link_to_left_elbow_roll_link_sphere1" type="fixed"><parent link="left_elbow_roll_link" /><child link="left_elbow_roll_link_sphere1" /><origin xyz="0.020240919664502144 0.013649499043822289 0.011919522657990456" rpy="0 0 0" /></joint><link name="left_elbow_roll_link_sphere2"><inertial><origin xyz="0 0 0" rpy="0 0 0" /><mass value="0.01" /><inertia ixx="0.001" ixy="0" ixz="0" iyy="0.001" iyz="0" izz="0.001" /></inertial><visual><origin rpy="0 0 0" xyz="0 0 0" /><geometry><sphere radius="0.04086746647953987" /></geometry><material name="color_left_elbow_roll_link_sphere2_0"><color rgba="0.5 0.5 0.5 1.0" /></material></visual><collision><origin rpy="0 0 0" xyz="0 0 0" /><geometry><sphere radius="0.04086746647953987" /></geometry><drake:proximity_properties><drake:rigid_hydroelastic /><drake:mesh_resolution_hint value="1.5" /><drake:hunt_crossley_dissipation value="1.25" /></drake:proximity_properties></collision></link><joint name="left_elbow_roll_link_to_left_elbow_roll_link_sphere2" type="fixed"><parent link="left_elbow_roll_link" /><child link="left_elbow_roll_link_sphere2" /><origin xyz="0.03524236008524895 -0.0015582457417622209 -8.06146053946577e-05" rpy="0 0 0" /></joint><link name="left_elbow_roll_link_sphere3"><inertial><origin xyz="0 0 0" rpy="0 0 0" /><mass value="0.01" /><inertia ixx="0.001" ixy="0" ixz="0" iyy="0.001" iyz="0" izz="0.001" /></inertial><visual><origin rpy="0 0 0" xyz="0 0 0" /><geometry><sphere radius="0.025036387145519257" /></geometry><material name="color_left_elbow_roll_link_sphere3_0"><color rgba="0.5 0.5 0.5 1.0" /></material></visual><collision><origin rpy="0 0 0" xyz="0 0 0" /><geometry><sphere radius="0.025036387145519257" /></geometry><drake:proximity_properties><drake:rigid_hydroelastic /><drake:mesh_resolution_hint value="1.5" /><drake:hunt_crossley_dissipation value="1.25" /></drake:proximity_properties></collision></link><joint name="left_elbow_roll_link_to_left_elbow_roll_link_sphere3" type="fixed"><parent link="left_elbow_roll_link" /><child link="left_elbow_roll_link_sphere3" /><origin xyz="0.07486145198345184 0.014994501136243343 0.00013408101222012192" rpy="0 0 0" /></joint><link name="left_elbow_roll_link_sphere4"><inertial><origin xyz="0 0 0" rpy="0 0 0" /><mass value="0.01" /><inertia ixx="0.001" ixy="0" ixz="0" iyy="0.001" iyz="0" izz="0.001" /></inertial><visual><origin rpy="0 0 0" xyz="0 0 0" /><geometry><sphere radius="0.024043748155236244" /></geometry><material name="color_left_elbow_roll_link_sphere4_0"><color rgba="0.5 0.5 0.5 1.0" /></material></visual><collision><origin rpy="0 0 0" xyz="0 0 0" /><geometry><sphere radius="0.024043748155236244" /></geometry><drake:proximity_properties><drake:rigid_hydroelastic /><drake:mesh_resolution_hint value="1.5" /><drake:hunt_crossley_dissipation value="1.25" /></drake:proximity_properties></collision></link><joint name="left_elbow_roll_link_to_left_elbow_roll_link_sphere4" type="fixed"><parent link="left_elbow_roll_link" /><child link="left_elbow_roll_link_sphere4" /><origin xyz="0.07591700553894043 -0.016794539988040924 -2.4858256438164972e-05" rpy="0 0 0" /></joint><link name="left_wrist_pitch_link_sphere1"><inertial><origin xyz="0 0 0" rpy="0 0 0" /><mass value="0.01" /><inertia ixx="0.001" ixy="0" ixz="0" iyy="0.001" iyz="0" izz="0.001" /></inertial><visual><origin rpy="0 0 0" xyz="0 0 0" /><geometry><sphere radius="0.018751587718725204" /></geometry><material name="color_left_wrist_pitch_link_sphere1_0"><color rgba="0.4 0.4 0.6 1.0" /></material></visual><collision><origin rpy="0 0 0" xyz="0 0 0" /><geometry><sphere radius="0.018751587718725204" /></geometry><drake:proximity_properties><drake:rigid_hydroelastic /><drake:mesh_resolution_hint value="1.5" /><drake:hunt_crossley_dissipation value="1.25" /></drake:proximity_properties></collision></link><joint name="left_wrist_pitch_link_to_left_wrist_pitch_link_sphere1" type="fixed"><parent link="left_wrist_pitch_link" /><child link="left_wrist_pitch_link_sphere1" /><origin xyz="0.00958962645381689 -0.015840062871575356 0.014722274616360664" rpy="0 0 0" /></joint><link name="left_wrist_pitch_link_sphere2"><inertial><origin xyz="0 0 0" rpy="0 0 0" /><mass value="0.01" /><inertia ixx="0.001" ixy="0" ixz="0" iyy="0.001" iyz="0" izz="0.001" /></inertial><visual><origin rpy="0 0 0" xyz="0 0 0" /><geometry><sphere radius="0.035354580730199814" /></geometry><material name="color_left_wrist_pitch_link_sphere2_0"><color rgba="0.4 0.4 0.6 1.0" /></material></visual><collision><origin rpy="0 0 0" xyz="0 0 0" /><geometry><sphere radius="0.035354580730199814" /></geometry><drake:proximity_properties><drake:rigid_hydroelastic /><drake:mesh_resolution_hint value="1.5" /><drake:hunt_crossley_dissipation value="1.25" /></drake:proximity_properties></collision></link><joint name="left_wrist_pitch_link_to_left_wrist_pitch_link_sphere2" type="fixed"><parent link="left_wrist_pitch_link" /><child link="left_wrist_pitch_link_sphere2" /><origin xyz="0.020107543095946312 -0.0007916560862213373 0.00039604067569598556" rpy="0 0 0" /></joint><link name="left_wrist_pitch_link_sphere3"><inertial><origin xyz="0 0 0" rpy="0 0 0" /><mass value="0.01" /><inertia ixx="0.001" ixy="0" ixz="0" iyy="0.001" iyz="0" izz="0.001" /></inertial><visual><origin rpy="0 0 0" xyz="0 0 0" /><geometry><sphere radius="0.019627267494797707" /></geometry><material name="color_left_wrist_pitch_link_sphere3_0"><color rgba="0.4 0.4 0.6 1.0" /></material></visual><collision><origin rpy="0 0 0" xyz="0 0 0" /><geometry><sphere radius="0.019627267494797707" /></geometry><drake:proximity_properties><drake:rigid_hydroelastic /><drake:mesh_resolution_hint value="1.5" /><drake:hunt_crossley_dissipation value="1.25" /></drake:proximity_properties></collision></link><joint name="left_wrist_pitch_link_to_left_wrist_pitch_link_sphere3" type="fixed"><parent link="left_wrist_pitch_link" /><child link="left_wrist_pitch_link_sphere3" /><origin xyz="0.009673291817307472 0.015779299661517143 0.014047013595700264" rpy="0 0 0" /></joint><link name="left_wrist_pitch_link_sphere4"><inertial><origin xyz="0 0 0" rpy="0 0 0" /><mass value="0.01" /><inertia ixx="0.001" ixy="0" ixz="0" iyy="0.001" iyz="0" izz="0.001" /></inertial><visual><origin rpy="0 0 0" xyz="0 0 0" /><geometry><sphere radius="0.02186497300863266" /></geometry><material name="color_left_wrist_pitch_link_sphere4_0"><color rgba="0.4 0.4 0.6 1.0" /></material></visual><collision><origin rpy="0 0 0" xyz="0 0 0" /><geometry><sphere radius="0.02186497300863266" /></geometry><drake:proximity_properties><drake:rigid_hydroelastic /><drake:mesh_resolution_hint value="1.5" /><drake:hunt_crossley_dissipation value="1.25" /></drake:proximity_properties></collision></link><joint name="left_wrist_pitch_link_to_left_wrist_pitch_link_sphere4" type="fixed"><parent link="left_wrist_pitch_link" /><child link="left_wrist_pitch_link_sphere4" /><origin xyz="0.010667040012776852 0.014613635838031769 -0.008534671738743782" rpy="0 0 0" /></joint><link name="left_wrist_yaw_link_sphere1"><inertial><origin xyz="0 0 0" rpy="0 0 0" /><mass value="0.01" /><inertia ixx="0.001" ixy="0" ixz="0" iyy="0.001" iyz="0" izz="0.001" /></inertial><visual><origin rpy="0 0 0" xyz="0 0 0" /><geometry><sphere radius="0.031719133257865906" /></geometry><material name="color_left_wrist_yaw_link_sphere1_0"><color rgba="0.3 0.3 0.7 1.0" /></material></visual><collision><origin rpy="0 0 0" xyz="0 0 0" /><geometry><sphere radius="0.031719133257865906" /></geometry><drake:proximity_properties><drake:rigid_hydroelastic /><drake:mesh_resolution_hint value="1.5" /><drake:hunt_crossley_dissipation value="1.25" /></drake:proximity_properties></collision></link><joint name="left_wrist_yaw_link_to_left_wrist_yaw_link_sphere1" type="fixed"><parent link="left_wrist_yaw_link" /><child link="left_wrist_yaw_link_sphere1" /><origin xyz="0.03247670456767082 -9.962782496586442e-05 -0.011775790713727474" rpy="0 0 0" /></joint><link name="left_wrist_yaw_link_sphere2"><inertial><origin xyz="0 0 0" rpy="0 0 0" /><mass value="0.01" /><inertia ixx="0.001" ixy="0" ixz="0" iyy="0.001" iyz="0" izz="0.001" /></inertial><visual><origin rpy="0 0 0" xyz="0 0 0" /><geometry><sphere radius="0.03158062696456909" /></geometry><material name="color_left_wrist_yaw_link_sphere2_0"><color rgba="0.3 0.3 0.7 1.0" /></material></visual><collision><origin rpy="0 0 0" xyz="0 0 0" /><geometry><sphere radius="0.03158062696456909" /></geometry><drake:proximity_properties><drake:rigid_hydroelastic /><drake:mesh_resolution_hint value="1.5" /><drake:hunt_crossley_dissipation value="1.25" /></drake:proximity_properties></collision></link><joint name="left_wrist_yaw_link_to_left_wrist_yaw_link_sphere2" type="fixed"><parent link="left_wrist_yaw_link" /><child link="left_wrist_yaw_link_sphere2" /><origin xyz="0.03258088231086731 -0.00010324588947696611 0.011581777594983578" rpy="0 0 0" /></joint><link name="left_wrist_yaw_link_sphere3"><inertial><origin xyz="0 0 0" rpy="0 0 0" /><mass value="0.01" /><inertia ixx="0.001" ixy="0" ixz="0" iyy="0.001" iyz="0" izz="0.001" /></inertial><visual><origin rpy="0 0 0" xyz="0 0 0" /><geometry><sphere radius="0.024466942995786667" /></geometry><material name="color_left_wrist_yaw_link_sphere3_0"><color rgba="0.3 0.3 0.7 1.0" /></material></visual><collision><origin rpy="0 0 0" xyz="0 0 0" /><geometry><sphere radius="0.024466942995786667" /></geometry><drake:proximity_properties><drake:rigid_hydroelastic /><drake:mesh_resolution_hint value="1.5" /><drake:hunt_crossley_dissipation value="1.25" /></drake:proximity_properties></collision></link><joint name="left_wrist_yaw_link_to_left_wrist_yaw_link_sphere3" type="fixed"><parent link="left_wrist_yaw_link" /><child link="left_wrist_yaw_link_sphere3" /><origin xyz="0.0024220168124884367 -0.00017540311091579497 -0.021501706913113594" rpy="0 0 0" /></joint><link name="left_wrist_yaw_link_sphere4"><inertial><origin xyz="0 0 0" rpy="0 0 0" /><mass value="0.01" /><inertia ixx="0.001" ixy="0" ixz="0" iyy="0.001" iyz="0" izz="0.001" /></inertial><visual><origin rpy="0 0 0" xyz="0 0 0" /><geometry><sphere radius="0.02487834542989731" /></geometry><material name="color_left_wrist_yaw_link_sphere4_0"><color rgba="0.3 0.3 0.7 1.0" /></material></visual><collision><origin rpy="0 0 0" xyz="0 0 0" /><geometry><sphere radius="0.02487834542989731" /></geometry><drake:proximity_properties><drake:rigid_hydroelastic /><drake:mesh_resolution_hint value="1.5" /><drake:hunt_crossley_dissipation value="1.25" /></drake:proximity_properties></collision></link><joint name="left_wrist_yaw_link_to_left_wrist_yaw_link_sphere4" type="fixed"><parent link="left_wrist_yaw_link" /><child link="left_wrist_yaw_link_sphere4" /><origin xyz="0.002988561987876892 -8.413253090111539e-05 0.021157046779990196" rpy="0 0 0" /></joint><link name="right_shoulder_pitch_link_sphere1"><inertial><origin xyz="0 0 0" rpy="0 0 0" /><mass value="0.01" /><inertia ixx="0.001" ixy="0" ixz="0" iyy="0.001" iyz="0" izz="0.001" /></inertial><visual><origin rpy="0 0 0" xyz="0 0 0" /><geometry><sphere radius="0.04242650419473648" /></geometry><material name="color_right_shoulder_pitch_link_sphere1_0"><color rgba="0.8 0.2 0.8 1.0" /></material></visual><collision><origin rpy="0 0 0" xyz="0 0 0" /><geometry><sphere radius="0.04242650419473648" /></geometry><drake:proximity_properties><drake:rigid_hydroelastic /><drake:mesh_resolution_hint value="1.5" /><drake:hunt_crossley_dissipation value="1.25" /></drake:proximity_properties></collision></link><joint name="right_shoulder_pitch_link_to_right_shoulder_pitch_link_sphere1" type="fixed"><parent link="right_shoulder_pitch_link" /><child link="right_shoulder_pitch_link_sphere1" /><origin xyz="-0.004063849803060293 -0.06916814297437668 0.0013396504800766706" rpy="0 0 0" /></joint><link name="right_shoulder_pitch_link_sphere2"><inertial><origin xyz="0 0 0" rpy="0 0 0" /><mass value="0.01" /><inertia ixx="0.001" ixy="0" ixz="0" iyy="0.001" iyz="0" izz="0.001" /></inertial><visual><origin rpy="0 0 0" xyz="0 0 0" /><geometry><sphere radius="0.015824131667613983" /></geometry><material name="color_right_shoulder_pitch_link_sphere2_0"><color rgba="0.8 0.2 0.8 1.0" /></material></visual><collision><origin rpy="0 0 0" xyz="0 0 0" /><geometry><sphere radius="0.015824131667613983" /></geometry><drake:proximity_properties><drake:rigid_hydroelastic /><drake:mesh_resolution_hint value="1.5" /><drake:hunt_crossley_dissipation value="1.25" /></drake:proximity_properties></collision></link><joint name="right_shoulder_pitch_link_to_right_shoulder_pitch_link_sphere2" type="fixed"><parent link="right_shoulder_pitch_link" /><child link="right_shoulder_pitch_link_sphere2" /><origin xyz="0.01851818710565567 -0.046217888593673706 0.023993726819753647" rpy="0 0 0" /></joint><link name="right_shoulder_pitch_link_sphere3"><inertial><origin xyz="0 0 0" rpy="0 0 0" /><mass value="0.01" /><inertia ixx="0.001" ixy="0" ixz="0" iyy="0.001" iyz="0" izz="0.001" /></inertial><visual><origin rpy="0 0 0" xyz="0 0 0" /><geometry><sphere radius="0.04023420810699463" /></geometry><material name="color_right_shoulder_pitch_link_sphere3_0"><color rgba="0.8 0.2 0.8 1.0" /></material></visual><collision><origin rpy="0 0 0" xyz="0 0 0" /><geometry><sphere radius="0.04023420810699463" /></geometry><drake:proximity_properties><drake:rigid_hydroelastic /><drake:mesh_resolution_hint value="1.5" /><drake:hunt_crossley_dissipation value="1.25" /></drake:proximity_properties></collision></link><joint name="right_shoulder_pitch_link_to_right_shoulder_pitch_link_sphere3" type="fixed"><parent link="right_shoulder_pitch_link" /><child link="right_shoulder_pitch_link_sphere3" /><origin xyz="-0.005369790364056826 -0.028526965528726578 -0.0014903922565281391" rpy="0 0 0" /></joint><link name="right_shoulder_pitch_link_sphere4"><inertial><origin xyz="0 0 0" rpy="0 0 0" /><mass value="0.01" /><inertia ixx="0.001" ixy="0" ixz="0" iyy="0.001" iyz="0" izz="0.001" /></inertial><visual><origin rpy="0 0 0" xyz="0 0 0" /><geometry><sphere radius="0.04244041442871094" /></geometry><material name="color_right_shoulder_pitch_link_sphere4_0"><color rgba="0.8 0.2 0.8 1.0" /></material></visual><collision><origin rpy="0 0 0" xyz="0 0 0" /><geometry><sphere radius="0.04244041442871094" /></geometry><drake:proximity_properties><drake:rigid_hydroelastic /><drake:mesh_resolution_hint value="1.5" /><drake:hunt_crossley_dissipation value="1.25" /></drake:proximity_properties></collision></link><joint name="right_shoulder_pitch_link_to_right_shoulder_pitch_link_sphere4" type="fixed"><parent link="right_shoulder_pitch_link" /><child link="right_shoulder_pitch_link_sphere4" /><origin xyz="-0.0036314723547548056 -0.06418315321207047 -0.015317905694246292" rpy="0 0 0" /></joint><link name="right_shoulder_roll_link_sphere1"><inertial><origin xyz="0 0 0" rpy="0 0 0" /><mass value="0.01" /><inertia ixx="0.001" ixy="0" ixz="0" iyy="0.001" iyz="0" izz="0.001" /></inertial><visual><origin rpy="0 0 0" xyz="0 0 0" /><geometry><sphere radius="0.03391823172569275" /></geometry><material name="color_right_shoulder_roll_link_sphere1_0"><color rgba="0.7 0.3 0.7 1.0" /></material></visual><collision><origin rpy="0 0 0" xyz="0 0 0" /><geometry><sphere radius="0.03391823172569275" /></geometry><drake:proximity_properties><drake:rigid_hydroelastic /><drake:mesh_resolution_hint value="1.5" /><drake:hunt_crossley_dissipation value="1.25" /></drake:proximity_properties></collision></link><joint name="right_shoulder_roll_link_to_right_shoulder_roll_link_sphere1" type="fixed"><parent link="right_shoulder_roll_link" /><child link="right_shoulder_roll_link_sphere1" /><origin xyz="-0.007794792763888836 0.00016267904720734805 0.006533690728247166" rpy="0 0 0" /></joint><link name="right_shoulder_roll_link_sphere2"><inertial><origin xyz="0 0 0" rpy="0 0 0" /><mass value="0.01" /><inertia ixx="0.001" ixy="0" ixz="0" iyy="0.001" iyz="0" izz="0.001" /></inertial><visual><origin rpy="0 0 0" xyz="0 0 0" /><geometry><sphere radius="0.04501229152083397" /></geometry><material name="color_right_shoulder_roll_link_sphere2_0"><color rgba="0.7 0.3 0.7 1.0" /></material></visual><collision><origin rpy="0 0 0" xyz="0 0 0" /><geometry><sphere radius="0.04501229152083397" /></geometry><drake:proximity_properties><drake:rigid_hydroelastic /><drake:mesh_resolution_hint value="1.5" /><drake:hunt_crossley_dissipation value="1.25" /></drake:proximity_properties></collision></link><joint name="right_shoulder_roll_link_to_right_shoulder_roll_link_sphere2" type="fixed"><parent link="right_shoulder_roll_link" /><child link="right_shoulder_roll_link_sphere2" /><origin xyz="-0.022845908999443054 -0.00046605110401287675 -0.054240304976701736" rpy="0 0 0" /></joint><link name="right_shoulder_roll_link_sphere3"><inertial><origin xyz="0 0 0" rpy="0 0 0" /><mass value="0.01" /><inertia ixx="0.001" ixy="0" ixz="0" iyy="0.001" iyz="0" izz="0.001" /></inertial><visual><origin rpy="0 0 0" xyz="0 0 0" /><geometry><sphere radius="0.050567254424095154" /></geometry><material name="color_right_shoulder_roll_link_sphere3_0"><color rgba="0.7 0.3 0.7 1.0" /></material></visual><collision><origin rpy="0 0 0" xyz="0 0 0" /><geometry><sphere radius="0.050567254424095154" /></geometry><drake:proximity_properties><drake:rigid_hydroelastic /><drake:mesh_resolution_hint value="1.5" /><drake:hunt_crossley_dissipation value="1.25" /></drake:proximity_properties></collision></link><joint name="right_shoulder_roll_link_to_right_shoulder_roll_link_sphere3" type="fixed"><parent link="right_shoulder_roll_link" /><child link="right_shoulder_roll_link_sphere3" /><origin xyz="-0.03285490348935127 -0.00025381759041920304 -0.10250332206487656" rpy="0 0 0" /></joint><link name="right_shoulder_roll_link_sphere4"><inertial><origin xyz="0 0 0" rpy="0 0 0" /><mass value="0.01" /><inertia ixx="0.001" ixy="0" ixz="0" iyy="0.001" iyz="0" izz="0.001" /></inertial><visual><origin rpy="0 0 0" xyz="0 0 0" /><geometry><sphere radius="0.023292526602745056" /></geometry><material name="color_right_shoulder_roll_link_sphere4_0"><color rgba="0.7 0.3 0.7 1.0" /></material></visual><collision><origin rpy="0 0 0" xyz="0 0 0" /><geometry><sphere radius="0.023292526602745056" /></geometry><drake:proximity_properties><drake:rigid_hydroelastic /><drake:mesh_resolution_hint value="1.5" /><drake:hunt_crossley_dissipation value="1.25" /></drake:proximity_properties></collision></link><joint name="right_shoulder_roll_link_to_right_shoulder_roll_link_sphere4" type="fixed"><parent link="right_shoulder_roll_link" /><child link="right_shoulder_roll_link_sphere4" /><origin xyz="-0.06103086844086647 0.004464376717805862 -0.12745922803878784" rpy="0 0 0" /></joint><link name="right_shoulder_yaw_link_sphere1"><inertial><origin xyz="0 0 0" rpy="0 0 0" /><mass value="0.01" /><inertia ixx="0.001" ixy="0" ixz="0" iyy="0.001" iyz="0" izz="0.001" /></inertial><visual><origin rpy="0 0 0" xyz="0 0 0" /><geometry><sphere radius="0.048116911202669144" /></geometry><material name="color_right_shoulder_yaw_link_sphere1_0"><color rgba="0.6 0.4 0.6 1.0" /></material></visual><collision><origin rpy="0 0 0" xyz="0 0 0" /><geometry><sphere radius="0.048116911202669144" /></geometry><drake:proximity_properties><drake:rigid_hydroelastic /><drake:mesh_resolution_hint value="1.5" /><drake:hunt_crossley_dissipation value="1.25" /></drake:proximity_properties></collision></link><joint name="right_shoulder_yaw_link_to_right_shoulder_yaw_link_sphere1" type="fixed"><parent link="right_shoulder_yaw_link" /><child link="right_shoulder_yaw_link_sphere1" /><origin xyz="0.004131836351007223 0.0029738671146333218 -0.12714512646198273" rpy="0 0 0" /></joint><link name="right_shoulder_yaw_link_sphere2"><inertial><origin xyz="0 0 0" rpy="0 0 0" /><mass value="0.01" /><inertia ixx="0.001" ixy="0" ixz="0" iyy="0.001" iyz="0" izz="0.001" /></inertial><visual><origin rpy="0 0 0" xyz="0 0 0" /><geometry><sphere radius="0.046725839376449585" /></geometry><material name="color_right_shoulder_yaw_link_sphere2_0"><color rgba="0.6 0.4 0.6 1.0" /></material></visual><collision><origin rpy="0 0 0" xyz="0 0 0" /><geometry><sphere radius="0.046725839376449585" /></geometry><drake:proximity_properties><drake:rigid_hydroelastic /><drake:mesh_resolution_hint value="1.5" /><drake:hunt_crossley_dissipation value="1.25" /></drake:proximity_properties></collision></link><joint name="right_shoulder_yaw_link_to_right_shoulder_yaw_link_sphere2" type="fixed"><parent link="right_shoulder_yaw_link" /><child link="right_shoulder_yaw_link_sphere2" /><origin xyz="0.0025214676279574633 0.002017176477238536 -0.07783379405736923" rpy="0 0 0" /></joint><link name="right_shoulder_yaw_link_sphere3"><inertial><origin xyz="0 0 0" rpy="0 0 0" /><mass value="0.01" /><inertia ixx="0.001" ixy="0" ixz="0" iyy="0.001" iyz="0" izz="0.001" /></inertial><visual><origin rpy="0 0 0" xyz="0 0 0" /><geometry><sphere radius="0.04528370872139931" /></geometry><material name="color_right_shoulder_yaw_link_sphere3_0"><color rgba="0.6 0.4 0.6 1.0" /></material></visual><collision><origin rpy="0 0 0" xyz="0 0 0" /><geometry><sphere radius="0.04528370872139931" /></geometry><drake:proximity_properties><drake:rigid_hydroelastic /><drake:mesh_resolution_hint value="1.5" /><drake:hunt_crossley_dissipation value="1.25" /></drake:proximity_properties></collision></link><joint name="right_shoulder_yaw_link_to_right_shoulder_yaw_link_sphere3" type="fixed"><parent link="right_shoulder_yaw_link" /><child link="right_shoulder_yaw_link_sphere3" /><origin xyz="0.0011243813205510378 0.0009208439732901752 -0.03266278654336929" rpy="0 0 0" /></joint><link name="right_shoulder_yaw_link_sphere4"><inertial><origin xyz="0 0 0" rpy="0 0 0" /><mass value="0.01" /><inertia ixx="0.001" ixy="0" ixz="0" iyy="0.001" iyz="0" izz="0.001" /></inertial><visual><origin rpy="0 0 0" xyz="0 0 0" /><geometry><sphere radius="0.04820146784186363" /></geometry><material name="color_right_shoulder_yaw_link_sphere4_0"><color rgba="0.6 0.4 0.6 1.0" /></material></visual><collision><origin rpy="0 0 0" xyz="0 0 0" /><geometry><sphere radius="0.04820146784186363" /></geometry><drake:proximity_properties><drake:rigid_hydroelastic /><drake:mesh_resolution_hint value="1.5" /><drake:hunt_crossley_dissipation value="1.25" /></drake:proximity_properties></collision></link><joint name="right_shoulder_yaw_link_to_right_shoulder_yaw_link_sphere4" type="fixed"><parent link="right_shoulder_yaw_link" /><child link="right_shoulder_yaw_link_sphere4" /><origin xyz="0.006330971606075764 0.0038623132277280092 -0.18431489169597626" rpy="0 0 0" /></joint><link name="right_elbow_pitch_link_sphere1"><inertial><origin xyz="0 0 0" rpy="0 0 0" /><mass value="0.01" /><inertia ixx="0.001" ixy="0" ixz="0" iyy="0.001" iyz="0" izz="0.001" /></inertial><visual><origin rpy="0 0 0" xyz="0 0 0" /><geometry><sphere radius="0.0382736511528492" /></geometry><material name="color_right_elbow_pitch_link_sphere1_0"><color rgba="0.5 0.5 0.7 1.0" /></material></visual><collision><origin rpy="0 0 0" xyz="0 0 0" /><geometry><sphere radius="0.0382736511528492" /></geometry><drake:proximity_properties><drake:rigid_hydroelastic /><drake:mesh_resolution_hint value="1.5" /><drake:hunt_crossley_dissipation value="1.25" /></drake:proximity_properties></collision></link><joint name="right_elbow_pitch_link_to_right_elbow_pitch_link_sphere1" type="fixed"><parent link="right_elbow_pitch_link" /><child link="right_elbow_pitch_link_sphere1" /><origin xyz="0.029711127281188965 0.02060660347342491 -0.0046361288987100124" rpy="0 0 0" /></joint><link name="right_elbow_pitch_link_sphere2"><inertial><origin xyz="0 0 0" rpy="0 0 0" /><mass value="0.01" /><inertia ixx="0.001" ixy="0" ixz="0" iyy="0.001" iyz="0" izz="0.001" /></inertial><visual><origin rpy="0 0 0" xyz="0 0 0" /><geometry><sphere radius="0.03960632160305977" /></geometry><material name="color_right_elbow_pitch_link_sphere2_0"><color rgba="0.5 0.5 0.7 1.0" /></material></visual><collision><origin rpy="0 0 0" xyz="0 0 0" /><geometry><sphere radius="0.03960632160305977" /></geometry><drake:proximity_properties><drake:rigid_hydroelastic /><drake:mesh_resolution_hint value="1.5" /><drake:hunt_crossley_dissipation value="1.25" /></drake:proximity_properties></collision></link><joint name="right_elbow_pitch_link_to_right_elbow_pitch_link_sphere2" type="fixed"><parent link="right_elbow_pitch_link" /><child link="right_elbow_pitch_link_sphere2" /><origin xyz="0.06145494803786278 0.028429001569747925 -0.008579103276133537" rpy="0 0 0" /></joint><link name="right_elbow_pitch_link_sphere3"><inertial><origin xyz="0 0 0" rpy="0 0 0" /><mass value="0.01" /><inertia ixx="0.001" ixy="0" ixz="0" iyy="0.001" iyz="0" izz="0.001" /></inertial><visual><origin rpy="0 0 0" xyz="0 0 0" /><geometry><sphere radius="0.037904903292655945" /></geometry><material name="color_right_elbow_pitch_link_sphere3_0"><color rgba="0.5 0.5 0.7 1.0" /></material></visual><collision><origin rpy="0 0 0" xyz="0 0 0" /><geometry><sphere radius="0.037904903292655945" /></geometry><drake:proximity_properties><drake:rigid_hydroelastic /><drake:mesh_resolution_hint value="1.5" /><drake:hunt_crossley_dissipation value="1.25" /></drake:proximity_properties></collision></link><joint name="right_elbow_pitch_link_to_right_elbow_pitch_link_sphere3" type="fixed"><parent link="right_elbow_pitch_link" /><child link="right_elbow_pitch_link_sphere3" /><origin xyz="0.09313949197530746 0.030934862792491913 -0.009676174260675907" rpy="0 0 0" /></joint><link name="right_elbow_pitch_link_sphere4"><inertial><origin xyz="0 0 0" rpy="0 0 0" /><mass value="0.01" /><inertia ixx="0.001" ixy="0" ixz="0" iyy="0.001" iyz="0" izz="0.001" /></inertial><visual><origin rpy="0 0 0" xyz="0 0 0" /><geometry><sphere radius="0.02760862559080124" /></geometry><material name="color_right_elbow_pitch_link_sphere4_0"><color rgba="0.5 0.5 0.7 1.0" /></material></visual><collision><origin rpy="0 0 0" xyz="0 0 0" /><geometry><sphere radius="0.02760862559080124" /></geometry><drake:proximity_properties><drake:rigid_hydroelastic /><drake:mesh_resolution_hint value="1.5" /><drake:hunt_crossley_dissipation value="1.25" /></drake:proximity_properties></collision></link><joint name="right_elbow_pitch_link_to_right_elbow_pitch_link_sphere4" type="fixed"><parent link="right_elbow_pitch_link" /><child link="right_elbow_pitch_link_sphere4" /><origin xyz="-0.016005072742700577 0.008525704964995384 0.0034130725543946028" rpy="0 0 0" /></joint><link name="right_elbow_roll_link_sphere1"><inertial><origin xyz="0 0 0" rpy="0 0 0" /><mass value="0.01" /><inertia ixx="0.001" ixy="0" ixz="0" iyy="0.001" iyz="0" izz="0.001" /></inertial><visual><origin rpy="0 0 0" xyz="0 0 0" /><geometry><sphere radius="0.03960876166820526" /></geometry><material name="color_right_elbow_roll_link_sphere1_0"><color rgba="0.4 0.6 0.8 1.0" /></material></visual><collision><origin rpy="0 0 0" xyz="0 0 0" /><geometry><sphere radius="0.03960876166820526" /></geometry><drake:proximity_properties><drake:rigid_hydroelastic /><drake:mesh_resolution_hint value="1.5" /><drake:hunt_crossley_dissipation value="1.25" /></drake:proximity_properties></collision></link><joint name="right_elbow_roll_link_to_right_elbow_roll_link_sphere1" type="fixed"><parent link="right_elbow_roll_link" /><child link="right_elbow_roll_link_sphere1" /><origin xyz="0.033063508570194244 0.0012104966444894671 -0.00012280582450330257" rpy="0 0 0" /></joint><link name="right_elbow_roll_link_sphere2"><inertial><origin xyz="0 0 0" rpy="0 0 0" /><mass value="0.01" /><inertia ixx="0.001" ixy="0" ixz="0" iyy="0.001" iyz="0" izz="0.001" /></inertial><visual><origin rpy="0 0 0" xyz="0 0 0" /><geometry><sphere radius="0.022890526801347733" /></geometry><material name="color_right_elbow_roll_link_sphere2_0"><color rgba="0.4 0.6 0.8 1.0" /></material></visual><collision><origin rpy="0 0 0" xyz="0 0 0" /><geometry><sphere radius="0.022890526801347733" /></geometry><drake:proximity_properties><drake:rigid_hydroelastic /><drake:mesh_resolution_hint value="1.5" /><drake:hunt_crossley_dissipation value="1.25" /></drake:proximity_properties></collision></link><joint name="right_elbow_roll_link_to_right_elbow_roll_link_sphere2" type="fixed"><parent link="right_elbow_roll_link" /><child link="right_elbow_roll_link_sphere2" /><origin xyz="0.019108707085251808 -0.014461268670856953 0.012271201238036156" rpy="0 0 0" /></joint><link name="right_elbow_roll_link_sphere3"><inertial><origin xyz="0 0 0" rpy="0 0 0" /><mass value="0.01" /><inertia ixx="0.001" ixy="0" ixz="0" iyy="0.001" iyz="0" izz="0.001" /></inertial><visual><origin rpy="0 0 0" xyz="0 0 0" /><geometry><sphere radius="0.037413500249385834" /></geometry><material name="color_right_elbow_roll_link_sphere3_0"><color rgba="0.4 0.6 0.8 1.0" /></material></visual><collision><origin rpy="0 0 0" xyz="0 0 0" /><geometry><sphere radius="0.037413500249385834" /></geometry><drake:proximity_properties><drake:rigid_hydroelastic /><drake:mesh_resolution_hint value="1.5" /><drake:hunt_crossley_dissipation value="1.25" /></drake:proximity_properties></collision></link><joint name="right_elbow_roll_link_to_right_elbow_roll_link_sphere3" type="fixed"><parent link="right_elbow_roll_link" /><child link="right_elbow_roll_link_sphere3" /><origin xyz="0.05928383767604828 0.0008979005506262183 0.0001784294581739232" rpy="0 0 0" /></joint><link name="right_elbow_roll_link_sphere4"><inertial><origin xyz="0 0 0" rpy="0 0 0" /><mass value="0.01" /><inertia ixx="0.001" ixy="0" ixz="0" iyy="0.001" iyz="0" izz="0.001" /></inertial><visual><origin rpy="0 0 0" xyz="0 0 0" /><geometry><sphere radius="0.018358660861849785" /></geometry><material name="color_right_elbow_roll_link_sphere4_0"><color rgba="0.4 0.6 0.8 1.0" /></material></visual><collision><origin rpy="0 0 0" xyz="0 0 0" /><geometry><sphere radius="0.018358660861849785" /></geometry><drake:proximity_properties><drake:rigid_hydroelastic /><drake:mesh_resolution_hint value="1.5" /><drake:hunt_crossley_dissipation value="1.25" /></drake:proximity_properties></collision></link><joint name="right_elbow_roll_link_to_right_elbow_roll_link_sphere4" type="fixed"><parent link="right_elbow_roll_link" /><child link="right_elbow_roll_link_sphere4" /><origin xyz="0.015453869476914406 0.01637171022593975 -0.01631845347583294" rpy="0 0 0" /></joint><link name="right_wrist_pitch_link_sphere1"><inertial><origin xyz="0 0 0" rpy="0 0 0" /><mass value="0.01" /><inertia ixx="0.001" ixy="0" ixz="0" iyy="0.001" iyz="0" izz="0.001" /></inertial><visual><origin rpy="0 0 0" xyz="0 0 0" /><geometry><sphere radius="0.015381394885480404" /></geometry><material name="color_right_wrist_pitch_link_sphere1_0"><color rgba="0.3 0.7 0.9 1.0" /></material></visual><collision><origin rpy="0 0 0" xyz="0 0 0" /><geometry><sphere radius="0.015381394885480404" /></geometry><drake:proximity_properties><drake:rigid_hydroelastic /><drake:mesh_resolution_hint value="1.5" /><drake:hunt_crossley_dissipation value="1.25" /></drake:proximity_properties></collision></link><joint name="right_wrist_pitch_link_to_right_wrist_pitch_link_sphere1" type="fixed"><parent link="right_wrist_pitch_link" /><child link="right_wrist_pitch_link_sphere1" /><origin xyz="0.03797690570354462 -0.006935482379049063 0.018643150106072426" rpy="0 0 0" /></joint><link name="right_wrist_pitch_link_sphere2"><inertial><origin xyz="0 0 0" rpy="0 0 0" /><mass value="0.01" /><inertia ixx="0.001" ixy="0" ixz="0" iyy="0.001" iyz="0" izz="0.001" /></inertial><visual><origin rpy="0 0 0" xyz="0 0 0" /><geometry><sphere radius="0.03540808707475662" /></geometry><material name="color_right_wrist_pitch_link_sphere2_0"><color rgba="0.3 0.7 0.9 1.0" /></material></visual><collision><origin rpy="0 0 0" xyz="0 0 0" /><geometry><sphere radius="0.03540808707475662" /></geometry><drake:proximity_properties><drake:rigid_hydroelastic /><drake:mesh_resolution_hint value="1.5" /><drake:hunt_crossley_dissipation value="1.25" /></drake:proximity_properties></collision></link><joint name="right_wrist_pitch_link_to_right_wrist_pitch_link_sphere2" type="fixed"><parent link="right_wrist_pitch_link" /><child link="right_wrist_pitch_link_sphere2" /><origin xyz="0.019621985033154488 6.134451541583985e-05 -0.0010614283382892609" rpy="0 0 0" /></joint><link name="right_wrist_pitch_link_sphere3"><inertial><origin xyz="0 0 0" rpy="0 0 0" /><mass value="0.01" /><inertia ixx="0.001" ixy="0" ixz="0" iyy="0.001" iyz="0" izz="0.001" /></inertial><visual><origin rpy="0 0 0" xyz="0 0 0" /><geometry><sphere radius="0.02059900388121605" /></geometry><material name="color_right_wrist_pitch_link_sphere3_0"><color rgba="0.3 0.7 0.9 1.0" /></material></visual><collision><origin rpy="0 0 0" xyz="0 0 0" /><geometry><sphere radius="0.02059900388121605" /></geometry><drake:proximity_properties><drake:rigid_hydroelastic /><drake:mesh_resolution_hint value="1.5" /><drake:hunt_crossley_dissipation value="1.25" /></drake:proximity_properties></collision></link><joint name="right_wrist_pitch_link_to_right_wrist_pitch_link_sphere3" type="fixed"><parent link="right_wrist_pitch_link" /><child link="right_wrist_pitch_link_sphere3" /><origin xyz="0.010351959615945816 -0.015193742699921131 0.013112466782331467" rpy="0 0 0" /></joint><link name="right_wrist_pitch_link_sphere4"><inertial><origin xyz="0 0 0" rpy="0 0 0" /><mass value="0.01" /><inertia ixx="0.001" ixy="0" ixz="0" iyy="0.001" iyz="0" izz="0.001" /></inertial><visual><origin rpy="0 0 0" xyz="0 0 0" /><geometry><sphere radius="0.02025727555155754" /></geometry><material name="color_right_wrist_pitch_link_sphere4_0"><color rgba="0.3 0.7 0.9 1.0" /></material></visual><collision><origin rpy="0 0 0" xyz="0 0 0" /><geometry><sphere radius="0.02025727555155754" /></geometry><drake:proximity_properties><drake:rigid_hydroelastic /><drake:mesh_resolution_hint value="1.5" /><drake:hunt_crossley_dissipation value="1.25" /></drake:proximity_properties></collision></link><joint name="right_wrist_pitch_link_to_right_wrist_pitch_link_sphere4" type="fixed"><parent link="right_wrist_pitch_link" /><child link="right_wrist_pitch_link_sphere4" /><origin xyz="0.010425852611660957 0.014840397983789444 0.013168013654649258" rpy="0 0 0" /></joint><link name="right_wrist_yaw_link_sphere1"><inertial><origin xyz="0 0 0" rpy="0 0 0" /><mass value="0.01" /><inertia ixx="0.001" ixy="0" ixz="0" iyy="0.001" iyz="0" izz="0.001" /></inertial><visual><origin rpy="0 0 0" xyz="0 0 0" /><geometry><sphere radius="0.031719133257865906" /></geometry><material name="color_right_wrist_yaw_link_sphere1_0"><color rgba="0.2 0.8 0.8 1.0" /></material></visual><collision><origin rpy="0 0 0" xyz="0 0 0" /><geometry><sphere radius="0.031719133257865906" /></geometry><drake:proximity_properties><drake:rigid_hydroelastic /><drake:mesh_resolution_hint value="1.5" /><drake:hunt_crossley_dissipation value="1.25" /></drake:proximity_properties></collision></link><joint name="right_wrist_yaw_link_to_right_wrist_yaw_link_sphere1" type="fixed"><parent link="right_wrist_yaw_link" /><child link="right_wrist_yaw_link_sphere1" /><origin xyz="0.03247670456767082 -9.962782496586442e-05 -0.011775790713727474" rpy="0 0 0" /></joint><link name="right_wrist_yaw_link_sphere2"><inertial><origin xyz="0 0 0" rpy="0 0 0" /><mass value="0.01" /><inertia ixx="0.001" ixy="0" ixz="0" iyy="0.001" iyz="0" izz="0.001" /></inertial><visual><origin rpy="0 0 0" xyz="0 0 0" /><geometry><sphere radius="0.03158062696456909" /></geometry><material name="color_right_wrist_yaw_link_sphere2_0"><color rgba="0.2 0.8 0.8 1.0" /></material></visual><collision><origin rpy="0 0 0" xyz="0 0 0" /><geometry><sphere radius="0.03158062696456909" /></geometry><drake:proximity_properties><drake:rigid_hydroelastic /><drake:mesh_resolution_hint value="1.5" /><drake:hunt_crossley_dissipation value="1.25" /></drake:proximity_properties></collision></link><joint name="right_wrist_yaw_link_to_right_wrist_yaw_link_sphere2" type="fixed"><parent link="right_wrist_yaw_link" /><child link="right_wrist_yaw_link_sphere2" /><origin xyz="0.03258088231086731 -0.00010324588947696611 0.011581777594983578" rpy="0 0 0" /></joint><link name="right_wrist_yaw_link_sphere3"><inertial><origin xyz="0 0 0" rpy="0 0 0" /><mass value="0.01" /><inertia ixx="0.001" ixy="0" ixz="0" iyy="0.001" iyz="0" izz="0.001" /></inertial><visual><origin rpy="0 0 0" xyz="0 0 0" /><geometry><sphere radius="0.024466942995786667" /></geometry><material name="color_right_wrist_yaw_link_sphere3_0"><color rgba="0.2 0.8 0.8 1.0" /></material></visual><collision><origin rpy="0 0 0" xyz="0 0 0" /><geometry><sphere radius="0.024466942995786667" /></geometry><drake:proximity_properties><drake:rigid_hydroelastic /><drake:mesh_resolution_hint value="1.5" /><drake:hunt_crossley_dissipation value="1.25" /></drake:proximity_properties></collision></link><joint name="right_wrist_yaw_link_to_right_wrist_yaw_link_sphere3" type="fixed"><parent link="right_wrist_yaw_link" /><child link="right_wrist_yaw_link_sphere3" /><origin xyz="0.0024220168124884367 -0.00017540311091579497 -0.021501706913113594" rpy="0 0 0" /></joint><link name="right_wrist_yaw_link_sphere4"><inertial><origin xyz="0 0 0" rpy="0 0 0" /><mass value="0.01" /><inertia ixx="0.001" ixy="0" ixz="0" iyy="0.001" iyz="0" izz="0.001" /></inertial><visual><origin rpy="0 0 0" xyz="0 0 0" /><geometry><sphere radius="0.02487834542989731" /></geometry><material name="color_right_wrist_yaw_link_sphere4_0"><color rgba="0.2 0.8 0.8 1.0" /></material></visual><collision><origin rpy="0 0 0" xyz="0 0 0" /><geometry><sphere radius="0.02487834542989731" /></geometry><drake:proximity_properties><drake:rigid_hydroelastic /><drake:mesh_resolution_hint value="1.5" /><drake:hunt_crossley_dissipation value="1.25" /></drake:proximity_properties></collision></link><joint name="right_wrist_yaw_link_to_right_wrist_yaw_link_sphere4" type="fixed"><parent link="right_wrist_yaw_link" /><child link="right_wrist_yaw_link_sphere4" /><origin xyz="0.002988561987876892 -8.413253090111539e-05 0.021157046779990196" rpy="0 0 0" /></joint><link name="L_hand_base_link_sphere1"><inertial><origin xyz="0 0 0" rpy="0 0 0" /><mass value="0.01" /><inertia ixx="0.001" ixy="0" ixz="0" iyy="0.001" iyz="0" izz="0.001" /></inertial><visual><origin rpy="0 0 0" xyz="0 0 0" /><geometry><sphere radius="0.033237919211387634" /></geometry><material name="color_L_hand_base_link_sphere1_0"><color rgba="0.2 0.9 0.9 1.0" /></material></visual><collision><origin rpy="0 0 0" xyz="0 0 0" /><geometry><sphere radius="0.033237919211387634" /></geometry><drake:proximity_properties><drake:rigid_hydroelastic /><drake:mesh_resolution_hint value="1.5" /><drake:hunt_crossley_dissipation value="1.25" /></drake:proximity_properties></collision></link><joint name="L_hand_base_link_to_L_hand_base_link_sphere1" type="fixed"><parent link="L_hand_base_link" /><child link="L_hand_base_link_sphere1" /><origin xyz="-0.0009473565733060241 -0.06377485394477844 -0.0024058581329882145" rpy="0 0 0" /></joint><link name="L_hand_base_link_sphere2"><inertial><origin xyz="0 0 0" rpy="0 0 0" /><mass value="0.01" /><inertia ixx="0.001" ixy="0" ixz="0" iyy="0.001" iyz="0" izz="0.001" /></inertial><visual><origin rpy="0 0 0" xyz="0 0 0" /><geometry><sphere radius="0.031840622425079346" /></geometry><material name="color_L_hand_base_link_sphere2_0"><color rgba="0.2 0.9 0.9 1.0" /></material></visual><collision><origin rpy="0 0 0" xyz="0 0 0" /><geometry><sphere radius="0.031840622425079346" /></geometry><drake:proximity_properties><drake:rigid_hydroelastic /><drake:mesh_resolution_hint value="1.5" /><drake:hunt_crossley_dissipation value="1.25" /></drake:proximity_properties></collision></link><joint name="L_hand_base_link_to_L_hand_base_link_sphere2" type="fixed"><parent link="L_hand_base_link" /><child link="L_hand_base_link_sphere2" /><origin xyz="-0.0006277027423493564 -0.0251330379396677 -0.0004000853223260492" rpy="0 0 0" /></joint><link name="L_hand_base_link_sphere3"><inertial><origin xyz="0 0 0" rpy="0 0 0" /><mass value="0.01" /><inertia ixx="0.001" ixy="0" ixz="0" iyy="0.001" iyz="0" izz="0.001" /></inertial><visual><origin rpy="0 0 0" xyz="0 0 0" /><geometry><sphere radius="0.023020023480057716" /></geometry><material name="color_L_hand_base_link_sphere3_0"><color rgba="0.2 0.9 0.9 1.0" /></material></visual><collision><origin rpy="0 0 0" xyz="0 0 0" /><geometry><sphere radius="0.023020023480057716" /></geometry><drake:proximity_properties><drake:rigid_hydroelastic /><drake:mesh_resolution_hint value="1.5" /><drake:hunt_crossley_dissipation value="1.25" /></drake:proximity_properties></collision></link><joint name="L_hand_base_link_to_L_hand_base_link_sphere3" type="fixed"><parent link="L_hand_base_link" /><child link="L_hand_base_link_sphere3" /><origin xyz="0.0016109059797599912 -0.11427129805088043 -0.02197253704071045" rpy="0 0 0" /></joint><link name="L_hand_base_link_sphere4"><inertial><origin xyz="0 0 0" rpy="0 0 0" /><mass value="0.01" /><inertia ixx="0.001" ixy="0" ixz="0" iyy="0.001" iyz="0" izz="0.001" /></inertial><visual><origin rpy="0 0 0" xyz="0 0 0" /><geometry><sphere radius="0.022611647844314575" /></geometry><material name="color_L_hand_base_link_sphere4_0"><color rgba="0.2 0.9 0.9 1.0" /></material></visual><collision><origin rpy="0 0 0" xyz="0 0 0" /><geometry><sphere radius="0.022611647844314575" /></geometry><drake:proximity_properties><drake:rigid_hydroelastic /><drake:mesh_resolution_hint value="1.5" /><drake:hunt_crossley_dissipation value="1.25" /></drake:proximity_properties></collision></link><joint name="L_hand_base_link_to_L_hand_base_link_sphere4" type="fixed"><parent link="L_hand_base_link" /><child link="L_hand_base_link_sphere4" /><origin xyz="0.0016778403660282493 -0.11523733288049698 0.018877694383263588" rpy="0 0 0" /></joint><link name="R_hand_base_link_sphere1"><inertial><origin xyz="0 0 0" rpy="0 0 0" /><mass value="0.01" /><inertia ixx="0.001" ixy="0" ixz="0" iyy="0.001" iyz="0" izz="0.001" /></inertial><visual><origin rpy="0 0 0" xyz="0 0 0" /><geometry><sphere radius="0.03198834881186485" /></geometry><material name="color_R_hand_base_link_sphere1_0"><color rgba="0.9 0.6 0.2 1.0" /></material></visual><collision><origin rpy="0 0 0" xyz="0 0 0" /><geometry><sphere radius="0.03198834881186485" /></geometry><drake:proximity_properties><drake:rigid_hydroelastic /><drake:mesh_resolution_hint value="1.5" /><drake:hunt_crossley_dissipation value="1.25" /></drake:proximity_properties></collision></link><joint name="R_hand_base_link_to_R_hand_base_link_sphere1" type="fixed"><parent link="R_hand_base_link" /><child link="R_hand_base_link_sphere1" /><origin xyz="-0.0005932340282015502 -0.025933803990483284 0.00043479862506501377" rpy="0 0 0" /></joint><link name="R_hand_base_link_sphere2"><inertial><origin xyz="0 0 0" rpy="0 0 0" /><mass value="0.01" /><inertia ixx="0.001" ixy="0" ixz="0" iyy="0.001" iyz="0" izz="0.001" /></inertial><visual><origin rpy="0 0 0" xyz="0 0 0" /><geometry><sphere radius="0.022581230849027634" /></geometry><material name="color_R_hand_base_link_sphere2_0"><color rgba="0.9 0.6 0.2 1.0" /></material></visual><collision><origin rpy="0 0 0" xyz="0 0 0" /><geometry><sphere radius="0.022581230849027634" /></geometry><drake:proximity_properties><drake:rigid_hydroelastic /><drake:mesh_resolution_hint value="1.5" /><drake:hunt_crossley_dissipation value="1.25" /></drake:proximity_properties></collision></link><joint name="R_hand_base_link_to_R_hand_base_link_sphere2" type="fixed"><parent link="R_hand_base_link" /><child link="R_hand_base_link_sphere2" /><origin xyz="0.001230877940542996 -0.11561069637537003 -0.019020669162273407" rpy="0 0 0" /></joint><link name="R_hand_base_link_sphere3"><inertial><origin xyz="0 0 0" rpy="0 0 0" /><mass value="0.01" /><inertia ixx="0.001" ixy="0" ixz="0" iyy="0.001" iyz="0" izz="0.001" /></inertial><visual><origin rpy="0 0 0" xyz="0 0 0" /><geometry><sphere radius="0.033474840223789215" /></geometry><material name="color_R_hand_base_link_sphere3_0"><color rgba="0.9 0.6 0.2 1.0" /></material></visual><collision><origin rpy="0 0 0" xyz="0 0 0" /><geometry><sphere radius="0.033474840223789215" /></geometry><drake:proximity_properties><drake:rigid_hydroelastic /><drake:mesh_resolution_hint value="1.5" /><drake:hunt_crossley_dissipation value="1.25" /></drake:proximity_properties></collision></link><joint name="R_hand_base_link_to_R_hand_base_link_sphere3" type="fixed"><parent link="R_hand_base_link" /><child link="R_hand_base_link_sphere3" /><origin xyz="-0.000934883370064199 -0.06413783878087997 0.002412996953353286" rpy="0 0 0" /></joint><link name="R_hand_base_link_sphere4"><inertial><origin xyz="0 0 0" rpy="0 0 0" /><mass value="0.01" /><inertia ixx="0.001" ixy="0" ixz="0" iyy="0.001" iyz="0" izz="0.001" /></inertial><visual><origin rpy="0 0 0" xyz="0 0 0" /><geometry><sphere radius="0.022770613431930542" /></geometry><material name="color_R_hand_base_link_sphere4_0"><color rgba="0.9 0.6 0.2 1.0" /></material></visual><collision><origin rpy="0 0 0" xyz="0 0 0" /><geometry><sphere radius="0.022770613431930542" /></geometry><drake:proximity_properties><drake:rigid_hydroelastic /><drake:mesh_resolution_hint value="1.5" /><drake:hunt_crossley_dissipation value="1.25" /></drake:proximity_properties></collision></link><joint name="R_hand_base_link_to_R_hand_base_link_sphere4" type="fixed"><parent link="R_hand_base_link" /><child link="R_hand_base_link_sphere4" /><origin xyz="0.0016457666642963886 -0.11479291319847107 0.022344710305333138" rpy="0 0 0" /></joint></robot>
