<?xml version='1.0' encoding='utf-8'?>
<robot name="h1_5">

  <link name="world" /><joint name="floating_base_joint" type="floating"><parent link="world" /><child link="pelvis" /><origin xyz="0 0 0" rpy="0 0 0" /></joint><mujoco>
    <compiler meshdir="meshes" discardvisual="false" />
  </mujoco>

  <!-- [CAUTION] uncomment when convert to mujoco -->
  <!-- <link name="world"></link>
  <joint name="floating_base_joint" type="floating">
    <parent link="world"/>
    <child link="pelvis"/>
  </joint> -->

  <link name="pelvis">
    <inertial>
      <origin xyz="-0.0004 3.7E-05 -0.046864" rpy="0 0 0" />
      <mass value="5.983" />
      <inertia ixx="49168.411E-06" ixy="-19.869E-06" ixz="-48.460E-06" iyy="9025.844E-06" iyz="3.431E-06" izz="53155.891E-06" />
    </inertial>
    </link>

  <!-- L Leg -->
  <link name="left_hip_yaw_link">
    <inertial>
      <origin xyz="0 -0.026197 0.006647" rpy="0 0 0" />
      <mass value="2.829" />
      <inertia ixx="4553.605E-06" ixy="0.005E-06" ixz="0.817E-06" iyy="5688.730E-06" iyz="-345.157E-06" izz="3548.907E-06" />
    </inertial>
    </link>
  <joint name="left_hip_yaw_joint" type="revolute">
    <origin xyz="0 0.0875 -0.1632" rpy="0 0 0" />
    <parent link="pelvis" />
    <child link="left_hip_yaw_link" />
    <axis xyz="0 0 1" />
    <limit lower="-0.43" upper="0.43" effort="200" velocity="23" />
  </joint>
  <link name="left_hip_pitch_link">
    <inertial>
      <origin xyz="-0.00781 -0.004724 -0.000063" rpy="0 0 0" />
      <mass value="2.920" />
      <inertia ixx="5594.7E-06" ixy="143.308E-06" ixz="-11.847E-06" iyy="3862.581E-06" iyz="-9.607E-06" izz="4450.563E-06" />
    </inertial>
    </link>
  <joint name="left_hip_pitch_joint" type="revolute">
    <origin xyz="0 0.0755 0" rpy="0 0 0" />
    <parent link="left_hip_yaw_link" />
    <child link="left_hip_pitch_link" />
    <axis xyz="0 1 0" />
    <limit lower="-3.14" upper="2.5" effort="200" velocity="23" />
  </joint>
  <link name="left_hip_roll_link">
    <inertial>
      <origin xyz="0.004171 -0.008576 -0.194509" rpy="0 0 0" />
      <mass value="4.962" />
      <inertia ixx="46305.869E-06" ixy="-322.626E-06" ixz="-1199.703E-06" iyy="47955.402E-06" iyz="288.147E-06" izz="8914.518E-06" />
    </inertial>
    </link>
  <joint name="left_hip_roll_joint" type="revolute">
    <origin xyz="0 0 0" rpy="0 0 0" />
    <parent link="left_hip_pitch_link" />
    <child link="left_hip_roll_link" />
    <axis xyz="1 0 0" />
    <limit lower="-0.43" upper="3.14" effort="200" velocity="23" />
  </joint>
  <link name="left_knee_link">
    <inertial>
      <origin xyz="0.000179 0.000121 -0.168936" rpy="0 0 0" />
      <mass value="3.839" />
      <inertia ixx="39002.363e-6" ixy="-72.364e-6" ixz="-794.506e-6" iyy="39042.376e-6" iyz="-18.663e-6" izz="5029.829e-6" />
    </inertial>
    </link>
  <joint name="left_knee_joint" type="revolute">
    <origin xyz="0 0 -0.4" rpy="0 0 0" />
    <parent link="left_hip_roll_link" />
    <child link="left_knee_link" />
    <axis xyz="0 1 0" />
    <limit lower="-0.26" upper="2.05" effort="300" velocity="14" />
  </joint>
  <link name="left_ankle_pitch_link">
    <inertial>
      <origin xyz="-0.000294 0 -0.010794" rpy="0 0 0" />
      <mass value="0.102" />
      <inertia ixx="0.000023944" ixy="0" ixz="0.000000121" iyy="0.000021837" iyz="0" izz="0.000013414" />
    </inertial>
    </link>
  <joint name="left_ankle_pitch_joint" type="revolute">
    <origin xyz="0 0 -0.4" rpy="0 0 0" />
    <parent link="left_knee_link" />
    <child link="left_ankle_pitch_link" />
    <axis xyz="0 1 0" />
    <limit lower="-0.897334" upper="0.523598" effort="60" velocity="9" />
  </joint>
  <link name="left_ankle_roll_link">
    <inertial>
      <origin xyz="0.029589 0 -0.015973" rpy="0 0 0" />
      <mass value="0.747" />
      <inertia ixx="648.830e-6" ixy="0" ixz="158.380e-6" iyy="3435.339e-6" iyz="0" izz="3583.259e-6" />
    </inertial>
    </link>
  <joint name="left_ankle_roll_joint" type="revolute">
    <origin xyz="0 0 -0.02" rpy="0 0 0" />
    <parent link="left_ankle_pitch_link" />
    <child link="left_ankle_roll_link" />
    <axis xyz="1 0 0" />
    <limit lower="-0.261799" upper="0.261799" effort="40" velocity="9" />
  </joint>

  <!-- R Leg -->
  <link name="right_hip_yaw_link">
    <inertial>
      <origin xyz="0 0.026197 0.006647" rpy="0 0 0" />
      <mass value="2.829" />
      <inertia ixx="4553.605E-06" ixy="-0.005E-06" ixz="0.817E-06" iyy="5688.730E-06" iyz="345.157E-06" izz="3548.907E-06" />
    </inertial>
    </link>
  <joint name="right_hip_yaw_joint" type="revolute">
    <origin xyz="0 -0.0875 -0.1632" rpy="0 0 0" />
    <parent link="pelvis" />
    <child link="right_hip_yaw_link" />
    <axis xyz="0 0 1" />
    <limit lower="-0.43" upper="0.43" effort="200" velocity="23" />
  </joint>
  <link name="right_hip_pitch_link">
    <inertial>
      <origin xyz="-0.00781 0.004724 -0.000063" rpy="0 0 0" />
      <mass value="2.920" />
      <inertia ixx="5594.7E-06" ixy="-143.308E-06" ixz="-11.847E-06" iyy="3862.581E-06" iyz="9.607E-06" izz="4450.563E-06" />
    </inertial>
    </link>
  <joint name="right_hip_pitch_joint" type="revolute">
    <origin xyz="0 -0.0755 0" rpy="0 0 0" />
    <parent link="right_hip_yaw_link" />
    <child link="right_hip_pitch_link" />
    <axis xyz="0 1 0" />
    <limit lower="-3.14" upper="2.5" effort="200" velocity="23" />
  </joint>
  <link name="right_hip_roll_link">
    <inertial>
      <origin xyz="0.004171 0.008576 -0.194509" rpy="0 0 0" />
      <mass value="4.962" />
      <inertia ixx="46305.869E-06" ixy="322.626E-06" ixz="-1199.703E-06" iyy="47955.402E-06" iyz="-288.147E-06" izz="8914.518E-06" />
    </inertial>
    </link>
  <joint name="right_hip_roll_joint" type="revolute">
    <origin xyz="0 0 0" rpy="0 0 0" />
    <parent link="right_hip_pitch_link" />
    <child link="right_hip_roll_link" />
    <axis xyz="1 0 0" />
    <limit lower="-3.14" upper="0.43" effort="200" velocity="23" />
  </joint>
  <link name="right_knee_link">
    <inertial>
      <origin xyz="0.000179 -0.000121 -0.168936" rpy="0 0 0" />
      <mass value="3.839" />
      <inertia ixx="39002.363e-6" ixy="72.364e-6" ixz="-794.506e-6" iyy="39042.376e-6" iyz="18.663e-6" izz="5029.829e-6" />
    </inertial>
    </link>
  <joint name="right_knee_joint" type="revolute">
    <origin xyz="0 0 -0.4" rpy="0 0 0" />
    <parent link="right_hip_roll_link" />
    <child link="right_knee_link" />
    <axis xyz="0 1 0" />
    <limit lower="-0.26" upper="2.05" effort="300" velocity="14" />
  </joint>
  <link name="right_ankle_pitch_link">
    <inertial>
      <origin xyz="-0.000294 0 -0.010794" rpy="0 0 0" />
      <mass value="0.102" />
      <inertia ixx="0.000023944" ixy="0" ixz="0.000000121" iyy="0.000021837" iyz="0" izz="0.000013414" />
    </inertial>
    </link>
  <joint name="right_ankle_pitch_joint" type="revolute">
    <origin xyz="0 0 -0.4" rpy="0 0 0" />
    <parent link="right_knee_link" />
    <child link="right_ankle_pitch_link" />
    <axis xyz="0 1 0" />
    <limit lower="-0.897334" upper="0.523598" effort="60" velocity="9" />
  </joint>
  <link name="right_ankle_roll_link">
    <inertial>
      <origin xyz="0.029589 0 -0.015973" rpy="0 0 0" />
      <mass value="0.747" />
      <inertia ixx="648.830e-6" ixy="0" ixz="158.380e-6" iyy="3435.339e-6" iyz="0" izz="3583.259e-6" />
    </inertial>
    </link>
  <joint name="right_ankle_roll_joint" type="revolute">
    <origin xyz="0 0 -0.02" rpy="0 0 0" />
    <parent link="right_ankle_pitch_link" />
    <child link="right_ankle_roll_link" />
    <axis xyz="1 0 0" />
    <limit lower="-0.261799" upper="0.261799" effort="40" velocity="9" />
  </joint>

  <!-- Torso -->
  <link name="torso_link">
    <inertial>
      <origin xyz="0.000489 0.002797 0.20484" rpy="0 0 0" />
      <mass value="17.789" />
      <inertia ixx="0.4873" ixy="-0.00053763" ixz="0.0020276" iyy="0.40963" iyz="-0.00074582" izz="0.12785" />
    </inertial>
    </link>
  <joint name="torso_joint" type="revolute">
    <origin xyz="0 0 0" rpy="0 0 0" />
    <parent link="pelvis" />
    <child link="torso_link" />
    <axis xyz="0 0 1" />
    <limit lower="-2.35" upper="2.35" effort="200" velocity="23" />
  </joint>

  <!-- L arm -->
  <link name="left_shoulder_pitch_link">
    <inertial>
      <origin xyz="0.003053 0.06042 -0.0059" rpy="0 0 0" />
      <mass value="1.327" />
      <inertia ixx="0.00058661" ixy="-2.0157E-05" ixz="2.985E-06" iyy="0.0003989" iyz="2.238E-05" izz="0.00052936" />
    </inertial>
    </link>
  <joint name="left_shoulder_pitch_joint" type="revolute">
    <origin xyz="0 0.14806 0.42333" rpy="0.2618 0 0" />
    <parent link="torso_link" />
    <child link="left_shoulder_pitch_link" />
    <axis xyz="0 1 0" />
    <limit lower="-3.14" upper="1.57" effort="40" velocity="9" />
  </joint>
  <link name="left_shoulder_roll_link">
    <inertial>
      <origin xyz="-0.030932 -1E-06 -0.10609" rpy="0 0 0" />
      <mass value="1.393" />
      <inertia ixx="0.0018408" ixy="3.98E-07" ixz="-0.00048324" iyy="0.001934638" iyz="1.61E-07" izz="0.000617733" />
    </inertial>
    </link>
  <joint name="left_shoulder_roll_joint" type="revolute">
    <origin xyz="0.0342 0.061999 -0.0060011" rpy="-0.2618 0 0" />
    <parent link="left_shoulder_pitch_link" />
    <child link="left_shoulder_roll_link" />
    <axis xyz="1 0 0" />
    <limit lower="-0.38" upper="3.4" effort="40" velocity="9" />
  </joint>
  <link name="left_shoulder_yaw_link">
    <inertial>
      <origin xyz="0.004583 0.001128 -0.001128" rpy="0 0 0" />
      <mass value="1.505" />
      <inertia ixx="0.004199" ixy="-1.7786E-05" ixz="0.00018372" iyy="0.0043139" iyz="9.278E-05" izz="0.00065755" />
    </inertial>
    </link>
  <joint name="left_shoulder_yaw_joint" type="revolute">
    <origin xyz="-0.0342 0 -0.1456" rpy="0 0 0" />
    <parent link="left_shoulder_roll_link" />
    <child link="left_shoulder_yaw_link" />
    <axis xyz="0 0 1" />
    <limit lower="-2.66" upper="3.01" effort="18" velocity="20" />
  </joint>
  <link name="left_elbow_pitch_link">
    <inertial>
      <origin xyz="0.077092 -0.028751 -0.009714 " rpy="0 0 0" />
      <mass value="0.691" />
      <inertia ixx="0.000318491" ixy="0.000224554" ixz="6.62076E-05" iyy="0.000861224" iyz="-2.3329E-05" izz="0.000897899" />
    </inertial>
    </link>
  <joint name="left_elbow_pitch_joint" type="revolute">
    <origin xyz="0.006 0.0329 -0.182" rpy="0 0 0" />
    <parent link="left_shoulder_yaw_link" />
    <child link="left_elbow_pitch_link" />
    <axis xyz="0 1 0" />
    <limit lower="-0.95" upper="3.18" effort="18" velocity="20" />
  </joint>

  <link name="left_elbow_roll_link">
    <inertial>
      <origin xyz="0.035281 -0.002320 0.000337" rpy="0 0 0" />
      <mass value="0.683" />
      <inertia ixx="0.000313275" ixy="0.000016521" ixz="-0.000002501" iyy="0.000310412" iyz="0.000005435" izz="0.000345998" />
    </inertial>
    </link>
  <joint name="left_elbow_roll_joint" type="revolute">
    <origin xyz="0.121 -0.0329 -0.011" rpy="0 0 0" />
    <parent link="left_elbow_pitch_link" />
    <child link="left_elbow_roll_link" />
    <axis xyz="1 0 0" />
    <limit lower="-3.01" upper="2.75" effort="19" velocity="31.4" />
  </joint>

  <link name="left_wrist_pitch_link">
    <inertial>
      <origin xyz="0.020395 0.000036 -0.002973" rpy="0 0 0" />
      <mass value="0.484" />
      <inertia ixx="0.000071364" ixy="0.000000308" ixz="0.000001485" iyy="0.000069915" iyz="-0.000000088" izz="0.000070702" />
    </inertial>
    </link>
  <joint name="left_wrist_pitch_joint" type="revolute">
    <origin xyz="0.085 0 0" rpy="0 0 0" />
    <parent link="left_elbow_roll_link" />
    <child link="left_wrist_pitch_link" />
    <axis xyz="0 1 0" />
    <limit lower="-0.47" upper="0.47" effort="19" velocity="31.4" />
  </joint>
  <link name="left_wrist_yaw_link">
    <inertial>
      <origin xyz="0.027967 0.000096 0.000739" rpy="0 0 0" />
      <mass value="0.124" />
      <inertia ixx="137.3e-6" ixy="-0.171e-6" ixz="2.942e-6" iyy="169.998e-6" iyz="-0.025e-6" izz="84.808e-6" />
    </inertial>
    <!-- <collision>
      <origin xyz="0 0 0" rpy="0 0 0"/>
      <geometry>
        <mesh filename="meshes/wrist_yaw_link.STL"/>
      </geometry>
    </collision> -->
  </link>
  <joint name="left_wrist_yaw_joint" type="revolute">
    <origin xyz="0.020 0 0" rpy="0 0 0" />
    <parent link="left_wrist_pitch_link" />
    <child link="left_wrist_yaw_link" />
    <axis xyz="0 0 1" />
    <limit lower="-1.27" upper="1.27" effort="19" velocity="31.4" />
  </joint>

  <!-- R arm -->
  <link name="right_shoulder_pitch_link">
    <inertial>
      <origin xyz="0.003053 -0.06042 -0.0059" rpy="0 0 0" />
      <mass value="1.327" />
      <inertia ixx="0.00058661" ixy="2.0157E-05" ixz="2.985E-06" iyy="0.0003989" iyz="-2.238E-05" izz="0.00052936" />
    </inertial>
    </link>
  <joint name="right_shoulder_pitch_joint" type="revolute">
    <origin xyz="0 -0.14806 0.42333" rpy="-0.2618 0 0" />
    <parent link="torso_link" />
    <child link="right_shoulder_pitch_link" />
    <axis xyz="0 1 0" />
    <limit lower="-3.14" upper="1.57" effort="40" velocity="9" />
  </joint>
  <link name="right_shoulder_roll_link">
    <inertial>
      <origin xyz="-0.030932 1E-06 -0.10609" rpy="0 0 0" />
      <mass value="1.393" />
      <inertia ixx="0.0018408" ixy="-3.98E-07" ixz="-0.00048324" iyy="0.001934638" iyz="-1.61E-07" izz="0.000617733" />
    </inertial>
    </link>
  <joint name="right_shoulder_roll_joint" type="revolute">
    <origin xyz="0.0342 -0.061999 -0.0060011" rpy="0.2618 0 0" />
    <parent link="right_shoulder_pitch_link" />
    <child link="right_shoulder_roll_link" />
    <axis xyz="1 0 0" />
    <limit lower="-3.4" upper="0.38" effort="40" velocity="9" />
  </joint>
  <link name="right_shoulder_yaw_link">
    <inertial>
      <origin xyz="0.004583 -0.001128 -0.001128" rpy="0 0 0" />
      <mass value="1.505" />
      <inertia ixx="0.004199" ixy="1.7786E-05" ixz="0.00018372" iyy="0.0043139" iyz="-9.278E-05" izz="0.00065755" />

    </inertial>
    </link>
  <joint name="right_shoulder_yaw_joint" type="revolute">
    <origin xyz="-0.0342 0 -0.1456" rpy="0 0 0" />
    <parent link="right_shoulder_roll_link" />
    <child link="right_shoulder_yaw_link" />
    <axis xyz="0 0 1" />
    <limit lower="-3.01" upper="2.66" effort="18" velocity="20" />
  </joint>
  <link name="right_elbow_pitch_link">
    <inertial>
      <origin xyz="0.077092 0.028751 -0.009714 " rpy="0 0 0" />
      <mass value="0.691" />
      <inertia ixx="0.000318491" ixy="-0.000224554" ixz="6.62076E-05" iyy="0.000861224" iyz="2.3329E-05" izz="0.000897899" />
    </inertial>
    </link>
  <joint name="right_elbow_pitch_joint" type="revolute">
    <origin xyz="0.006 -0.0329 -0.182" rpy="0 0 0" />
    <parent link="right_shoulder_yaw_link" />
    <child link="right_elbow_pitch_link" />
    <axis xyz="0 1 0" />
    <limit lower="-0.95" upper="3.18" effort="18" velocity="20" />
  </joint>

  <link name="right_elbow_roll_link">
    <inertial>
      <origin xyz="0.035281 -0.002320 0.000337" rpy="0 0 0" />
      <mass value="0.683" />
      <inertia ixx="0.000313275" ixy="0.000016521" ixz="-0.000002501" iyy="0.000310412" iyz="0.000005435" izz="0.000345998" />
    </inertial>
    </link>
  <joint name="right_elbow_roll_joint" type="revolute">
    <origin xyz="0.121 0.0329 -0.011" rpy="0 0 0" />
    <parent link="right_elbow_pitch_link" />
    <child link="right_elbow_roll_link" />
    <axis xyz="1 0 0" />
    <limit lower="-2.75" upper="3.01" effort="19" velocity="31.4" />
  </joint>

  <link name="right_wrist_pitch_link">
    <inertial>
      <origin xyz="0.020395 0.000036 -0.002973" rpy="0 0 0" />
      <mass value="0.484" />
      <inertia ixx="0.000071364" ixy="0.000000308" ixz="0.000001485" iyy="0.000069915" iyz="-0.000000088" izz="0.000070702" />
    </inertial>
    </link>
  <joint name="right_wrist_pitch_joint" type="revolute">
    <origin xyz="0.085 0 0" rpy="0 0 0" />
    <parent link="right_elbow_roll_link" />
    <child link="right_wrist_pitch_link" />
    <axis xyz="0 1 0" />
    <limit lower="-0.47" upper="0.47" effort="19" velocity="31.4" />
  </joint>
  <link name="right_wrist_yaw_link">
    <inertial>
      <origin xyz="0.027967 -0.000096 0.000739" rpy="0 0 0" />
      <mass value="0.124" />
      <inertia ixx="137.3e-6" ixy="0.171e-6" ixz="2.942e-6" iyy="169.998e-6" iyz="0.025e-6" izz="84.808e-6" />
    </inertial>
    <!-- <collision>
      <origin xyz="0 0 0" rpy="0 0 0"/>
      <geometry>
        <mesh filename="meshes/wrist_yaw_link.STL"/>
      </geometry>
    </collision> -->
  </link>
  <joint name="right_wrist_yaw_joint" type="revolute">
    <origin xyz="0.020 0 0" rpy="0 0 0" />
    <parent link="right_wrist_pitch_link" />
    <child link="right_wrist_yaw_link" />
    <axis xyz="0 0 1" />
    <limit lower="-1.27" upper="1.27" effort="19" velocity="31.4" />
  </joint>

  <!-- LOGO -->
  <link name="logo_link">
    <visual>
      <origin xyz="0 0 0" rpy="0 0 0" />
      <geometry>
        <mesh filename="meshes/logo_link.STL" />
      </geometry>
      <material name="white">
        <color rgba="1 1 1 1" />
      </material>
    </visual>
  </link>
  <joint name="logo_joint" type="fixed">
    <origin xyz="0 0 0" rpy="0 0 0" />
    <parent link="torso_link" />
    <child link="logo_link" />
    <axis xyz="0 0 0" />
  </joint>

  <!-- IMU -->
  <link name="imu_link" />
  <joint name="imu_joint" type="fixed">
    <origin xyz="-0.04233868314 0.00166 0.152067" rpy="0 0 0" />
    <parent link="torso_link" />
    <child link="imu_link" />
  </joint>

  <!-- L Gripper -->
  <joint name="L_base_link_joint" type="fixed">
    <origin xyz="0.054 0 0" rpy="0 0 1.5707963267948966192313216916398" />
    <parent link="left_wrist_yaw_link" />
    <child link="L_hand_base_link" />
  </joint>
  <link name="L_hand_base_link">
    <inertial>
      <origin xyz="-0.002551 -0.066047 -0.0019357" rpy="0 0 0" />
      <mass value="0.14143" />
      <inertia ixx="0.0001234" ixy="2.1995E-06" ixz="-1.7694E-06" iyy="8.3835E-05" iyz="1.5968E-06" izz="7.7231E-05" />
    </inertial>
    </link>
  <link name="L_thumb_proximal_base">
    <inertial>
      <origin xyz="0.0048817 0.00038782 -0.00722" rpy="0 0 0" />
      <mass value="0.0018869" />
      <inertia ixx="5.5158E-08" ixy="-1.1803E-08" ixz="-4.6743E-09" iyy="8.2164E-08" iyz="-1.3521E-09" izz="6.7434E-08" />
    </inertial>
    </link>
  <joint name="L_thumb_proximal_yaw_joint" type="revolute">
    <origin xyz="-0.01696 -0.0691 0.02045" rpy="1.5708 -1.5708 0" />
    <parent link="L_hand_base_link" />
    <child link="L_thumb_proximal_base" />
    <axis xyz="0 0 1" />
    <limit lower="-0.1" upper="1.3" effort="1" velocity="0.5" />
  </joint>
  <link name="L_thumb_proximal">
    <inertial>
      <origin xyz="0.021936 -0.01279 -0.0080386" rpy="0 0 0" />
      <mass value="0.0066101" />
      <inertia ixx="1.5693E-06" ixy="7.8339E-07" ixz="8.5959E-10" iyy="1.7356E-06" iyz="1.0378E-09" izz="2.787E-06" />
    </inertial>
    </link>
  <joint name="L_thumb_proximal_pitch_joint" type="revolute">
    <origin xyz="0.0099867 0.0098242 -0.0089" rpy="-1.5708 0 0.16939" />
    <parent link="L_thumb_proximal_base" />
    <child link="L_thumb_proximal" />
    <axis xyz="0 0 -1" />
    <limit lower="-0.1" upper="0.6" effort="1" velocity="0.5" />
  </joint>
  <link name="L_thumb_intermediate">
    <inertial>
      <origin xyz="0.0095531 0.0016282 -0.0072002" rpy="0 0 0" />
      <mass value="0.0037844" />
      <inertia ixx="3.6981E-07" ixy="9.8603E-08" ixz="-2.8173E-12" iyy="3.2395E-07" iyz="-2.8028E-12" izz="4.6532E-07" />
    </inertial>
    </link>
  <joint name="L_thumb_intermediate_joint" type="revolute">
    <origin xyz="0.04407 -0.034553 -0.0008" rpy="0 0 0" />
    <parent link="L_thumb_proximal" />
    <child link="L_thumb_intermediate" />
    <axis xyz="0 0 -1" />
    <limit lower="0" upper="0.8" effort="1" velocity="0.5" />
    <mimic joint="L_thumb_proximal_pitch_joint" multiplier="1.6" offset="0" />
  </joint>
  <link name="L_thumb_distal">
    <inertial>
      <origin xyz="0.0092888 -0.004953 -0.0060033" rpy="0 0 0" />
      <mass value="0.003344" />
      <inertia ixx="1.3632E-07" ixy="5.6787E-08" ixz="-9.1939E-11" iyy="1.4052E-07" iyz="1.2145E-10" izz="2.0026E-07" />
    </inertial>
    </link>
  <joint name="L_thumb_distal_joint" type="revolute">
    <origin xyz="0.020248 -0.010156 -0.0012" rpy="0 0 0" />
    <parent link="L_thumb_intermediate" />
    <child link="L_thumb_distal" />
    <axis xyz="0 0 -1" />
    <limit lower="0" upper="1.2" effort="1" velocity="0.5" />
    <mimic joint="L_thumb_proximal_pitch_joint" multiplier="2.4" offset="0" />
  </joint>
  <link name="L_index_proximal">
    <inertial>
      <origin xyz="0.0012971 -0.011934 -0.0059998" rpy="0 0 0" />
      <mass value="0.0042405" />
      <inertia ixx="6.6215E-07" ixy="1.8442E-08" ixz="1.3746E-12" iyy="2.1167E-07" iyz="-1.4773E-11" izz="6.9402E-07" />
    </inertial>
    </link>
  <joint name="L_index_proximal_joint" type="revolute">
    <origin xyz="0.00028533 -0.13653 0.032268" rpy="-0.034907 0 0" />
    <parent link="L_hand_base_link" />
    <child link="L_index_proximal" />
    <axis xyz="0 0 -1" />
    <limit lower="0" upper="1.7" effort="1" velocity="0.5" />
  </joint>
  <link name="L_index_intermediate">
    <inertial>
      <origin xyz="0.0021753 -0.019567 -0.005" rpy="0 0 0" />
      <mass value="0.0045682" />
      <inertia ixx="7.6284E-07" ixy="-8.063E-08" ixz="3.6797E-13" iyy="9.4308E-08" iyz="1.5743E-13" izz="7.8176E-07" />
    </inertial>
    </link>
  <joint name="L_index_intermediate_joint" type="revolute">
    <origin xyz="-0.0024229 -0.032041 -0.001" rpy="0 0 0" />
    <parent link="L_index_proximal" />
    <child link="L_index_intermediate" />
    <axis xyz="0 0 -1" />
    <limit lower="0" upper="1.7" effort="1" velocity="0.5" />
    <mimic joint="L_index_proximal_joint" multiplier="1" offset="0" />
  </joint>
  <link name="L_middle_proximal">
    <inertial>
      <origin xyz="0.0012971 -0.011934 -0.0059999" rpy="0 0 0" />
      <mass value="0.0042405" />
      <inertia ixx="6.6215E-07" ixy="1.8442E-08" ixz="1.2299E-12" iyy="2.1167E-07" iyz="-1.4484E-11" izz="6.9402E-07" />
    </inertial>
    </link>
  <joint name="L_middle_proximal_joint" type="revolute">
    <origin xyz="0.00028533 -0.1371 0.01295" rpy="0 0 0" />
    <parent link="L_hand_base_link" />
    <child link="L_middle_proximal" />
    <axis xyz="0 0 -1" />
    <limit lower="0" upper="1.7" effort="1" velocity="0.5" />
  </joint>
  <link name="L_middle_intermediate">
    <inertial>
      <origin xyz="0.001921 -0.020796 -0.0049999" rpy="0 0 0" />
      <mass value="0.0050397" />
      <inertia ixx="9.5823E-07" ixy="-1.1425E-07" ixz="-2.4186E-12" iyy="1.0646E-07" iyz="3.6974E-12" izz="9.8385E-07" />
    </inertial>
    </link>
  <joint name="L_middle_intermediate_joint" type="revolute">
    <origin xyz="-0.0024229 -0.032041 -0.001" rpy="0 0 0" />
    <parent link="L_middle_proximal" />
    <child link="L_middle_intermediate" />
    <axis xyz="0 0 -1" />
    <limit lower="0" upper="1.7" effort="1" velocity="0.5" />
    <mimic joint="L_middle_proximal_joint" multiplier="1" offset="0" />
  </joint>
  <link name="L_ring_proximal">
    <inertial>
      <origin xyz="0.0012971 -0.011934 -0.0059999" rpy="0 0 0" />
      <mass value="0.0042405" />
      <inertia ixx="6.6215E-07" ixy="1.8442E-08" ixz="9.6052E-13" iyy="2.1167E-07" iyz="-1.4124E-11" izz="6.9402E-07" />
    </inertial>
    </link>
  <joint name="L_ring_proximal_joint" type="revolute">
    <origin xyz="0.00028533 -0.13691 -0.0062872" rpy="0.05236 0 0" />
    <parent link="L_hand_base_link" />
    <child link="L_ring_proximal" />
    <axis xyz="0 0 -1" />
    <limit lower="0" upper="1.7" effort="1" velocity="0.5" />
  </joint>
  <link name="L_ring_intermediate">
    <inertial>
      <origin xyz="0.0021753 -0.019567 -0.005" rpy="0 0 0" />
      <mass value="0.0045682" />
      <inertia ixx="7.6285E-07" ixy="-8.0631E-08" ixz="3.3472E-14" iyy="9.4308E-08" iyz="-4.4773E-13" izz="7.8176E-07" />
    </inertial>
    </link>
  <joint name="L_ring_intermediate_joint" type="revolute">
    <origin xyz="-0.0024229 -0.032041 -0.001" rpy="0 0 0" />
    <parent link="L_ring_proximal" />
    <child link="L_ring_intermediate" />
    <axis xyz="0 0 -1" />
    <limit lower="0" upper="1.7" effort="1" velocity="0.5" />
    <mimic joint="L_ring_proximal_joint" multiplier="1" offset="0" />
  </joint>
  <link name="L_pinky_proximal">
    <inertial>
      <origin xyz="0.0012971 -0.011934 -0.0059999" rpy="0 0 0" />
      <mass value="0.0042405" />
      <inertia ixx="6.6215E-07" ixy="1.8442E-08" ixz="1.0279E-12" iyy="2.1167E-07" iyz="-1.4277E-11" izz="6.9402E-07" />
    </inertial>
    </link>
  <joint name="L_pinky_proximal_joint" type="revolute">
    <origin xyz="0.00028533 -0.13571 -0.025488" rpy="0.10472 0 0" />
    <parent link="L_hand_base_link" />
    <child link="L_pinky_proximal" />
    <axis xyz="0 0 -1" />
    <limit lower="0" upper="1.7" effort="1" velocity="0.5" />
  </joint>
  <link name="L_pinky_intermediate">
    <inertial>
      <origin xyz="0.0024788 -0.016208 -0.0050001" rpy="0 0 0" />
      <mass value="0.0036036" />
      <inertia ixx="4.3923E-07" ixy="-4.1355E-08" ixz="1.2263E-12" iyy="7.0315E-08" iyz="3.1311E-12" izz="4.4881E-07" />
    </inertial>
    </link>
  <joint name="L_pinky_intermediate_joint" type="revolute">
    <origin xyz="-0.0024229 -0.032041 -0.001" rpy="0 0 0" />
    <parent link="L_pinky_proximal" />
    <child link="L_pinky_intermediate" />
    <axis xyz="0 0 -1" />
    <limit lower="0" upper="1.7" effort="1" velocity="0.5" />
    <mimic joint="L_pinky_proximal_joint" multiplier="1" offset="0" />
  </joint>

  <!-- R Gripper -->
  <joint name="R_base_link_joint" type="fixed">
    <origin xyz="0.054 0 0" rpy="3.1415926535897932384626433832795 0 -1.5707963267948966192313216916398" />
    <parent link="right_wrist_yaw_link" />
    <child link="R_hand_base_link" />
  </joint>
  <link name="R_hand_base_link">
    <inertial>
      <origin xyz="-0.0025264 -0.066047 0.0019598" rpy="0 0 0" />
      <mass value="0.14143" />
      <inertia ixx="0.00012281" ixy="2.1711E-06" ixz="1.7709E-06" iyy="8.3832E-05" iyz="-1.6551E-06" izz="7.6663E-05" />
    </inertial>
    </link>
  <link name="R_thumb_proximal_base">
    <inertial>
      <origin xyz="-0.0048064 0.0009382 -0.00757" rpy="0 0 0" />
      <mass value="0.0018869" />
      <inertia ixx="5.816E-08" ixy="1.4539E-08" ixz="4.491E-09" iyy="7.9161E-08" iyz="-1.8727E-09" izz="6.7433E-08" />
    </inertial>
    </link>
  <joint name="R_thumb_proximal_yaw_joint" type="revolute">
    <origin xyz="-0.01696 -0.0691 -0.02045" rpy="1.5708 -1.5708 0" />
    <parent link="R_hand_base_link" />
    <child link="R_thumb_proximal_base" />
    <axis xyz="0 0 -1" />
    <limit lower="-0.1" upper="1.3" effort="1" velocity="0.5" />
  </joint>
  <link name="R_thumb_proximal">
    <inertial>
      <origin xyz="0.021932 0.012785 -0.0080386" rpy="0 0 0" />
      <mass value="0.0066075" />
      <inertia ixx="1.5686E-06" ixy="-7.8296E-07" ixz="8.9143E-10" iyy="1.7353E-06" iyz="-1.0191E-09" izz="2.786E-06" />
    </inertial>
    </link>
  <joint name="R_thumb_proximal_pitch_joint" type="revolute">
    <origin xyz="-0.0088099 0.010892 -0.00925" rpy="1.5708 0 2.8587" />
    <parent link="R_thumb_proximal_base" />
    <child link="R_thumb_proximal" />
    <axis xyz="0 0 1" />
    <limit lower="-0.1" upper="0.6" effort="1" velocity="0.5" />
  </joint>
  <link name="R_thumb_intermediate">
    <inertial>
      <origin xyz="0.0095544 -0.0016282 -0.0071997" rpy="0 0 0" />
      <mass value="0.0037847" />
      <inertia ixx="3.6981E-07" ixy="-9.8581E-08" ixz="-4.7469E-12" iyy="3.2394E-07" iyz="1.0939E-12" izz="4.6531E-07" />
    </inertial>
    </link>
  <joint name="R_thumb_intermediate_joint" type="revolute">
    <origin xyz="0.04407 0.034553 -0.0008" rpy="0 0 0" />
    <parent link="R_thumb_proximal" />
    <child link="R_thumb_intermediate" />
    <axis xyz="0 0 1" />
    <limit lower="0" upper="0.8" effort="1" velocity="0.5" />
    <mimic joint="R_thumb_proximal_pitch_joint" multiplier="1.6" offset="0" />
  </joint>
  <link name="R_thumb_distal">
    <inertial>
      <origin xyz="0.0092888 0.0049529 -0.0060033" rpy="0 0 0" />
      <mass value="0.0033441" />
      <inertia ixx="1.3632E-07" ixy="-5.6788E-08" ixz="-9.2764E-11" iyy="1.4052E-07" iyz="-1.2283E-10" izz="2.0026E-07" />
    </inertial>
    </link>
  <joint name="R_thumb_distal_joint" type="revolute">
    <origin xyz="0.020248 0.010156 -0.0012" rpy="0 0 0" />
    <parent link="R_thumb_intermediate" />
    <child link="R_thumb_distal" />
    <axis xyz="0 0 1" />
    <limit lower="0" upper="1.2" effort="1" velocity="0.5" />
    <mimic joint="R_thumb_proximal_pitch_joint" multiplier="2.4" offset="0" />
  </joint>
  <link name="R_index_proximal">
    <inertial>
      <origin xyz="0.0012259 0.011942 -0.0060001" rpy="0 0 0" />
      <mass value="0.0042403" />
      <inertia ixx="6.6232E-07" ixy="-1.5775E-08" ixz="1.8515E-12" iyy="2.1146E-07" iyz="-5.0828E-12" izz="6.9398E-07" />
    </inertial>
    </link>
  <joint name="R_index_proximal_joint" type="revolute">
    <origin xyz="0.00028533 -0.13653 -0.032268" rpy="-3.1067 0 0" />
    <parent link="R_hand_base_link" />
    <child link="R_index_proximal" />
    <axis xyz="0 0 1" />
    <limit lower="0" upper="1.7" effort="1" velocity="0.5" />
  </joint>
  <link name="R_index_intermediate">
    <inertial>
      <origin xyz="0.0019697 0.019589 -0.005" rpy="0 0 0" />
      <mass value="0.0045683" />
      <inertia ixx="7.6111E-07" ixy="8.7637E-08" ixz="-3.7751E-13" iyy="9.6076E-08" iyz="9.9444E-13" izz="7.8179E-07" />
    </inertial>
    </link>
  <joint name="R_index_intermediate_joint" type="revolute">
    <origin xyz="-0.0026138 0.032026 -0.001" rpy="0 0 0" />
    <parent link="R_index_proximal" />
    <child link="R_index_intermediate" />
    <axis xyz="0 0 1" />
    <limit lower="0" upper="1.7" effort="1" velocity="0.5" />
    <mimic joint="R_index_proximal_joint" multiplier="1" offset="0" />
  </joint>
  <link name="R_middle_proximal">
    <inertial>
      <origin xyz="0.001297 0.011934 -0.0060001" rpy="0 0 0" />
      <mass value="0.0042403" />
      <inertia ixx="6.6211E-07" ixy="-1.8461E-08" ixz="1.8002E-12" iyy="2.1167E-07" iyz="-6.6808E-12" izz="6.9397E-07" />
    </inertial>
    </link>
  <joint name="R_middle_proximal_joint" type="revolute">
    <origin xyz="0.00028533 -0.1371 -0.01295" rpy="-3.1416 0 0" />
    <parent link="R_hand_base_link" />
    <child link="R_middle_proximal" />
    <axis xyz="0 0 1" />
    <limit lower="0" upper="1.7" effort="1" velocity="0.5" />
  </joint>
  <link name="R_middle_intermediate">
    <inertial>
      <origin xyz="0.001921 0.020796 -0.005" rpy="0 0 0" />
      <mass value="0.0050396" />
      <inertia ixx="9.5822E-07" ixy="1.1425E-07" ixz="-2.4791E-12" iyy="1.0646E-07" iyz="5.9173E-12" izz="9.8384E-07" />
    </inertial>
    </link>
  <joint name="R_middle_intermediate_joint" type="revolute">
    <origin xyz="-0.0024229 0.032041 -0.001" rpy="0 0 0" />
    <parent link="R_middle_proximal" />
    <child link="R_middle_intermediate" />
    <axis xyz="0 0 1" />
    <limit lower="0" upper="1.7" effort="1" velocity="0.5" />
    <mimic joint="R_middle_proximal_joint" multiplier="1" offset="0" />
  </joint>
  <link name="R_ring_proximal">
    <inertial>
      <origin xyz="0.001297 0.011934 -0.0060002" rpy="0 0 0" />
      <mass value="0.0042403" />
      <inertia ixx="6.6211E-07" ixy="-1.8461E-08" ixz="1.5793E-12" iyy="2.1167E-07" iyz="-6.6868E-12" izz="6.9397E-07" />
    </inertial>
    </link>
  <joint name="R_ring_proximal_joint" type="revolute">
    <origin xyz="0.00028533 -0.13691 0.0062872" rpy="3.0892 0 0" />
    <parent link="R_hand_base_link" />
    <child link="R_ring_proximal" />
    <axis xyz="0 0 1" />
    <limit lower="0" upper="1.7" effort="1" velocity="0.5" />
  </joint>
  <link name="R_ring_intermediate">
    <inertial>
      <origin xyz="0.0021753 0.019567 -0.005" rpy="0 0 0" />
      <mass value="0.0045683" />
      <inertia ixx="7.6286E-07" ixy="8.0635E-08" ixz="-6.1562E-13" iyy="9.431E-08" iyz="5.8619E-13" izz="7.8177E-07" />
    </inertial>
    </link>
  <joint name="R_ring_intermediate_joint" type="revolute">
    <origin xyz="-0.0024229 0.032041 -0.001" rpy="0 0 0" />
    <parent link="R_ring_proximal" />
    <child link="R_ring_intermediate" />
    <axis xyz="0 0 1" />
    <limit lower="0" upper="1.7" effort="1" velocity="0.5" />
    <mimic joint="R_ring_proximal_joint" multiplier="1" offset="0" />
  </joint>
  <link name="R_pinky_proximal">
    <inertial>
      <origin xyz="0.001297 0.011934 -0.0060001" rpy="0 0 0" />
      <mass value="0.0042403" />
      <inertia ixx="6.6211E-07" ixy="-1.8461E-08" ixz="1.6907E-12" iyy="2.1167E-07" iyz="-6.9334E-12" izz="6.9397E-07" />
    </inertial>
    </link>
  <joint name="R_pinky_proximal_joint" type="revolute">
    <origin xyz="0.00028533 -0.13571 0.025488" rpy="3.0369 0 0" />
    <parent link="R_hand_base_link" />
    <child link="R_pinky_proximal" />
    <axis xyz="0 0 1" />
    <limit lower="0" upper="1.7" effort="1" velocity="0.5" />
  </joint>
  <link name="R_pinky_intermediate">
    <inertial>
      <origin xyz="0.0024748 0.016203 -0.0050031" rpy="0 0 0" />
      <mass value="0.0035996" />
      <inertia ixx="4.3913E-07" ixy="4.1418E-08" ixz="3.7168E-11" iyy="7.0247E-08" iyz="5.8613E-11" izz="4.4867E-07" />
    </inertial>
    </link>
  <joint name="R_pinky_intermediate_joint" type="revolute">
    <origin xyz="-0.0024229 0.032041 -0.001" rpy="0 0 0" />
    <parent link="R_pinky_proximal" />
    <child link="R_pinky_intermediate" />
    <axis xyz="0 0 1" />
    <limit lower="0" upper="1.7" effort="1" velocity="0.5" />
    <mimic joint="R_pinky_proximal_joint" multiplier="1" offset="0" />
  </joint>
<link name="pelvis_sphere1"><inertial><origin xyz="0 0 0" rpy="0 0 0" /><mass value="0.01" /><inertia ixx="0.001" ixy="0" ixz="0" iyy="0.001" iyz="0" izz="0.001" /></inertial><visual><origin rpy="0 0 0" xyz="0 0 0" /><geometry><sphere radius="0.03535475581884384" /></geometry><material name="color_pelvis_sphere1_0"><color rgba="0.9 0.2 0.2 1.0" /></material></visual><collision><origin rpy="0 0 0" xyz="0 0 0" /><geometry><sphere radius="0.03535475581884384" /></geometry><drake:proximity_properties><drake:rigid_hydroelastic /><drake:mesh_resolution_hint value="1.5" /><drake:hunt_crossley_dissipation value="1.25" /></drake:proximity_properties></collision></link><joint name="pelvis_to_pelvis_sphere1" type="fixed"><parent link="pelvis" /><child link="pelvis_sphere1" /><origin xyz="0.03285375237464905 -0.020608358085155487 -0.03105171211063862" rpy="0 0 0" /></joint><link name="pelvis_sphere2"><inertial><origin xyz="0 0 0" rpy="0 0 0" /><mass value="0.01" /><inertia ixx="0.001" ixy="0" ixz="0" iyy="0.001" iyz="0" izz="0.001" /></inertial><visual><origin rpy="0 0 0" xyz="0 0 0" /><geometry><sphere radius="0.042126938700675964" /></geometry><material name="color_pelvis_sphere2_0"><color rgba="0.9 0.2 0.2 1.0" /></material></visual><collision><origin rpy="0 0 0" xyz="0 0 0" /><geometry><sphere radius="0.042126938700675964" /></geometry><drake:proximity_properties><drake:rigid_hydroelastic /><drake:mesh_resolution_hint value="1.5" /><drake:hunt_crossley_dissipation value="1.25" /></drake:proximity_properties></collision></link><joint name="pelvis_to_pelvis_sphere2" type="fixed"><parent link="pelvis" /><child link="pelvis_sphere2" /><origin xyz="0.001858933363109827 -0.1067747101187706 -0.045513685792684555" rpy="0 0 0" /></joint><link name="pelvis_sphere3"><inertial><origin xyz="0 0 0" rpy="0 0 0" /><mass value="0.01" /><inertia ixx="0.001" ixy="0" ixz="0" iyy="0.001" iyz="0" izz="0.001" /></inertial><visual><origin rpy="0 0 0" xyz="0 0 0" /><geometry><sphere radius="0.046216439455747604" /></geometry><material name="color_pelvis_sphere3_0"><color rgba="0.9 0.2 0.2 1.0" /></material></visual><collision><origin rpy="0 0 0" xyz="0 0 0" /><geometry><sphere radius="0.046216439455747604" /></geometry><drake:proximity_properties><drake:rigid_hydroelastic /><drake:mesh_resolution_hint value="1.5" /><drake:hunt_crossley_dissipation value="1.25" /></drake:proximity_properties></collision></link><joint name="pelvis_to_pelvis_sphere3" type="fixed"><parent link="pelvis" /><child link="pelvis_sphere3" /><origin xyz="-0.00013040834164712578 0.08626830577850342 -0.039163608103990555" rpy="0 0 0" /></joint><link name="pelvis_sphere4"><inertial><origin xyz="0 0 0" rpy="0 0 0" /><mass value="0.01" /><inertia ixx="0.001" ixy="0" ixz="0" iyy="0.001" iyz="0" izz="0.001" /></inertial><visual><origin rpy="0 0 0" xyz="0 0 0" /><geometry><sphere radius="0.03358186036348343" /></geometry><material name="color_pelvis_sphere4_0"><color rgba="0.9 0.2 0.2 1.0" /></material></visual><collision><origin rpy="0 0 0" xyz="0 0 0" /><geometry><sphere radius="0.03358186036348343" /></geometry><drake:proximity_properties><drake:rigid_hydroelastic /><drake:mesh_resolution_hint value="1.5" /><drake:hunt_crossley_dissipation value="1.25" /></drake:proximity_properties></collision></link><joint name="pelvis_to_pelvis_sphere4" type="fixed"><parent link="pelvis" /><child link="pelvis_sphere4" /><origin xyz="-0.03459916636347771 -0.019494902342557907 -0.029198065400123596" rpy="0 0 0" /></joint><link name="left_hip_yaw_link_sphere1"><inertial><origin xyz="0 0 0" rpy="0 0 0" /><mass value="0.01" /><inertia ixx="0.001" ixy="0" ixz="0" iyy="0.001" iyz="0" izz="0.001" /></inertial><visual><origin rpy="0 0 0" xyz="0 0 0" /><geometry><sphere radius="0.02964329905807972" /></geometry><material name="color_left_hip_yaw_link_sphere1_0"><color rgba="0.2 0.9 0.2 1.0" /></material></visual><collision><origin rpy="0 0 0" xyz="0 0 0" /><geometry><sphere radius="0.02964329905807972" /></geometry><drake:proximity_properties><drake:rigid_hydroelastic /><drake:mesh_resolution_hint value="1.5" /><drake:hunt_crossley_dissipation value="1.25" /></drake:proximity_properties></collision></link><joint name="left_hip_yaw_link_to_left_hip_yaw_link_sphere1" type="fixed"><parent link="left_hip_yaw_link" /><child link="left_hip_yaw_link_sphere1" /><origin xyz="0.0311901718378067 -0.026605376973748207 -0.022482462227344513" rpy="0 0 0" /></joint><link name="left_hip_yaw_link_sphere2"><inertial><origin xyz="0 0 0" rpy="0 0 0" /><mass value="0.01" /><inertia ixx="0.001" ixy="0" ixz="0" iyy="0.001" iyz="0" izz="0.001" /></inertial><visual><origin rpy="0 0 0" xyz="0 0 0" /><geometry><sphere radius="0.027777789160609245" /></geometry><material name="color_left_hip_yaw_link_sphere2_0"><color rgba="0.2 0.9 0.2 1.0" /></material></visual><collision><origin rpy="0 0 0" xyz="0 0 0" /><geometry><sphere radius="0.027777789160609245" /></geometry><drake:proximity_properties><drake:rigid_hydroelastic /><drake:mesh_resolution_hint value="1.5" /><drake:hunt_crossley_dissipation value="1.25" /></drake:proximity_properties></collision></link><joint name="left_hip_yaw_link_to_left_hip_yaw_link_sphere2" type="fixed"><parent link="left_hip_yaw_link" /><child link="left_hip_yaw_link_sphere2" /><origin xyz="-0.040840912610292435 -0.027678918093442917 -0.004012137185782194" rpy="0 0 0" /></joint><link name="left_hip_yaw_link_sphere3"><inertial><origin xyz="0 0 0" rpy="0 0 0" /><mass value="0.01" /><inertia ixx="0.001" ixy="0" ixz="0" iyy="0.001" iyz="0" izz="0.001" /></inertial><visual><origin rpy="0 0 0" xyz="0 0 0" /><geometry><sphere radius="0.016798751428723335" /></geometry><material name="color_left_hip_yaw_link_sphere3_0"><color rgba="0.2 0.9 0.2 1.0" /></material></visual><collision><origin rpy="0 0 0" xyz="0 0 0" /><geometry><sphere radius="0.016798751428723335" /></geometry><drake:proximity_properties><drake:rigid_hydroelastic /><drake:mesh_resolution_hint value="1.5" /><drake:hunt_crossley_dissipation value="1.25" /></drake:proximity_properties></collision></link><joint name="left_hip_yaw_link_to_left_hip_yaw_link_sphere3" type="fixed"><parent link="left_hip_yaw_link" /><child link="left_hip_yaw_link_sphere3" /><origin xyz="0.022366290912032127 -0.01893879659473896 0.06074201315641403" rpy="0 0 0" /></joint><link name="left_hip_pitch_link_sphere1"><inertial><origin xyz="0 0 0" rpy="0 0 0" /><mass value="0.01" /><inertia ixx="0.001" ixy="0" ixz="0" iyy="0.001" iyz="0" izz="0.001" /></inertial><visual><origin rpy="0 0 0" xyz="0 0 0" /><geometry><sphere radius="0.01520676538348198" /></geometry><material name="color_left_hip_pitch_link_sphere1_0"><color rgba="0.2 0.9 0.2 1.0" /></material></visual><collision><origin rpy="0 0 0" xyz="0 0 0" /><geometry><sphere radius="0.01520676538348198" /></geometry><drake:proximity_properties><drake:rigid_hydroelastic /><drake:mesh_resolution_hint value="1.5" /><drake:hunt_crossley_dissipation value="1.25" /></drake:proximity_properties></collision></link><joint name="left_hip_pitch_link_to_left_hip_pitch_link_sphere1" type="fixed"><parent link="left_hip_pitch_link" /><child link="left_hip_pitch_link_sphere1" /><origin xyz="0.00812328327447176 -0.054878413677215576 0.026931388303637505" rpy="0 0 0" /></joint><link name="left_hip_pitch_link_sphere2"><inertial><origin xyz="0 0 0" rpy="0 0 0" /><mass value="0.01" /><inertia ixx="0.001" ixy="0" ixz="0" iyy="0.001" iyz="0" izz="0.001" /></inertial><visual><origin rpy="0 0 0" xyz="0 0 0" /><geometry><sphere radius="0.021975712850689888" /></geometry><material name="color_left_hip_pitch_link_sphere2_0"><color rgba="0.2 0.9 0.2 1.0" /></material></visual><collision><origin rpy="0 0 0" xyz="0 0 0" /><geometry><sphere radius="0.021975712850689888" /></geometry><drake:proximity_properties><drake:rigid_hydroelastic /><drake:mesh_resolution_hint value="1.5" /><drake:hunt_crossley_dissipation value="1.25" /></drake:proximity_properties></collision></link><joint name="left_hip_pitch_link_to_left_hip_pitch_link_sphere2" type="fixed"><parent link="left_hip_pitch_link" /><child link="left_hip_pitch_link_sphere2" /><origin xyz="-0.019554460421204567 0.0298446174710989 -0.034127820283174515" rpy="0 0 0" /></joint><link name="left_hip_pitch_link_sphere3"><inertial><origin xyz="0 0 0" rpy="0 0 0" /><mass value="0.01" /><inertia ixx="0.001" ixy="0" ixz="0" iyy="0.001" iyz="0" izz="0.001" /></inertial><visual><origin rpy="0 0 0" xyz="0 0 0" /><geometry><sphere radius="0.019210588186979294" /></geometry><material name="color_left_hip_pitch_link_sphere3_0"><color rgba="0.2 0.9 0.2 1.0" /></material></visual><collision><origin rpy="0 0 0" xyz="0 0 0" /><geometry><sphere radius="0.019210588186979294" /></geometry><drake:proximity_properties><drake:rigid_hydroelastic /><drake:mesh_resolution_hint value="1.5" /><drake:hunt_crossley_dissipation value="1.25" /></drake:proximity_properties></collision></link><joint name="left_hip_pitch_link_to_left_hip_pitch_link_sphere3" type="fixed"><parent link="left_hip_pitch_link" /><child link="left_hip_pitch_link_sphere3" /><origin xyz="-0.025245195254683495 0.015884920954704285 0.041687123477458954" rpy="0 0 0" /></joint><link name="left_hip_roll_link_sphere1"><inertial><origin xyz="0 0 0" rpy="0 0 0" /><mass value="0.01" /><inertia ixx="0.001" ixy="0" ixz="0" iyy="0.001" iyz="0" izz="0.001" /></inertial><visual><origin rpy="0 0 0" xyz="0 0 0" /><geometry><sphere radius="0.04659309983253479" /></geometry><material name="color_left_hip_roll_link_sphere1_0"><color rgba="0.2 0.9 0.2 1.0" /></material></visual><collision><origin rpy="0 0 0" xyz="0 0 0" /><geometry><sphere radius="0.04659309983253479" /></geometry><drake:proximity_properties><drake:rigid_hydroelastic /><drake:mesh_resolution_hint value="1.5" /><drake:hunt_crossley_dissipation value="1.25" /></drake:proximity_properties></collision></link><joint name="left_hip_roll_link_to_left_hip_roll_link_sphere1" type="fixed"><parent link="left_hip_roll_link" /><child link="left_hip_roll_link_sphere1" /><origin xyz="0.010468613356351852 0.0006188496481627226 -0.32738733291625977" rpy="0 0 0" /></joint><link name="left_hip_roll_link_sphere2"><inertial><origin xyz="0 0 0" rpy="0 0 0" /><mass value="0.01" /><inertia ixx="0.001" ixy="0" ixz="0" iyy="0.001" iyz="0" izz="0.001" /></inertial><visual><origin rpy="0 0 0" xyz="0 0 0" /><geometry><sphere radius="0.06723503023386002" /></geometry><material name="color_left_hip_roll_link_sphere2_0"><color rgba="0.2 0.9 0.2 1.0" /></material></visual><collision><origin rpy="0 0 0" xyz="0 0 0" /><geometry><sphere radius="0.06723503023386002" /></geometry><drake:proximity_properties><drake:rigid_hydroelastic /><drake:mesh_resolution_hint value="1.5" /><drake:hunt_crossley_dissipation value="1.25" /></drake:proximity_properties></collision></link><joint name="left_hip_roll_link_to_left_hip_roll_link_sphere2" type="fixed"><parent link="left_hip_roll_link" /><child link="left_hip_roll_link_sphere2" /><origin xyz="-5.3515497711487114e-05 -0.0006074253469705582 -0.15800096094608307" rpy="0 0 0" /></joint><link name="left_hip_roll_link_sphere3"><inertial><origin xyz="0 0 0" rpy="0 0 0" /><mass value="0.01" /><inertia ixx="0.001" ixy="0" ixz="0" iyy="0.001" iyz="0" izz="0.001" /></inertial><visual><origin rpy="0 0 0" xyz="0 0 0" /><geometry><sphere radius="0.03023781068623066" /></geometry><material name="color_left_hip_roll_link_sphere3_0"><color rgba="0.2 0.9 0.2 1.0" /></material></visual><collision><origin rpy="0 0 0" xyz="0 0 0" /><geometry><sphere radius="0.03023781068623066" /></geometry><drake:proximity_properties><drake:rigid_hydroelastic /><drake:mesh_resolution_hint value="1.5" /><drake:hunt_crossley_dissipation value="1.25" /></drake:proximity_properties></collision></link><joint name="left_hip_roll_link_to_left_hip_roll_link_sphere3" type="fixed"><parent link="left_hip_roll_link" /><child link="left_hip_roll_link_sphere3" /><origin xyz="0.042250022292137146 0.0008663294720463455 -0.014343533664941788" rpy="0 0 0" /></joint><link name="left_ankle_pitch_link_sphere1"><inertial><origin xyz="0 0 0" rpy="0 0 0" /><mass value="0.01" /><inertia ixx="0.001" ixy="0" ixz="0" iyy="0.001" iyz="0" izz="0.001" /></inertial><visual><origin rpy="0 0 0" xyz="0 0 0" /><geometry><sphere radius="0.010070424526929855" /></geometry><material name="color_left_ankle_pitch_link_sphere1_0"><color rgba="0.2 0.9 0.2 1.0" /></material></visual><collision><origin rpy="0 0 0" xyz="0 0 0" /><geometry><sphere radius="0.010070424526929855" /></geometry><drake:proximity_properties><drake:rigid_hydroelastic /><drake:mesh_resolution_hint value="1.5" /><drake:hunt_crossley_dissipation value="1.25" /></drake:proximity_properties></collision></link><joint name="left_ankle_pitch_link_to_left_ankle_pitch_link_sphere1" type="fixed"><parent link="left_ankle_pitch_link" /><child link="left_ankle_pitch_link_sphere1" /><origin xyz="0.0005312478169798851 -0.009358920156955719 -0.023509079590439796" rpy="0 0 0" /></joint><link name="left_ankle_pitch_link_sphere2"><inertial><origin xyz="0 0 0" rpy="0 0 0" /><mass value="0.01" /><inertia ixx="0.001" ixy="0" ixz="0" iyy="0.001" iyz="0" izz="0.001" /></inertial><visual><origin rpy="0 0 0" xyz="0 0 0" /><geometry><sphere radius="0.009328470565378666" /></geometry><material name="color_left_ankle_pitch_link_sphere2_0"><color rgba="0.2 0.9 0.2 1.0" /></material></visual><collision><origin rpy="0 0 0" xyz="0 0 0" /><geometry><sphere radius="0.009328470565378666" /></geometry><drake:proximity_properties><drake:rigid_hydroelastic /><drake:mesh_resolution_hint value="1.5" /><drake:hunt_crossley_dissipation value="1.25" /></drake:proximity_properties></collision></link><joint name="left_ankle_pitch_link_to_left_ankle_pitch_link_sphere2" type="fixed"><parent link="left_ankle_pitch_link" /><child link="left_ankle_pitch_link_sphere2" /><origin xyz="0.006843125447630882 -0.00020012885215692222 0.005019757431000471" rpy="0 0 0" /></joint><link name="left_ankle_pitch_link_sphere3"><inertial><origin xyz="0 0 0" rpy="0 0 0" /><mass value="0.01" /><inertia ixx="0.001" ixy="0" ixz="0" iyy="0.001" iyz="0" izz="0.001" /></inertial><visual><origin rpy="0 0 0" xyz="0 0 0" /><geometry><sphere radius="0.010167974978685379" /></geometry><material name="color_left_ankle_pitch_link_sphere3_0"><color rgba="0.2 0.9 0.2 1.0" /></material></visual><collision><origin rpy="0 0 0" xyz="0 0 0" /><geometry><sphere radius="0.010167974978685379" /></geometry><drake:proximity_properties><drake:rigid_hydroelastic /><drake:mesh_resolution_hint value="1.5" /><drake:hunt_crossley_dissipation value="1.25" /></drake:proximity_properties></collision></link><joint name="left_ankle_pitch_link_to_left_ankle_pitch_link_sphere3" type="fixed"><parent link="left_ankle_pitch_link" /><child link="left_ankle_pitch_link_sphere3" /><origin xyz="0.00039108842611312866 0.009366544894874096 -0.023081229999661446" rpy="0 0 0" /></joint><link name="left_ankle_pitch_link_sphere4"><inertial><origin xyz="0 0 0" rpy="0 0 0" /><mass value="0.01" /><inertia ixx="0.001" ixy="0" ixz="0" iyy="0.001" iyz="0" izz="0.001" /></inertial><visual><origin rpy="0 0 0" xyz="0 0 0" /><geometry><sphere radius="0.009920455515384674" /></geometry><material name="color_left_ankle_pitch_link_sphere4_0"><color rgba="0.2 0.9 0.2 1.0" /></material></visual><collision><origin rpy="0 0 0" xyz="0 0 0" /><geometry><sphere radius="0.009920455515384674" /></geometry><drake:proximity_properties><drake:rigid_hydroelastic /><drake:mesh_resolution_hint value="1.5" /><drake:hunt_crossley_dissipation value="1.25" /></drake:proximity_properties></collision></link><joint name="left_ankle_pitch_link_to_left_ankle_pitch_link_sphere4" type="fixed"><parent link="left_ankle_pitch_link" /><child link="left_ankle_pitch_link_sphere4" /><origin xyz="-0.008759360760450363 0.00034302729181945324 -0.0028617146890610456" rpy="0 0 0" /></joint><link name="left_ankle_roll_link_sphere1"><inertial><origin xyz="0 0 0" rpy="0 0 0" /><mass value="0.01" /><inertia ixx="0.001" ixy="0" ixz="0" iyy="0.001" iyz="0" izz="0.001" /></inertial><visual><origin rpy="0 0 0" xyz="0 0 0" /><geometry><sphere radius="0.036363039165735245" /></geometry><material name="color_left_ankle_roll_link_sphere1_0"><color rgba="0.2 0.9 0.2 1.0" /></material></visual><collision><origin rpy="0 0 0" xyz="0 0 0" /><geometry><sphere radius="0.036363039165735245" /></geometry><drake:proximity_properties><drake:rigid_hydroelastic /><drake:mesh_resolution_hint value="1.5" /><drake:hunt_crossley_dissipation value="1.25" /></drake:proximity_properties></collision></link><joint name="left_ankle_roll_link_to_left_ankle_roll_link_sphere1" type="fixed"><parent link="left_ankle_roll_link" /><child link="left_ankle_roll_link_sphere1" /><origin xyz="0.06484188139438629 0.00012148998939665034 -0.01576853357255459" rpy="0 0 0" /></joint><link name="left_ankle_roll_link_sphere2"><inertial><origin xyz="0 0 0" rpy="0 0 0" /><mass value="0.01" /><inertia ixx="0.001" ixy="0" ixz="0" iyy="0.001" iyz="0" izz="0.001" /></inertial><visual><origin rpy="0 0 0" xyz="0 0 0" /><geometry><sphere radius="0.03163197636604309" /></geometry><material name="color_left_ankle_roll_link_sphere2_0"><color rgba="0.2 0.9 0.2 1.0" /></material></visual><collision><origin rpy="0 0 0" xyz="0 0 0" /><geometry><sphere radius="0.03163197636604309" /></geometry><drake:proximity_properties><drake:rigid_hydroelastic /><drake:mesh_resolution_hint value="1.5" /><drake:hunt_crossley_dissipation value="1.25" /></drake:proximity_properties></collision></link><joint name="left_ankle_roll_link_to_left_ankle_roll_link_sphere2" type="fixed"><parent link="left_ankle_roll_link" /><child link="left_ankle_roll_link_sphere2" /><origin xyz="0.1356523185968399 0.00024248783302027732 -0.025666378438472748" rpy="0 0 0" /></joint><link name="left_ankle_roll_link_sphere3"><inertial><origin xyz="0 0 0" rpy="0 0 0" /><mass value="0.01" /><inertia ixx="0.001" ixy="0" ixz="0" iyy="0.001" iyz="0" izz="0.001" /></inertial><visual><origin rpy="0 0 0" xyz="0 0 0" /><geometry><sphere radius="0.038335829973220825" /></geometry><material name="color_left_ankle_roll_link_sphere3_0"><color rgba="0.2 0.9 0.2 1.0" /></material></visual><collision><origin rpy="0 0 0" xyz="0 0 0" /><geometry><sphere radius="0.038335829973220825" /></geometry><drake:proximity_properties><drake:rigid_hydroelastic /><drake:mesh_resolution_hint value="1.5" /><drake:hunt_crossley_dissipation value="1.25" /></drake:proximity_properties></collision></link><joint name="left_ankle_roll_link_to_left_ankle_roll_link_sphere3" type="fixed"><parent link="left_ankle_roll_link" /><child link="left_ankle_roll_link_sphere3" /><origin xyz="-0.0454358235001564 -0.00014850081061013043 -0.014682523906230927" rpy="0 0 0" /></joint><link name="left_ankle_roll_link_sphere4"><inertial><origin xyz="0 0 0" rpy="0 0 0" /><mass value="0.01" /><inertia ixx="0.001" ixy="0" ixz="0" iyy="0.001" iyz="0" izz="0.001" /></inertial><visual><origin rpy="0 0 0" xyz="0 0 0" /><geometry><sphere radius="0.02555808052420616" /></geometry><material name="color_left_ankle_roll_link_sphere4_0"><color rgba="0.2 0.9 0.2 1.0" /></material></visual><collision><origin rpy="0 0 0" xyz="0 0 0" /><geometry><sphere radius="0.02555808052420616" /></geometry><drake:proximity_properties><drake:rigid_hydroelastic /><drake:mesh_resolution_hint value="1.5" /><drake:hunt_crossley_dissipation value="1.25" /></drake:proximity_properties></collision></link><joint name="left_ankle_roll_link_to_left_ankle_roll_link_sphere4" type="fixed"><parent link="left_ankle_roll_link" /><child link="left_ankle_roll_link_sphere4" /><origin xyz="0.025457490235567093 -0.000610856746789068 -0.01827399805188179" rpy="0 0 0" /></joint><link name="right_hip_yaw_link_sphere1"><inertial><origin xyz="0 0 0" rpy="0 0 0" /><mass value="0.01" /><inertia ixx="0.001" ixy="0" ixz="0" iyy="0.001" iyz="0" izz="0.001" /></inertial><visual><origin rpy="0 0 0" xyz="0 0 0" /><geometry><sphere radius="0.02475532330572605" /></geometry><material name="color_right_hip_yaw_link_sphere1_0"><color rgba="0.2 0.2 0.9 1.0" /></material></visual><collision><origin rpy="0 0 0" xyz="0 0 0" /><geometry><sphere radius="0.02475532330572605" /></geometry><drake:proximity_properties><drake:rigid_hydroelastic /><drake:mesh_resolution_hint value="1.5" /><drake:hunt_crossley_dissipation value="1.25" /></drake:proximity_properties></collision></link><joint name="right_hip_yaw_link_to_right_hip_yaw_link_sphere1" type="fixed"><parent link="right_hip_yaw_link" /><child link="right_hip_yaw_link_sphere1" /><origin xyz="-0.037665706127882004 0.025210065767169 -0.023536227643489838" rpy="0 0 0" /></joint><link name="right_hip_yaw_link_sphere2"><inertial><origin xyz="0 0 0" rpy="0 0 0" /><mass value="0.01" /><inertia ixx="0.001" ixy="0" ixz="0" iyy="0.001" iyz="0" izz="0.001" /></inertial><visual><origin rpy="0 0 0" xyz="0 0 0" /><geometry><sphere radius="0.01449542585760355" /></geometry><material name="color_right_hip_yaw_link_sphere2_0"><color rgba="0.2 0.2 0.9 1.0" /></material></visual><collision><origin rpy="0 0 0" xyz="0 0 0" /><geometry><sphere radius="0.01449542585760355" /></geometry><drake:proximity_properties><drake:rigid_hydroelastic /><drake:mesh_resolution_hint value="1.5" /><drake:hunt_crossley_dissipation value="1.25" /></drake:proximity_properties></collision></link><joint name="right_hip_yaw_link_to_right_hip_yaw_link_sphere2" type="fixed"><parent link="right_hip_yaw_link" /><child link="right_hip_yaw_link_sphere2" /><origin xyz="0.0259780902415514 0.006770155858248472 0.06561353802680969" rpy="0 0 0" /></joint><link name="right_hip_yaw_link_sphere3"><inertial><origin xyz="0 0 0" rpy="0 0 0" /><mass value="0.01" /><inertia ixx="0.001" ixy="0" ixz="0" iyy="0.001" iyz="0" izz="0.001" /></inertial><visual><origin rpy="0 0 0" xyz="0 0 0" /><geometry><sphere radius="0.01735180802643299" /></geometry><material name="color_right_hip_yaw_link_sphere3_0"><color rgba="0.2 0.2 0.9 1.0" /></material></visual><collision><origin rpy="0 0 0" xyz="0 0 0" /><geometry><sphere radius="0.01735180802643299" /></geometry><drake:proximity_properties><drake:rigid_hydroelastic /><drake:mesh_resolution_hint value="1.5" /><drake:hunt_crossley_dissipation value="1.25" /></drake:proximity_properties></collision></link><joint name="right_hip_yaw_link_to_right_hip_yaw_link_sphere3" type="fixed"><parent link="right_hip_yaw_link" /><child link="right_hip_yaw_link_sphere3" /><origin xyz="-0.024567706510424614 0.022813042625784874 0.056966282427310944" rpy="0 0 0" /></joint><link name="right_hip_yaw_link_sphere4"><inertial><origin xyz="0 0 0" rpy="0 0 0" /><mass value="0.01" /><inertia ixx="0.001" ixy="0" ixz="0" iyy="0.001" iyz="0" izz="0.001" /></inertial><visual><origin rpy="0 0 0" xyz="0 0 0" /><geometry><sphere radius="0.028688784688711166" /></geometry><material name="color_right_hip_yaw_link_sphere4_0"><color rgba="0.2 0.2 0.9 1.0" /></material></visual><collision><origin rpy="0 0 0" xyz="0 0 0" /><geometry><sphere radius="0.028688784688711166" /></geometry><drake:proximity_properties><drake:rigid_hydroelastic /><drake:mesh_resolution_hint value="1.5" /><drake:hunt_crossley_dissipation value="1.25" /></drake:proximity_properties></collision></link><joint name="right_hip_yaw_link_to_right_hip_yaw_link_sphere4" type="fixed"><parent link="right_hip_yaw_link" /><child link="right_hip_yaw_link_sphere4" /><origin xyz="0.03625304624438286 0.02780681662261486 -0.016019737347960472" rpy="0 0 0" /></joint><link name="right_hip_pitch_link_sphere1"><inertial><origin xyz="0 0 0" rpy="0 0 0" /><mass value="0.01" /><inertia ixx="0.001" ixy="0" ixz="0" iyy="0.001" iyz="0" izz="0.001" /></inertial><visual><origin rpy="0 0 0" xyz="0 0 0" /><geometry><sphere radius="0.01640346832573414" /></geometry><material name="color_right_hip_pitch_link_sphere1_0"><color rgba="0.2 0.2 0.9 1.0" /></material></visual><collision><origin rpy="0 0 0" xyz="0 0 0" /><geometry><sphere radius="0.01640346832573414" /></geometry><drake:proximity_properties><drake:rigid_hydroelastic /><drake:mesh_resolution_hint value="1.5" /><drake:hunt_crossley_dissipation value="1.25" /></drake:proximity_properties></collision></link><joint name="right_hip_pitch_link_to_right_hip_pitch_link_sphere1" type="fixed"><parent link="right_hip_pitch_link" /><child link="right_hip_pitch_link_sphere1" /><origin xyz="0.009448417462408543 0.05554869398474693 -0.026210326701402664" rpy="0 0 0" /></joint><link name="right_hip_pitch_link_sphere2"><inertial><origin xyz="0 0 0" rpy="0 0 0" /><mass value="0.01" /><inertia ixx="0.001" ixy="0" ixz="0" iyy="0.001" iyz="0" izz="0.001" /></inertial><visual><origin rpy="0 0 0" xyz="0 0 0" /><geometry><sphere radius="0.024246539920568466" /></geometry><material name="color_right_hip_pitch_link_sphere2_0"><color rgba="0.2 0.2 0.9 1.0" /></material></visual><collision><origin rpy="0 0 0" xyz="0 0 0" /><geometry><sphere radius="0.024246539920568466" /></geometry><drake:proximity_properties><drake:rigid_hydroelastic /><drake:mesh_resolution_hint value="1.5" /><drake:hunt_crossley_dissipation value="1.25" /></drake:proximity_properties></collision></link><joint name="right_hip_pitch_link_to_right_hip_pitch_link_sphere2" type="fixed"><parent link="right_hip_pitch_link" /><child link="right_hip_pitch_link_sphere2" /><origin xyz="-0.015889625996351242 -0.031951095908880234 0.030326692387461662" rpy="0 0 0" /></joint><link name="right_hip_pitch_link_sphere3"><inertial><origin xyz="0 0 0" rpy="0 0 0" /><mass value="0.01" /><inertia ixx="0.001" ixy="0" ixz="0" iyy="0.001" iyz="0" izz="0.001" /></inertial><visual><origin rpy="0 0 0" xyz="0 0 0" /><geometry><sphere radius="0.017913375049829483" /></geometry><material name="color_right_hip_pitch_link_sphere3_0"><color rgba="0.2 0.2 0.9 1.0" /></material></visual><collision><origin rpy="0 0 0" xyz="0 0 0" /><geometry><sphere radius="0.017913375049829483" /></geometry><drake:proximity_properties><drake:rigid_hydroelastic /><drake:mesh_resolution_hint value="1.5" /><drake:hunt_crossley_dissipation value="1.25" /></drake:proximity_properties></collision></link><joint name="right_hip_pitch_link_to_right_hip_pitch_link_sphere3" type="fixed"><parent link="right_hip_pitch_link" /><child link="right_hip_pitch_link_sphere3" /><origin xyz="-0.02842537872493267 -0.009321879595518112 -0.04531102627515793" rpy="0 0 0" /></joint><link name="right_hip_roll_link_sphere1"><inertial><origin xyz="0 0 0" rpy="0 0 0" /><mass value="0.01" /><inertia ixx="0.001" ixy="0" ixz="0" iyy="0.001" iyz="0" izz="0.001" /></inertial><visual><origin rpy="0 0 0" xyz="0 0 0" /><geometry><sphere radius="0.06411394476890564" /></geometry><material name="color_right_hip_roll_link_sphere1_0"><color rgba="0.2 0.2 0.9 1.0" /></material></visual><collision><origin rpy="0 0 0" xyz="0 0 0" /><geometry><sphere radius="0.06411394476890564" /></geometry><drake:proximity_properties><drake:rigid_hydroelastic /><drake:mesh_resolution_hint value="1.5" /><drake:hunt_crossley_dissipation value="1.25" /></drake:proximity_properties></collision></link><joint name="right_hip_roll_link_to_right_hip_roll_link_sphere1" type="fixed"><parent link="right_hip_roll_link" /><child link="right_hip_roll_link_sphere1" /><origin xyz="0.0020176160614937544 -0.0001231100904988125 -0.14142316579818726" rpy="0 0 0" /></joint><link name="right_hip_roll_link_sphere2"><inertial><origin xyz="0 0 0" rpy="0 0 0" /><mass value="0.01" /><inertia ixx="0.001" ixy="0" ixz="0" iyy="0.001" iyz="0" izz="0.001" /></inertial><visual><origin rpy="0 0 0" xyz="0 0 0" /><geometry><sphere radius="0.02888680249452591" /></geometry><material name="color_right_hip_roll_link_sphere2_0"><color rgba="0.2 0.2 0.9 1.0" /></material></visual><collision><origin rpy="0 0 0" xyz="0 0 0" /><geometry><sphere radius="0.02888680249452591" /></geometry><drake:proximity_properties><drake:rigid_hydroelastic /><drake:mesh_resolution_hint value="1.5" /><drake:hunt_crossley_dissipation value="1.25" /></drake:proximity_properties></collision></link><joint name="right_hip_roll_link_to_right_hip_roll_link_sphere2" type="fixed"><parent link="right_hip_roll_link" /><child link="right_hip_roll_link_sphere2" /><origin xyz="0.04076015576720238 -0.002613452961668372 -0.01238175481557846" rpy="0 0 0" /></joint><link name="right_hip_roll_link_sphere3"><inertial><origin xyz="0 0 0" rpy="0 0 0" /><mass value="0.01" /><inertia ixx="0.001" ixy="0" ixz="0" iyy="0.001" iyz="0" izz="0.001" /></inertial><visual><origin rpy="0 0 0" xyz="0 0 0" /><geometry><sphere radius="0.05759043991565704" /></geometry><material name="color_right_hip_roll_link_sphere3_0"><color rgba="0.2 0.2 0.9 1.0" /></material></visual><collision><origin rpy="0 0 0" xyz="0 0 0" /><geometry><sphere radius="0.05759043991565704" /></geometry><drake:proximity_properties><drake:rigid_hydroelastic /><drake:mesh_resolution_hint value="1.5" /><drake:hunt_crossley_dissipation value="1.25" /></drake:proximity_properties></collision></link><joint name="right_hip_roll_link_to_right_hip_roll_link_sphere3" type="fixed"><parent link="right_hip_roll_link" /><child link="right_hip_roll_link_sphere3" /><origin xyz="0.006684152875095606 6.80402954458259e-05 -0.2507788836956024" rpy="0 0 0" /></joint><link name="right_hip_roll_link_sphere4"><inertial><origin xyz="0 0 0" rpy="0 0 0" /><mass value="0.01" /><inertia ixx="0.001" ixy="0" ixz="0" iyy="0.001" iyz="0" izz="0.001" /></inertial><visual><origin rpy="0 0 0" xyz="0 0 0" /><geometry><sphere radius="0.02915494702756405" /></geometry><material name="color_right_hip_roll_link_sphere4_0"><color rgba="0.2 0.2 0.9 1.0" /></material></visual><collision><origin rpy="0 0 0" xyz="0 0 0" /><geometry><sphere radius="0.02915494702756405" /></geometry><drake:proximity_properties><drake:rigid_hydroelastic /><drake:mesh_resolution_hint value="1.5" /><drake:hunt_crossley_dissipation value="1.25" /></drake:proximity_properties></collision></link><joint name="right_hip_roll_link_to_right_hip_roll_link_sphere4" type="fixed"><parent link="right_hip_roll_link" /><child link="right_hip_roll_link_sphere4" /><origin xyz="0.011829369701445103 0.0017154774395748973 -0.3662645220756531" rpy="0 0 0" /></joint><link name="right_knee_link_sphere1"><inertial><origin xyz="0 0 0" rpy="0 0 0" /><mass value="0.01" /><inertia ixx="0.001" ixy="0" ixz="0" iyy="0.001" iyz="0" izz="0.001" /></inertial><visual><origin rpy="0 0 0" xyz="0 0 0" /><geometry><sphere radius="0.011684687808156013" /></geometry><material name="color_right_knee_link_sphere1_0"><color rgba="0.2 0.2 0.9 1.0" /></material></visual><collision><origin rpy="0 0 0" xyz="0 0 0" /><geometry><sphere radius="0.011684687808156013" /></geometry><drake:proximity_properties><drake:rigid_hydroelastic /><drake:mesh_resolution_hint value="1.5" /><drake:hunt_crossley_dissipation value="1.25" /></drake:proximity_properties></collision></link><joint name="right_knee_link_to_right_knee_link_sphere1" type="fixed"><parent link="right_knee_link" /><child link="right_knee_link_sphere1" /><origin xyz="-0.015890460461378098 -0.0005430210148915648 -0.3735186457633972" rpy="0 0 0" /></joint><link name="right_ankle_pitch_link_sphere1"><inertial><origin xyz="0 0 0" rpy="0 0 0" /><mass value="0.01" /><inertia ixx="0.001" ixy="0" ixz="0" iyy="0.001" iyz="0" izz="0.001" /></inertial><visual><origin rpy="0 0 0" xyz="0 0 0" /><geometry><sphere radius="0.009788116440176964" /></geometry><material name="color_right_ankle_pitch_link_sphere1_0"><color rgba="0.2 0.2 0.9 1.0" /></material></visual><collision><origin rpy="0 0 0" xyz="0 0 0" /><geometry><sphere radius="0.009788116440176964" /></geometry><drake:proximity_properties><drake:rigid_hydroelastic /><drake:mesh_resolution_hint value="1.5" /><drake:hunt_crossley_dissipation value="1.25" /></drake:proximity_properties></collision></link><joint name="right_ankle_pitch_link_to_right_ankle_pitch_link_sphere1" type="fixed"><parent link="right_ankle_pitch_link" /><child link="right_ankle_pitch_link_sphere1" /><origin xyz="0.0003584670484997332 0.009791352786123753 -0.024093342944979668" rpy="0 0 0" /></joint><link name="right_ankle_pitch_link_sphere2"><inertial><origin xyz="0 0 0" rpy="0 0 0" /><mass value="0.01" /><inertia ixx="0.001" ixy="0" ixz="0" iyy="0.001" iyz="0" izz="0.001" /></inertial><visual><origin rpy="0 0 0" xyz="0 0 0" /><geometry><sphere radius="0.010482694953680038" /></geometry><material name="color_right_ankle_pitch_link_sphere2_0"><color rgba="0.2 0.2 0.9 1.0" /></material></visual><collision><origin rpy="0 0 0" xyz="0 0 0" /><geometry><sphere radius="0.010482694953680038" /></geometry><drake:proximity_properties><drake:rigid_hydroelastic /><drake:mesh_resolution_hint value="1.5" /><drake:hunt_crossley_dissipation value="1.25" /></drake:proximity_properties></collision></link><joint name="right_ankle_pitch_link_to_right_ankle_pitch_link_sphere2" type="fixed"><parent link="right_ankle_pitch_link" /><child link="right_ankle_pitch_link_sphere2" /><origin xyz="-0.008090229704976082 0.00013004470383748412 -0.0029204462189227343" rpy="0 0 0" /></joint><link name="right_ankle_pitch_link_sphere3"><inertial><origin xyz="0 0 0" rpy="0 0 0" /><mass value="0.01" /><inertia ixx="0.001" ixy="0" ixz="0" iyy="0.001" iyz="0" izz="0.001" /></inertial><visual><origin rpy="0 0 0" xyz="0 0 0" /><geometry><sphere radius="0.009844348765909672" /></geometry><material name="color_right_ankle_pitch_link_sphere3_0"><color rgba="0.2 0.2 0.9 1.0" /></material></visual><collision><origin rpy="0 0 0" xyz="0 0 0" /><geometry><sphere radius="0.009844348765909672" /></geometry><drake:proximity_properties><drake:rigid_hydroelastic /><drake:mesh_resolution_hint value="1.5" /><drake:hunt_crossley_dissipation value="1.25" /></drake:proximity_properties></collision></link><joint name="right_ankle_pitch_link_to_right_ankle_pitch_link_sphere3" type="fixed"><parent link="right_ankle_pitch_link" /><child link="right_ankle_pitch_link_sphere3" /><origin xyz="0.0005831252783536911 -0.009590724483132362 -0.023617392405867577" rpy="0 0 0" /></joint><link name="right_ankle_pitch_link_sphere4"><inertial><origin xyz="0 0 0" rpy="0 0 0" /><mass value="0.01" /><inertia ixx="0.001" ixy="0" ixz="0" iyy="0.001" iyz="0" izz="0.001" /></inertial><visual><origin rpy="0 0 0" xyz="0 0 0" /><geometry><sphere radius="0.009110236540436745" /></geometry><material name="color_right_ankle_pitch_link_sphere4_0"><color rgba="0.2 0.2 0.9 1.0" /></material></visual><collision><origin rpy="0 0 0" xyz="0 0 0" /><geometry><sphere radius="0.009110236540436745" /></geometry><drake:proximity_properties><drake:rigid_hydroelastic /><drake:mesh_resolution_hint value="1.5" /><drake:hunt_crossley_dissipation value="1.25" /></drake:proximity_properties></collision></link><joint name="right_ankle_pitch_link_to_right_ankle_pitch_link_sphere4" type="fixed"><parent link="right_ankle_pitch_link" /><child link="right_ankle_pitch_link_sphere4" /><origin xyz="0.007330447435379028 2.6727066142484546e-05 0.004622550215572119" rpy="0 0 0" /></joint><link name="right_ankle_roll_link_sphere1"><inertial><origin xyz="0 0 0" rpy="0 0 0" /><mass value="0.01" /><inertia ixx="0.001" ixy="0" ixz="0" iyy="0.001" iyz="0" izz="0.001" /></inertial><visual><origin rpy="0 0 0" xyz="0 0 0" /><geometry><sphere radius="0.0336172953248024" /></geometry><material name="color_right_ankle_roll_link_sphere1_0"><color rgba="0.2 0.2 0.9 1.0" /></material></visual><collision><origin rpy="0 0 0" xyz="0 0 0" /><geometry><sphere radius="0.0336172953248024" /></geometry><drake:proximity_properties><drake:rigid_hydroelastic /><drake:mesh_resolution_hint value="1.5" /><drake:hunt_crossley_dissipation value="1.25" /></drake:proximity_properties></collision></link><joint name="right_ankle_roll_link_to_right_ankle_roll_link_sphere1" type="fixed"><parent link="right_ankle_roll_link" /><child link="right_ankle_roll_link_sphere1" /><origin xyz="0.12971055507659912 -0.0006492937682196498 -0.024949345737695694" rpy="0 0 0" /></joint><link name="right_ankle_roll_link_sphere2"><inertial><origin xyz="0 0 0" rpy="0 0 0" /><mass value="0.01" /><inertia ixx="0.001" ixy="0" ixz="0" iyy="0.001" iyz="0" izz="0.001" /></inertial><visual><origin rpy="0 0 0" xyz="0 0 0" /><geometry><sphere radius="0.0352960005402565" /></geometry><material name="color_right_ankle_roll_link_sphere2_0"><color rgba="0.2 0.2 0.9 1.0" /></material></visual><collision><origin rpy="0 0 0" xyz="0 0 0" /><geometry><sphere radius="0.0352960005402565" /></geometry><drake:proximity_properties><drake:rigid_hydroelastic /><drake:mesh_resolution_hint value="1.5" /><drake:hunt_crossley_dissipation value="1.25" /></drake:proximity_properties></collision></link><joint name="right_ankle_roll_link_to_right_ankle_roll_link_sphere2" type="fixed"><parent link="right_ankle_roll_link" /><child link="right_ankle_roll_link_sphere2" /><origin xyz="0.05043923854827881 0.0008641728782095015 -0.013622225262224674" rpy="0 0 0" /></joint><link name="right_ankle_roll_link_sphere3"><inertial><origin xyz="0 0 0" rpy="0 0 0" /><mass value="0.01" /><inertia ixx="0.001" ixy="0" ixz="0" iyy="0.001" iyz="0" izz="0.001" /></inertial><visual><origin rpy="0 0 0" xyz="0 0 0" /><geometry><sphere radius="0.03766068443655968" /></geometry><material name="color_right_ankle_roll_link_sphere3_0"><color rgba="0.2 0.2 0.9 1.0" /></material></visual><collision><origin rpy="0 0 0" xyz="0 0 0" /><geometry><sphere radius="0.03766068443655968" /></geometry><drake:proximity_properties><drake:rigid_hydroelastic /><drake:mesh_resolution_hint value="1.5" /><drake:hunt_crossley_dissipation value="1.25" /></drake:proximity_properties></collision></link><joint name="right_ankle_roll_link_to_right_ankle_roll_link_sphere3" type="fixed"><parent link="right_ankle_roll_link" /><child link="right_ankle_roll_link_sphere3" /><origin xyz="-0.0450952909886837 0.00170988985337317 -0.014922095462679863" rpy="0 0 0" /></joint><link name="right_ankle_roll_link_sphere4"><inertial><origin xyz="0 0 0" rpy="0 0 0" /><mass value="0.01" /><inertia ixx="0.001" ixy="0" ixz="0" iyy="0.001" iyz="0" izz="0.001" /></inertial><visual><origin rpy="0 0 0" xyz="0 0 0" /><geometry><sphere radius="0.016279812902212143" /></geometry><material name="color_right_ankle_roll_link_sphere4_0"><color rgba="0.2 0.2 0.9 1.0" /></material></visual><collision><origin rpy="0 0 0" xyz="0 0 0" /><geometry><sphere radius="0.016279812902212143" /></geometry><drake:proximity_properties><drake:rigid_hydroelastic /><drake:mesh_resolution_hint value="1.5" /><drake:hunt_crossley_dissipation value="1.25" /></drake:proximity_properties></collision></link><joint name="right_ankle_roll_link_to_right_ankle_roll_link_sphere4" type="fixed"><parent link="right_ankle_roll_link" /><child link="right_ankle_roll_link_sphere4" /><origin xyz="0.006583199370652437 -0.024508822709321976 -0.025513090193271637" rpy="0 0 0" /></joint><link name="torso_link_sphere1"><inertial><origin xyz="0 0 0" rpy="0 0 0" /><mass value="0.01" /><inertia ixx="0.001" ixy="0" ixz="0" iyy="0.001" iyz="0" izz="0.001" /></inertial><visual><origin rpy="0 0 0" xyz="0 0 0" /><geometry><sphere radius="0.05425542965531349" /></geometry><material name="color_torso_link_sphere1_0"><color rgba="0.9 0.2 0.2 1.0" /></material></visual><collision><origin rpy="0 0 0" xyz="0 0 0" /><geometry><sphere radius="0.05425542965531349" /></geometry><drake:proximity_properties><drake:rigid_hydroelastic /><drake:mesh_resolution_hint value="1.5" /><drake:hunt_crossley_dissipation value="1.25" /></drake:proximity_properties></collision></link><joint name="torso_link_to_torso_link_sphere1" type="fixed"><parent link="torso_link" /><child link="torso_link_sphere1" /><origin xyz="-0.0006071061361581087 -0.0009373507346026599 0.0708697959780693" rpy="0 0 0" /></joint><link name="torso_link_sphere2"><inertial><origin xyz="0 0 0" rpy="0 0 0" /><mass value="0.01" /><inertia ixx="0.001" ixy="0" ixz="0" iyy="0.001" iyz="0" izz="0.001" /></inertial><visual><origin rpy="0 0 0" xyz="0 0 0" /><geometry><sphere radius="0.04342954605817795" /></geometry><material name="color_torso_link_sphere2_0"><color rgba="0.9 0.2 0.2 1.0" /></material></visual><collision><origin rpy="0 0 0" xyz="0 0 0" /><geometry><sphere radius="0.04342954605817795" /></geometry><drake:proximity_properties><drake:rigid_hydroelastic /><drake:mesh_resolution_hint value="1.5" /><drake:hunt_crossley_dissipation value="1.25" /></drake:proximity_properties></collision></link><joint name="torso_link_to_torso_link_sphere2" type="fixed"><parent link="torso_link" /><child link="torso_link_sphere2" /><origin xyz="0.060880254954099655 -0.007517693564295769 0.7208219170570374" rpy="0 0 0" /></joint><link name="torso_link_sphere3"><inertial><origin xyz="0 0 0" rpy="0 0 0" /><mass value="0.01" /><inertia ixx="0.001" ixy="0" ixz="0" iyy="0.001" iyz="0" izz="0.001" /></inertial><visual><origin rpy="0 0 0" xyz="0 0 0" /><geometry><sphere radius="0.07769273221492767" /></geometry><material name="color_torso_link_sphere3_0"><color rgba="0.9 0.2 0.2 1.0" /></material></visual><collision><origin rpy="0 0 0" xyz="0 0 0" /><geometry><sphere radius="0.07769273221492767" /></geometry><drake:proximity_properties><drake:rigid_hydroelastic /><drake:mesh_resolution_hint value="1.5" /><drake:hunt_crossley_dissipation value="1.25" /></drake:proximity_properties></collision></link><joint name="torso_link_to_torso_link_sphere3" type="fixed"><parent link="torso_link" /><child link="torso_link_sphere3" /><origin xyz="-0.0002492230851203203 0.00512490002438426 0.40687453746795654" rpy="0 0 0" /></joint><link name="left_shoulder_pitch_link_sphere1"><inertial><origin xyz="0 0 0" rpy="0 0 0" /><mass value="0.01" /><inertia ixx="0.001" ixy="0" ixz="0" iyy="0.001" iyz="0" izz="0.001" /></inertial><visual><origin rpy="0 0 0" xyz="0 0 0" /><geometry><sphere radius="0.014496734365820885" /></geometry><material name="color_left_shoulder_pitch_link_sphere1_0"><color rgba="0.9 0.9 0.2 1.0" /></material></visual><collision><origin rpy="0 0 0" xyz="0 0 0" /><geometry><sphere radius="0.014496734365820885" /></geometry><drake:proximity_properties><drake:rigid_hydroelastic /><drake:mesh_resolution_hint value="1.5" /><drake:hunt_crossley_dissipation value="1.25" /></drake:proximity_properties></collision></link><joint name="left_shoulder_pitch_link_to_left_shoulder_pitch_link_sphere1" type="fixed"><parent link="left_shoulder_pitch_link" /><child link="left_shoulder_pitch_link_sphere1" /><origin xyz="-0.012806085869669914 0.05015198513865471 -0.038937900215387344" rpy="0 0 0" /></joint><link name="left_shoulder_pitch_link_sphere2"><inertial><origin xyz="0 0 0" rpy="0 0 0" /><mass value="0.01" /><inertia ixx="0.001" ixy="0" ixz="0" iyy="0.001" iyz="0" izz="0.001" /></inertial><visual><origin rpy="0 0 0" xyz="0 0 0" /><geometry><sphere radius="0.014783861115574837" /></geometry><material name="color_left_shoulder_pitch_link_sphere2_0"><color rgba="0.9 0.9 0.2 1.0" /></material></visual><collision><origin rpy="0 0 0" xyz="0 0 0" /><geometry><sphere radius="0.014783861115574837" /></geometry><drake:proximity_properties><drake:rigid_hydroelastic /><drake:mesh_resolution_hint value="1.5" /><drake:hunt_crossley_dissipation value="1.25" /></drake:proximity_properties></collision></link><joint name="left_shoulder_pitch_link_to_left_shoulder_pitch_link_sphere2" type="fixed"><parent link="left_shoulder_pitch_link" /><child link="left_shoulder_pitch_link_sphere2" /><origin xyz="-0.007922135293483734 0.09627038240432739 -0.014241914264857769" rpy="0 0 0" /></joint><link name="left_shoulder_pitch_link_sphere3"><inertial><origin xyz="0 0 0" rpy="0 0 0" /><mass value="0.01" /><inertia ixx="0.001" ixy="0" ixz="0" iyy="0.001" iyz="0" izz="0.001" /></inertial><visual><origin rpy="0 0 0" xyz="0 0 0" /><geometry><sphere radius="0.01530552376061678" /></geometry><material name="color_left_shoulder_pitch_link_sphere3_0"><color rgba="0.9 0.9 0.2 1.0" /></material></visual><collision><origin rpy="0 0 0" xyz="0 0 0" /><geometry><sphere radius="0.01530552376061678" /></geometry><drake:proximity_properties><drake:rigid_hydroelastic /><drake:mesh_resolution_hint value="1.5" /><drake:hunt_crossley_dissipation value="1.25" /></drake:proximity_properties></collision></link><joint name="left_shoulder_pitch_link_to_left_shoulder_pitch_link_sphere3" type="fixed"><parent link="left_shoulder_pitch_link" /><child link="left_shoulder_pitch_link_sphere3" /><origin xyz="-0.014848542399704456 0.06730856746435165 0.027110842987895012" rpy="0 0 0" /></joint><link name="left_shoulder_roll_link_sphere1"><inertial><origin xyz="0 0 0" rpy="0 0 0" /><mass value="0.01" /><inertia ixx="0.001" ixy="0" ixz="0" iyy="0.001" iyz="0" izz="0.001" /></inertial><visual><origin rpy="0 0 0" xyz="0 0 0" /><geometry><sphere radius="0.011372411623597145" /></geometry><material name="color_left_shoulder_roll_link_sphere1_0"><color rgba="0.9 0.9 0.2 1.0" /></material></visual><collision><origin rpy="0 0 0" xyz="0 0 0" /><geometry><sphere radius="0.011372411623597145" /></geometry><drake:proximity_properties><drake:rigid_hydroelastic /><drake:mesh_resolution_hint value="1.5" /><drake:hunt_crossley_dissipation value="1.25" /></drake:proximity_properties></collision></link><joint name="left_shoulder_roll_link_to_left_shoulder_roll_link_sphere1" type="fixed"><parent link="left_shoulder_roll_link" /><child link="left_shoulder_roll_link_sphere1" /><origin xyz="0.0021241200156509876 0.012873485684394836 -0.0995306596159935" rpy="0 0 0" /></joint><link name="left_shoulder_roll_link_sphere2"><inertial><origin xyz="0 0 0" rpy="0 0 0" /><mass value="0.01" /><inertia ixx="0.001" ixy="0" ixz="0" iyy="0.001" iyz="0" izz="0.001" /></inertial><visual><origin rpy="0 0 0" xyz="0 0 0" /><geometry><sphere radius="0.016254479065537453" /></geometry><material name="color_left_shoulder_roll_link_sphere2_0"><color rgba="0.9 0.9 0.2 1.0" /></material></visual><collision><origin rpy="0 0 0" xyz="0 0 0" /><geometry><sphere radius="0.016254479065537453" /></geometry><drake:proximity_properties><drake:rigid_hydroelastic /><drake:mesh_resolution_hint value="1.5" /><drake:hunt_crossley_dissipation value="1.25" /></drake:proximity_properties></collision></link><joint name="left_shoulder_roll_link_to_left_shoulder_roll_link_sphere2" type="fixed"><parent link="left_shoulder_roll_link" /><child link="left_shoulder_roll_link_sphere2" /><origin xyz="-0.05733408406376839 0.024363243952393532 -0.10715324431657791" rpy="0 0 0" /></joint><link name="left_shoulder_roll_link_sphere3"><inertial><origin xyz="0 0 0" rpy="0 0 0" /><mass value="0.01" /><inertia ixx="0.001" ixy="0" ixz="0" iyy="0.001" iyz="0" izz="0.001" /></inertial><visual><origin rpy="0 0 0" xyz="0 0 0" /><geometry><sphere radius="0.01655576005578041" /></geometry><material name="color_left_shoulder_roll_link_sphere3_0"><color rgba="0.9 0.9 0.2 1.0" /></material></visual><collision><origin rpy="0 0 0" xyz="0 0 0" /><geometry><sphere radius="0.01655576005578041" /></geometry><drake:proximity_properties><drake:rigid_hydroelastic /><drake:mesh_resolution_hint value="1.5" /><drake:hunt_crossley_dissipation value="1.25" /></drake:proximity_properties></collision></link><joint name="left_shoulder_roll_link_to_left_shoulder_roll_link_sphere3" type="fixed"><parent link="left_shoulder_roll_link" /><child link="left_shoulder_roll_link_sphere3" /><origin xyz="-0.03354591131210327 -0.03588879108428955 -0.1085122600197792" rpy="0 0 0" /></joint><link name="left_shoulder_yaw_link_sphere1"><inertial><origin xyz="0 0 0" rpy="0 0 0" /><mass value="0.01" /><inertia ixx="0.001" ixy="0" ixz="0" iyy="0.001" iyz="0" izz="0.001" /></inertial><visual><origin rpy="0 0 0" xyz="0 0 0" /><geometry><sphere radius="0.03" /></geometry><material name="color_left_shoulder_yaw_link_sphere1_0"><color rgba="0.9 0.9 0.2 1.0" /></material></visual><collision><origin rpy="0 0 0" xyz="0 0 0" /><geometry><sphere radius="0.03" /></geometry><drake:proximity_properties><drake:rigid_hydroelastic /><drake:mesh_resolution_hint value="1.5" /><drake:hunt_crossley_dissipation value="1.25" /></drake:proximity_properties></collision></link><joint name="left_shoulder_yaw_link_to_left_shoulder_yaw_link_sphere1" type="fixed"><parent link="left_shoulder_yaw_link" /><child link="left_shoulder_yaw_link_sphere1" /><origin xyz="0 0 0" rpy="0 0 0" /></joint><link name="left_elbow_pitch_link_sphere1"><inertial><origin xyz="0 0 0" rpy="0 0 0" /><mass value="0.01" /><inertia ixx="0.001" ixy="0" ixz="0" iyy="0.001" iyz="0" izz="0.001" /></inertial><visual><origin rpy="0 0 0" xyz="0 0 0" /><geometry><sphere radius="0.007698118686676025" /></geometry><material name="color_left_elbow_pitch_link_sphere1_0"><color rgba="0.9 0.9 0.2 1.0" /></material></visual><collision><origin rpy="0 0 0" xyz="0 0 0" /><geometry><sphere radius="0.007698118686676025" /></geometry><drake:proximity_properties><drake:rigid_hydroelastic /><drake:mesh_resolution_hint value="1.5" /><drake:hunt_crossley_dissipation value="1.25" /></drake:proximity_properties></collision></link><joint name="left_elbow_pitch_link_to_left_elbow_pitch_link_sphere1" type="fixed"><parent link="left_elbow_pitch_link" /><child link="left_elbow_pitch_link_sphere1" /><origin xyz="-0.0043645016849040985 0.003824834479019046 0.029409950599074364" rpy="0 0 0" /></joint><link name="left_elbow_pitch_link_sphere2"><inertial><origin xyz="0 0 0" rpy="0 0 0" /><mass value="0.01" /><inertia ixx="0.001" ixy="0" ixz="0" iyy="0.001" iyz="0" izz="0.001" /></inertial><visual><origin rpy="0 0 0" xyz="0 0 0" /><geometry><sphere radius="0.008516798727214336" /></geometry><material name="color_left_elbow_pitch_link_sphere2_0"><color rgba="0.9 0.9 0.2 1.0" /></material></visual><collision><origin rpy="0 0 0" xyz="0 0 0" /><geometry><sphere radius="0.008516798727214336" /></geometry><drake:proximity_properties><drake:rigid_hydroelastic /><drake:mesh_resolution_hint value="1.5" /><drake:hunt_crossley_dissipation value="1.25" /></drake:proximity_properties></collision></link><joint name="left_elbow_pitch_link_to_left_elbow_pitch_link_sphere2" type="fixed"><parent link="left_elbow_pitch_link" /><child link="left_elbow_pitch_link_sphere2" /><origin xyz="-0.012175733223557472 0.004158966243267059 -0.025407567620277405" rpy="0 0 0" /></joint><link name="left_elbow_pitch_link_sphere3"><inertial><origin xyz="0 0 0" rpy="0 0 0" /><mass value="0.01" /><inertia ixx="0.001" ixy="0" ixz="0" iyy="0.001" iyz="0" izz="0.001" /></inertial><visual><origin rpy="0 0 0" xyz="0 0 0" /><geometry><sphere radius="0.02036837860941887" /></geometry><material name="color_left_elbow_pitch_link_sphere3_0"><color rgba="0.9 0.9 0.2 1.0" /></material></visual><collision><origin rpy="0 0 0" xyz="0 0 0" /><geometry><sphere radius="0.02036837860941887" /></geometry><drake:proximity_properties><drake:rigid_hydroelastic /><drake:mesh_resolution_hint value="1.5" /><drake:hunt_crossley_dissipation value="1.25" /></drake:proximity_properties></collision></link><joint name="left_elbow_pitch_link_to_left_elbow_pitch_link_sphere3" type="fixed"><parent link="left_elbow_pitch_link" /><child link="left_elbow_pitch_link_sphere3" /><origin xyz="0.0866299569606781 -0.02514098584651947 -0.011716009117662907" rpy="0 0 0" /></joint><link name="left_elbow_roll_link_sphere1"><inertial><origin xyz="0 0 0" rpy="0 0 0" /><mass value="0.01" /><inertia ixx="0.001" ixy="0" ixz="0" iyy="0.001" iyz="0" izz="0.001" /></inertial><visual><origin rpy="0 0 0" xyz="0 0 0" /><geometry><sphere radius="0.01545617263764143" /></geometry><material name="color_left_elbow_roll_link_sphere1_0"><color rgba="0.9 0.9 0.2 1.0" /></material></visual><collision><origin rpy="0 0 0" xyz="0 0 0" /><geometry><sphere radius="0.01545617263764143" /></geometry><drake:proximity_properties><drake:rigid_hydroelastic /><drake:mesh_resolution_hint value="1.5" /><drake:hunt_crossley_dissipation value="1.25" /></drake:proximity_properties></collision></link><joint name="left_elbow_roll_link_to_left_elbow_roll_link_sphere1" type="fixed"><parent link="left_elbow_roll_link" /><child link="left_elbow_roll_link_sphere1" /><origin xyz="0.017341280356049538 0.01886879652738571 0.018779031932353973" rpy="0 0 0" /></joint><link name="left_elbow_roll_link_sphere2"><inertial><origin xyz="0 0 0" rpy="0 0 0" /><mass value="0.01" /><inertia ixx="0.001" ixy="0" ixz="0" iyy="0.001" iyz="0" izz="0.001" /></inertial><visual><origin rpy="0 0 0" xyz="0 0 0" /><geometry><sphere radius="0.0141350869089365" /></geometry><material name="color_left_elbow_roll_link_sphere2_0"><color rgba="0.9 0.9 0.2 1.0" /></material></visual><collision><origin rpy="0 0 0" xyz="0 0 0" /><geometry><sphere radius="0.0141350869089365" /></geometry><drake:proximity_properties><drake:rigid_hydroelastic /><drake:mesh_resolution_hint value="1.5" /><drake:hunt_crossley_dissipation value="1.25" /></drake:proximity_properties></collision></link><joint name="left_elbow_roll_link_to_left_elbow_roll_link_sphere2" type="fixed"><parent link="left_elbow_roll_link" /><child link="left_elbow_roll_link_sphere2" /><origin xyz="0.023426279425621033 0.02030288428068161 -0.01995033770799637" rpy="0 0 0" /></joint><link name="left_elbow_roll_link_sphere3"><inertial><origin xyz="0 0 0" rpy="0 0 0" /><mass value="0.01" /><inertia ixx="0.001" ixy="0" ixz="0" iyy="0.001" iyz="0" izz="0.001" /></inertial><visual><origin rpy="0 0 0" xyz="0 0 0" /><geometry><sphere radius="0.025471709668636322" /></geometry><material name="color_left_elbow_roll_link_sphere3_0"><color rgba="0.9 0.9 0.2 1.0" /></material></visual><collision><origin rpy="0 0 0" xyz="0 0 0" /><geometry><sphere radius="0.025471709668636322" /></geometry><drake:proximity_properties><drake:rigid_hydroelastic /><drake:mesh_resolution_hint value="1.5" /><drake:hunt_crossley_dissipation value="1.25" /></drake:proximity_properties></collision></link><joint name="left_elbow_roll_link_to_left_elbow_roll_link_sphere3" type="fixed"><parent link="left_elbow_roll_link" /><child link="left_elbow_roll_link_sphere3" /><origin xyz="0.042150430381298065 -0.021441465243697166 8.865594281814992e-06" rpy="0 0 0" /></joint><link name="left_wrist_pitch_link_sphere1"><inertial><origin xyz="0 0 0" rpy="0 0 0" /><mass value="0.01" /><inertia ixx="0.001" ixy="0" ixz="0" iyy="0.001" iyz="0" izz="0.001" /></inertial><visual><origin rpy="0 0 0" xyz="0 0 0" /><geometry><sphere radius="0.011123963631689548" /></geometry><material name="color_left_wrist_pitch_link_sphere1_0"><color rgba="0.9 0.9 0.2 1.0" /></material></visual><collision><origin rpy="0 0 0" xyz="0 0 0" /><geometry><sphere radius="0.011123963631689548" /></geometry><drake:proximity_properties><drake:rigid_hydroelastic /><drake:mesh_resolution_hint value="1.5" /><drake:hunt_crossley_dissipation value="1.25" /></drake:proximity_properties></collision></link><joint name="left_wrist_pitch_link_to_left_wrist_pitch_link_sphere1" type="fixed"><parent link="left_wrist_pitch_link" /><child link="left_wrist_pitch_link_sphere1" /><origin xyz="0.035960469394922256 0.015254618600010872 -0.01567894220352173" rpy="0 0 0" /></joint><link name="left_wrist_pitch_link_sphere2"><inertial><origin xyz="0 0 0" rpy="0 0 0" /><mass value="0.01" /><inertia ixx="0.001" ixy="0" ixz="0" iyy="0.001" iyz="0" izz="0.001" /></inertial><visual><origin rpy="0 0 0" xyz="0 0 0" /><geometry><sphere radius="0.008248898200690746" /></geometry><material name="color_left_wrist_pitch_link_sphere2_0"><color rgba="0.9 0.9 0.2 1.0" /></material></visual><collision><origin rpy="0 0 0" xyz="0 0 0" /><geometry><sphere radius="0.008248898200690746" /></geometry><drake:proximity_properties><drake:rigid_hydroelastic /><drake:mesh_resolution_hint value="1.5" /><drake:hunt_crossley_dissipation value="1.25" /></drake:proximity_properties></collision></link><joint name="left_wrist_pitch_link_to_left_wrist_pitch_link_sphere2" type="fixed"><parent link="left_wrist_pitch_link" /><child link="left_wrist_pitch_link_sphere2" /><origin xyz="0.005382400471717119 0.02182190865278244 -0.01544537115842104" rpy="0 0 0" /></joint><link name="left_wrist_pitch_link_sphere3"><inertial><origin xyz="0 0 0" rpy="0 0 0" /><mass value="0.01" /><inertia ixx="0.001" ixy="0" ixz="0" iyy="0.001" iyz="0" izz="0.001" /></inertial><visual><origin rpy="0 0 0" xyz="0 0 0" /><geometry><sphere radius="0.03131774812936783" /></geometry><material name="color_left_wrist_pitch_link_sphere3_0"><color rgba="0.9 0.9 0.2 1.0" /></material></visual><collision><origin rpy="0 0 0" xyz="0 0 0" /><geometry><sphere radius="0.03131774812936783" /></geometry><drake:proximity_properties><drake:rigid_hydroelastic /><drake:mesh_resolution_hint value="1.5" /><drake:hunt_crossley_dissipation value="1.25" /></drake:proximity_properties></collision></link><joint name="left_wrist_pitch_link_to_left_wrist_pitch_link_sphere3" type="fixed"><parent link="left_wrist_pitch_link" /><child link="left_wrist_pitch_link_sphere3" /><origin xyz="0.020215831696987152 -0.0005128221237100661 0.0003939898160751909" rpy="0 0 0" /></joint><link name="left_wrist_pitch_link_sphere4"><inertial><origin xyz="0 0 0" rpy="0 0 0" /><mass value="0.01" /><inertia ixx="0.001" ixy="0" ixz="0" iyy="0.001" iyz="0" izz="0.001" /></inertial><visual><origin rpy="0 0 0" xyz="0 0 0" /><geometry><sphere radius="0.012095782905817032" /></geometry><material name="color_left_wrist_pitch_link_sphere4_0"><color rgba="0.9 0.9 0.2 1.0" /></material></visual><collision><origin rpy="0 0 0" xyz="0 0 0" /><geometry><sphere radius="0.012095782905817032" /></geometry><drake:proximity_properties><drake:rigid_hydroelastic /><drake:mesh_resolution_hint value="1.5" /><drake:hunt_crossley_dissipation value="1.25" /></drake:proximity_properties></collision></link><joint name="left_wrist_pitch_link_to_left_wrist_pitch_link_sphere4" type="fixed"><parent link="left_wrist_pitch_link" /><child link="left_wrist_pitch_link_sphere4" /><origin xyz="0.0049871038645505905 0.01658765599131584 0.019302451983094215" rpy="0 0 0" /></joint><link name="left_wrist_yaw_link_sphere1"><inertial><origin xyz="0 0 0" rpy="0 0 0" /><mass value="0.01" /><inertia ixx="0.001" ixy="0" ixz="0" iyy="0.001" iyz="0" izz="0.001" /></inertial><visual><origin rpy="0 0 0" xyz="0 0 0" /><geometry><sphere radius="0.011606113985180855" /></geometry><material name="color_left_wrist_yaw_link_sphere1_0"><color rgba="0.9 0.9 0.2 1.0" /></material></visual><collision><origin rpy="0 0 0" xyz="0 0 0" /><geometry><sphere radius="0.011606113985180855" /></geometry><drake:proximity_properties><drake:rigid_hydroelastic /><drake:mesh_resolution_hint value="1.5" /><drake:hunt_crossley_dissipation value="1.25" /></drake:proximity_properties></collision></link><joint name="left_wrist_yaw_link_to_left_wrist_yaw_link_sphere1" type="fixed"><parent link="left_wrist_yaw_link" /><child link="left_wrist_yaw_link_sphere1" /><origin xyz="-0.0013128016144037247 0.0003213058807887137 0.037185974419116974" rpy="0 0 0" /></joint><link name="left_wrist_yaw_link_sphere2"><inertial><origin xyz="0 0 0" rpy="0 0 0" /><mass value="0.01" /><inertia ixx="0.001" ixy="0" ixz="0" iyy="0.001" iyz="0" izz="0.001" /></inertial><visual><origin rpy="0 0 0" xyz="0 0 0" /><geometry><sphere radius="0.01397098507732153" /></geometry><material name="color_left_wrist_yaw_link_sphere2_0"><color rgba="0.9 0.9 0.2 1.0" /></material></visual><collision><origin rpy="0 0 0" xyz="0 0 0" /><geometry><sphere radius="0.01397098507732153" /></geometry><drake:proximity_properties><drake:rigid_hydroelastic /><drake:mesh_resolution_hint value="1.5" /><drake:hunt_crossley_dissipation value="1.25" /></drake:proximity_properties></collision></link><joint name="left_wrist_yaw_link_to_left_wrist_yaw_link_sphere2" type="fixed"><parent link="left_wrist_yaw_link" /><child link="left_wrist_yaw_link_sphere2" /><origin xyz="0.0005446894792839885 5.7640718296170235e-06 -0.03719298914074898" rpy="0 0 0" /></joint><link name="left_wrist_yaw_link_sphere3"><inertial><origin xyz="0 0 0" rpy="0 0 0" /><mass value="0.01" /><inertia ixx="0.001" ixy="0" ixz="0" iyy="0.001" iyz="0" izz="0.001" /></inertial><visual><origin rpy="0 0 0" xyz="0 0 0" /><geometry><sphere radius="0.017137723043560982" /></geometry><material name="color_left_wrist_yaw_link_sphere3_0"><color rgba="0.9 0.9 0.2 1.0" /></material></visual><collision><origin rpy="0 0 0" xyz="0 0 0" /><geometry><sphere radius="0.017137723043560982" /></geometry><drake:proximity_properties><drake:rigid_hydroelastic /><drake:mesh_resolution_hint value="1.5" /><drake:hunt_crossley_dissipation value="1.25" /></drake:proximity_properties></collision></link><joint name="left_wrist_yaw_link_to_left_wrist_yaw_link_sphere3" type="fixed"><parent link="left_wrist_yaw_link" /><child link="left_wrist_yaw_link_sphere3" /><origin xyz="0.04339425265789032 -0.00029951459146104753 -0.024706179276108742" rpy="0 0 0" /></joint><link name="left_wrist_yaw_link_sphere4"><inertial><origin xyz="0 0 0" rpy="0 0 0" /><mass value="0.01" /><inertia ixx="0.001" ixy="0" ixz="0" iyy="0.001" iyz="0" izz="0.001" /></inertial><visual><origin rpy="0 0 0" xyz="0 0 0" /><geometry><sphere radius="0.01727457530796528" /></geometry><material name="color_left_wrist_yaw_link_sphere4_0"><color rgba="0.9 0.9 0.2 1.0" /></material></visual><collision><origin rpy="0 0 0" xyz="0 0 0" /><geometry><sphere radius="0.01727457530796528" /></geometry><drake:proximity_properties><drake:rigid_hydroelastic /><drake:mesh_resolution_hint value="1.5" /><drake:hunt_crossley_dissipation value="1.25" /></drake:proximity_properties></collision></link><joint name="left_wrist_yaw_link_to_left_wrist_yaw_link_sphere4" type="fixed"><parent link="left_wrist_yaw_link" /><child link="left_wrist_yaw_link_sphere4" /><origin xyz="0.04322057589888573 0.0003908132784999907 0.02535353973507881" rpy="0 0 0" /></joint><link name="right_shoulder_pitch_link_sphere1"><inertial><origin xyz="0 0 0" rpy="0 0 0" /><mass value="0.01" /><inertia ixx="0.001" ixy="0" ixz="0" iyy="0.001" iyz="0" izz="0.001" /></inertial><visual><origin rpy="0 0 0" xyz="0 0 0" /><geometry><sphere radius="0.017486121505498886" /></geometry><material name="color_right_shoulder_pitch_link_sphere1_0"><color rgba="0.9 0.2 0.9 1.0" /></material></visual><collision><origin rpy="0 0 0" xyz="0 0 0" /><geometry><sphere radius="0.017486121505498886" /></geometry><drake:proximity_properties><drake:rigid_hydroelastic /><drake:mesh_resolution_hint value="1.5" /><drake:hunt_crossley_dissipation value="1.25" /></drake:proximity_properties></collision></link><joint name="right_shoulder_pitch_link_to_right_shoulder_pitch_link_sphere1" type="fixed"><parent link="right_shoulder_pitch_link" /><child link="right_shoulder_pitch_link_sphere1" /><origin xyz="-0.0048226248472929 -0.09123209863901138 0.009087561629712582" rpy="0 0 0" /></joint><link name="right_shoulder_pitch_link_sphere2"><inertial><origin xyz="0 0 0" rpy="0 0 0" /><mass value="0.01" /><inertia ixx="0.001" ixy="0" ixz="0" iyy="0.001" iyz="0" izz="0.001" /></inertial><visual><origin rpy="0 0 0" xyz="0 0 0" /><geometry><sphere radius="0.013973357155919075" /></geometry><material name="color_right_shoulder_pitch_link_sphere2_0"><color rgba="0.9 0.2 0.9 1.0" /></material></visual><collision><origin rpy="0 0 0" xyz="0 0 0" /><geometry><sphere radius="0.013973357155919075" /></geometry><drake:proximity_properties><drake:rigid_hydroelastic /><drake:mesh_resolution_hint value="1.5" /><drake:hunt_crossley_dissipation value="1.25" /></drake:proximity_properties></collision></link><joint name="right_shoulder_pitch_link_to_right_shoulder_pitch_link_sphere2" type="fixed"><parent link="right_shoulder_pitch_link" /><child link="right_shoulder_pitch_link_sphere2" /><origin xyz="-0.019152365624904633 -0.06020510196685791 -0.040170859545469284" rpy="0 0 0" /></joint><link name="right_shoulder_pitch_link_sphere3"><inertial><origin xyz="0 0 0" rpy="0 0 0" /><mass value="0.01" /><inertia ixx="0.001" ixy="0" ixz="0" iyy="0.001" iyz="0" izz="0.001" /></inertial><visual><origin rpy="0 0 0" xyz="0 0 0" /><geometry><sphere radius="0.010455785319209099" /></geometry><material name="color_right_shoulder_pitch_link_sphere3_0"><color rgba="0.9 0.2 0.9 1.0" /></material></visual><collision><origin rpy="0 0 0" xyz="0 0 0" /><geometry><sphere radius="0.010455785319209099" /></geometry><drake:proximity_properties><drake:rigid_hydroelastic /><drake:mesh_resolution_hint value="1.5" /><drake:hunt_crossley_dissipation value="1.25" /></drake:proximity_properties></collision></link><joint name="right_shoulder_pitch_link_to_right_shoulder_pitch_link_sphere3" type="fixed"><parent link="right_shoulder_pitch_link" /><child link="right_shoulder_pitch_link_sphere3" /><origin xyz="-0.028237339109182358 -0.04533207789063454 0.025993971154093742" rpy="0 0 0" /></joint><link name="right_shoulder_roll_link_sphere1"><inertial><origin xyz="0 0 0" rpy="0 0 0" /><mass value="0.01" /><inertia ixx="0.001" ixy="0" ixz="0" iyy="0.001" iyz="0" izz="0.001" /></inertial><visual><origin rpy="0 0 0" xyz="0 0 0" /><geometry><sphere radius="0.013487252406775951" /></geometry><material name="color_right_shoulder_roll_link_sphere1_0"><color rgba="0.9 0.2 0.9 1.0" /></material></visual><collision><origin rpy="0 0 0" xyz="0 0 0" /><geometry><sphere radius="0.013487252406775951" /></geometry><drake:proximity_properties><drake:rigid_hydroelastic /><drake:mesh_resolution_hint value="1.5" /><drake:hunt_crossley_dissipation value="1.25" /></drake:proximity_properties></collision></link><joint name="right_shoulder_roll_link_to_right_shoulder_roll_link_sphere1" type="fixed"><parent link="right_shoulder_roll_link" /><child link="right_shoulder_roll_link_sphere1" /><origin xyz="0.0011063750134781003 0.012165486812591553 -0.10041197389364243" rpy="0 0 0" /></joint><link name="right_shoulder_roll_link_sphere2"><inertial><origin xyz="0 0 0" rpy="0 0 0" /><mass value="0.01" /><inertia ixx="0.001" ixy="0" ixz="0" iyy="0.001" iyz="0" izz="0.001" /></inertial><visual><origin rpy="0 0 0" xyz="0 0 0" /><geometry><sphere radius="0.015526237897574902" /></geometry><material name="color_right_shoulder_roll_link_sphere2_0"><color rgba="0.9 0.2 0.9 1.0" /></material></visual><collision><origin rpy="0 0 0" xyz="0 0 0" /><geometry><sphere radius="0.015526237897574902" /></geometry><drake:proximity_properties><drake:rigid_hydroelastic /><drake:mesh_resolution_hint value="1.5" /><drake:hunt_crossley_dissipation value="1.25" /></drake:proximity_properties></collision></link><joint name="right_shoulder_roll_link_to_right_shoulder_roll_link_sphere2" type="fixed"><parent link="right_shoulder_roll_link" /><child link="right_shoulder_roll_link_sphere2" /><origin xyz="-0.029984453693032265 -0.035398561507463455 -0.10458216816186905" rpy="0 0 0" /></joint><link name="right_shoulder_roll_link_sphere3"><inertial><origin xyz="0 0 0" rpy="0 0 0" /><mass value="0.01" /><inertia ixx="0.001" ixy="0" ixz="0" iyy="0.001" iyz="0" izz="0.001" /></inertial><visual><origin rpy="0 0 0" xyz="0 0 0" /><geometry><sphere radius="0.017211416736245155" /></geometry><material name="color_right_shoulder_roll_link_sphere3_0"><color rgba="0.9 0.2 0.9 1.0" /></material></visual><collision><origin rpy="0 0 0" xyz="0 0 0" /><geometry><sphere radius="0.017211416736245155" /></geometry><drake:proximity_properties><drake:rigid_hydroelastic /><drake:mesh_resolution_hint value="1.5" /><drake:hunt_crossley_dissipation value="1.25" /></drake:proximity_properties></collision></link><joint name="right_shoulder_roll_link_to_right_shoulder_roll_link_sphere3" type="fixed"><parent link="right_shoulder_roll_link" /><child link="right_shoulder_roll_link_sphere3" /><origin xyz="-0.05964508280158043 0.02146228216588497 -0.10775172710418701" rpy="0 0 0" /></joint><link name="right_shoulder_yaw_link_sphere1"><inertial><origin xyz="0 0 0" rpy="0 0 0" /><mass value="0.01" /><inertia ixx="0.001" ixy="0" ixz="0" iyy="0.001" iyz="0" izz="0.001" /></inertial><visual><origin rpy="0 0 0" xyz="0 0 0" /><geometry><sphere radius="0.012341132387518883" /></geometry><material name="color_right_shoulder_yaw_link_sphere1_0"><color rgba="0.9 0.2 0.9 1.0" /></material></visual><collision><origin rpy="0 0 0" xyz="0 0 0" /><geometry><sphere radius="0.012341132387518883" /></geometry><drake:proximity_properties><drake:rigid_hydroelastic /><drake:mesh_resolution_hint value="1.5" /><drake:hunt_crossley_dissipation value="1.25" /></drake:proximity_properties></collision></link><joint name="right_shoulder_yaw_link_to_right_shoulder_yaw_link_sphere1" type="fixed"><parent link="right_shoulder_yaw_link" /><child link="right_shoulder_yaw_link_sphere1" /><origin xyz="-0.03145815059542656 0.012809265404939651 -0.17036280035972595" rpy="0 0 0" /></joint><link name="right_elbow_pitch_link_sphere1"><inertial><origin xyz="0 0 0" rpy="0 0 0" /><mass value="0.01" /><inertia ixx="0.001" ixy="0" ixz="0" iyy="0.001" iyz="0" izz="0.001" /></inertial><visual><origin rpy="0 0 0" xyz="0 0 0" /><geometry><sphere radius="0.007495453115552664" /></geometry><material name="color_right_elbow_pitch_link_sphere1_0"><color rgba="0.9 0.2 0.9 1.0" /></material></visual><collision><origin rpy="0 0 0" xyz="0 0 0" /><geometry><sphere radius="0.007495453115552664" /></geometry><drake:proximity_properties><drake:rigid_hydroelastic /><drake:mesh_resolution_hint value="1.5" /><drake:hunt_crossley_dissipation value="1.25" /></drake:proximity_properties></collision></link><joint name="right_elbow_pitch_link_to_right_elbow_pitch_link_sphere1" type="fixed"><parent link="right_elbow_pitch_link" /><child link="right_elbow_pitch_link_sphere1" /><origin xyz="0.03831541910767555 -0.003366833785548806 -0.015228118747472763" rpy="0 0 0" /></joint><link name="right_elbow_pitch_link_sphere2"><inertial><origin xyz="0 0 0" rpy="0 0 0" /><mass value="0.01" /><inertia ixx="0.001" ixy="0" ixz="0" iyy="0.001" iyz="0" izz="0.001" /></inertial><visual><origin rpy="0 0 0" xyz="0 0 0" /><geometry><sphere radius="0.021338334307074547" /></geometry><material name="color_right_elbow_pitch_link_sphere2_0"><color rgba="0.9 0.2 0.9 1.0" /></material></visual><collision><origin rpy="0 0 0" xyz="0 0 0" /><geometry><sphere radius="0.021338334307074547" /></geometry><drake:proximity_properties><drake:rigid_hydroelastic /><drake:mesh_resolution_hint value="1.5" /><drake:hunt_crossley_dissipation value="1.25" /></drake:proximity_properties></collision></link><joint name="right_elbow_pitch_link_to_right_elbow_pitch_link_sphere2" type="fixed"><parent link="right_elbow_pitch_link" /><child link="right_elbow_pitch_link_sphere2" /><origin xyz="0.08621324598789215 0.03350076079368591 -0.009892851114273071" rpy="0 0 0" /></joint><link name="right_elbow_roll_link_sphere1"><inertial><origin xyz="0 0 0" rpy="0 0 0" /><mass value="0.01" /><inertia ixx="0.001" ixy="0" ixz="0" iyy="0.001" iyz="0" izz="0.001" /></inertial><visual><origin rpy="0 0 0" xyz="0 0 0" /><geometry><sphere radius="0.02461102046072483" /></geometry><material name="color_right_elbow_roll_link_sphere1_0"><color rgba="0.9 0.2 0.9 1.0" /></material></visual><collision><origin rpy="0 0 0" xyz="0 0 0" /><geometry><sphere radius="0.02461102046072483" /></geometry><drake:proximity_properties><drake:rigid_hydroelastic /><drake:mesh_resolution_hint value="1.5" /><drake:hunt_crossley_dissipation value="1.25" /></drake:proximity_properties></collision></link><joint name="right_elbow_roll_link_to_right_elbow_roll_link_sphere1" type="fixed"><parent link="right_elbow_roll_link" /><child link="right_elbow_roll_link_sphere1" /><origin xyz="0.04294821247458458 0.020522382110357285 0.0002610346709843725" rpy="0 0 0" /></joint><link name="right_elbow_roll_link_sphere2"><inertial><origin xyz="0 0 0" rpy="0 0 0" /><mass value="0.01" /><inertia ixx="0.001" ixy="0" ixz="0" iyy="0.001" iyz="0" izz="0.001" /></inertial><visual><origin rpy="0 0 0" xyz="0 0 0" /><geometry><sphere radius="0.014757996425032616" /></geometry><material name="color_right_elbow_roll_link_sphere2_0"><color rgba="0.9 0.2 0.9 1.0" /></material></visual><collision><origin rpy="0 0 0" xyz="0 0 0" /><geometry><sphere radius="0.014757996425032616" /></geometry><drake:proximity_properties><drake:rigid_hydroelastic /><drake:mesh_resolution_hint value="1.5" /><drake:hunt_crossley_dissipation value="1.25" /></drake:proximity_properties></collision></link><joint name="right_elbow_roll_link_to_right_elbow_roll_link_sphere2" type="fixed"><parent link="right_elbow_roll_link" /><child link="right_elbow_roll_link_sphere2" /><origin xyz="0.02356361411511898 -0.02090843953192234 0.021996434777975082" rpy="0 0 0" /></joint><link name="right_elbow_roll_link_sphere3"><inertial><origin xyz="0 0 0" rpy="0 0 0" /><mass value="0.01" /><inertia ixx="0.001" ixy="0" ixz="0" iyy="0.001" iyz="0" izz="0.001" /></inertial><visual><origin rpy="0 0 0" xyz="0 0 0" /><geometry><sphere radius="0.01579013094305992" /></geometry><material name="color_right_elbow_roll_link_sphere3_0"><color rgba="0.9 0.2 0.9 1.0" /></material></visual><collision><origin rpy="0 0 0" xyz="0 0 0" /><geometry><sphere radius="0.01579013094305992" /></geometry><drake:proximity_properties><drake:rigid_hydroelastic /><drake:mesh_resolution_hint value="1.5" /><drake:hunt_crossley_dissipation value="1.25" /></drake:proximity_properties></collision></link><joint name="right_elbow_roll_link_to_right_elbow_roll_link_sphere3" type="fixed"><parent link="right_elbow_roll_link" /><child link="right_elbow_roll_link_sphere3" /><origin xyz="0.019527144730091095 -0.018915880471467972 -0.019627681002020836" rpy="0 0 0" /></joint><link name="right_wrist_pitch_link_sphere1"><inertial><origin xyz="0 0 0" rpy="0 0 0" /><mass value="0.01" /><inertia ixx="0.001" ixy="0" ixz="0" iyy="0.001" iyz="0" izz="0.001" /></inertial><visual><origin rpy="0 0 0" xyz="0 0 0" /><geometry><sphere radius="0.008731285110116005" /></geometry><material name="color_right_wrist_pitch_link_sphere1_0"><color rgba="0.9 0.2 0.9 1.0" /></material></visual><collision><origin rpy="0 0 0" xyz="0 0 0" /><geometry><sphere radius="0.008731285110116005" /></geometry><drake:proximity_properties><drake:rigid_hydroelastic /><drake:mesh_resolution_hint value="1.5" /><drake:hunt_crossley_dissipation value="1.25" /></drake:proximity_properties></collision></link><joint name="right_wrist_pitch_link_to_right_wrist_pitch_link_sphere1" type="fixed"><parent link="right_wrist_pitch_link" /><child link="right_wrist_pitch_link_sphere1" /><origin xyz="0.0052133649587631226 -0.02116597816348076 -0.015395905822515488" rpy="0 0 0" /></joint><link name="right_wrist_pitch_link_sphere2"><inertial><origin xyz="0 0 0" rpy="0 0 0" /><mass value="0.01" /><inertia ixx="0.001" ixy="0" ixz="0" iyy="0.001" iyz="0" izz="0.001" /></inertial><visual><origin rpy="0 0 0" xyz="0 0 0" /><geometry><sphere radius="0.013825408183038235" /></geometry><material name="color_right_wrist_pitch_link_sphere2_0"><color rgba="0.9 0.2 0.9 1.0" /></material></visual><collision><origin rpy="0 0 0" xyz="0 0 0" /><geometry><sphere radius="0.013825408183038235" /></geometry><drake:proximity_properties><drake:rigid_hydroelastic /><drake:mesh_resolution_hint value="1.5" /><drake:hunt_crossley_dissipation value="1.25" /></drake:proximity_properties></collision></link><joint name="right_wrist_pitch_link_to_right_wrist_pitch_link_sphere2" type="fixed"><parent link="right_wrist_pitch_link" /><child link="right_wrist_pitch_link_sphere2" /><origin xyz="0.03648427501320839 0.010796661488711834 -0.015391373075544834" rpy="0 0 0" /></joint><link name="right_wrist_pitch_link_sphere3"><inertial><origin xyz="0 0 0" rpy="0 0 0" /><mass value="0.01" /><inertia ixx="0.001" ixy="0" ixz="0" iyy="0.001" iyz="0" izz="0.001" /></inertial><visual><origin rpy="0 0 0" xyz="0 0 0" /><geometry><sphere radius="0.011647481471300125" /></geometry><material name="color_right_wrist_pitch_link_sphere3_0"><color rgba="0.9 0.2 0.9 1.0" /></material></visual><collision><origin rpy="0 0 0" xyz="0 0 0" /><geometry><sphere radius="0.011647481471300125" /></geometry><drake:proximity_properties><drake:rigid_hydroelastic /><drake:mesh_resolution_hint value="1.5" /><drake:hunt_crossley_dissipation value="1.25" /></drake:proximity_properties></collision></link><joint name="right_wrist_pitch_link_to_right_wrist_pitch_link_sphere3" type="fixed"><parent link="right_wrist_pitch_link" /><child link="right_wrist_pitch_link_sphere3" /><origin xyz="0.01397884450852871 0.02060858905315399 -0.01589229516685009" rpy="0 0 0" /></joint><link name="right_wrist_pitch_link_sphere4"><inertial><origin xyz="0 0 0" rpy="0 0 0" /><mass value="0.01" /><inertia ixx="0.001" ixy="0" ixz="0" iyy="0.001" iyz="0" izz="0.001" /></inertial><visual><origin rpy="0 0 0" xyz="0 0 0" /><geometry><sphere radius="0.03137034922838211" /></geometry><material name="color_right_wrist_pitch_link_sphere4_0"><color rgba="0.9 0.2 0.9 1.0" /></material></visual><collision><origin rpy="0 0 0" xyz="0 0 0" /><geometry><sphere radius="0.03137034922838211" /></geometry><drake:proximity_properties><drake:rigid_hydroelastic /><drake:mesh_resolution_hint value="1.5" /><drake:hunt_crossley_dissipation value="1.25" /></drake:proximity_properties></collision></link><joint name="right_wrist_pitch_link_to_right_wrist_pitch_link_sphere4" type="fixed"><parent link="right_wrist_pitch_link" /><child link="right_wrist_pitch_link_sphere4" /><origin xyz="0.019597020000219345 -0.00032618106342852116 0.0011628423817455769" rpy="0 0 0" /></joint><link name="right_wrist_yaw_link_sphere1"><inertial><origin xyz="0 0 0" rpy="0 0 0" /><mass value="0.01" /><inertia ixx="0.001" ixy="0" ixz="0" iyy="0.001" iyz="0" izz="0.001" /></inertial><visual><origin rpy="0 0 0" xyz="0 0 0" /><geometry><sphere radius="0.011606113985180855" /></geometry><material name="color_right_wrist_yaw_link_sphere1_0"><color rgba="0.9 0.2 0.9 1.0" /></material></visual><collision><origin rpy="0 0 0" xyz="0 0 0" /><geometry><sphere radius="0.011606113985180855" /></geometry><drake:proximity_properties><drake:rigid_hydroelastic /><drake:mesh_resolution_hint value="1.5" /><drake:hunt_crossley_dissipation value="1.25" /></drake:proximity_properties></collision></link><joint name="right_wrist_yaw_link_to_right_wrist_yaw_link_sphere1" type="fixed"><parent link="right_wrist_yaw_link" /><child link="right_wrist_yaw_link_sphere1" /><origin xyz="-0.0013128016144037247 0.0003213058807887137 0.037185974419116974" rpy="0 0 0" /></joint><link name="right_wrist_yaw_link_sphere2"><inertial><origin xyz="0 0 0" rpy="0 0 0" /><mass value="0.01" /><inertia ixx="0.001" ixy="0" ixz="0" iyy="0.001" iyz="0" izz="0.001" /></inertial><visual><origin rpy="0 0 0" xyz="0 0 0" /><geometry><sphere radius="0.01397098507732153" /></geometry><material name="color_right_wrist_yaw_link_sphere2_0"><color rgba="0.9 0.2 0.9 1.0" /></material></visual><collision><origin rpy="0 0 0" xyz="0 0 0" /><geometry><sphere radius="0.01397098507732153" /></geometry><drake:proximity_properties><drake:rigid_hydroelastic /><drake:mesh_resolution_hint value="1.5" /><drake:hunt_crossley_dissipation value="1.25" /></drake:proximity_properties></collision></link><joint name="right_wrist_yaw_link_to_right_wrist_yaw_link_sphere2" type="fixed"><parent link="right_wrist_yaw_link" /><child link="right_wrist_yaw_link_sphere2" /><origin xyz="0.0005446894792839885 5.7640718296170235e-06 -0.03719298914074898" rpy="0 0 0" /></joint><link name="right_wrist_yaw_link_sphere3"><inertial><origin xyz="0 0 0" rpy="0 0 0" /><mass value="0.01" /><inertia ixx="0.001" ixy="0" ixz="0" iyy="0.001" iyz="0" izz="0.001" /></inertial><visual><origin rpy="0 0 0" xyz="0 0 0" /><geometry><sphere radius="0.017137723043560982" /></geometry><material name="color_right_wrist_yaw_link_sphere3_0"><color rgba="0.9 0.2 0.9 1.0" /></material></visual><collision><origin rpy="0 0 0" xyz="0 0 0" /><geometry><sphere radius="0.017137723043560982" /></geometry><drake:proximity_properties><drake:rigid_hydroelastic /><drake:mesh_resolution_hint value="1.5" /><drake:hunt_crossley_dissipation value="1.25" /></drake:proximity_properties></collision></link><joint name="right_wrist_yaw_link_to_right_wrist_yaw_link_sphere3" type="fixed"><parent link="right_wrist_yaw_link" /><child link="right_wrist_yaw_link_sphere3" /><origin xyz="0.04339425265789032 -0.00029951459146104753 -0.024706179276108742" rpy="0 0 0" /></joint><link name="right_wrist_yaw_link_sphere4"><inertial><origin xyz="0 0 0" rpy="0 0 0" /><mass value="0.01" /><inertia ixx="0.001" ixy="0" ixz="0" iyy="0.001" iyz="0" izz="0.001" /></inertial><visual><origin rpy="0 0 0" xyz="0 0 0" /><geometry><sphere radius="0.01727457530796528" /></geometry><material name="color_right_wrist_yaw_link_sphere4_0"><color rgba="0.9 0.2 0.9 1.0" /></material></visual><collision><origin rpy="0 0 0" xyz="0 0 0" /><geometry><sphere radius="0.01727457530796528" /></geometry><drake:proximity_properties><drake:rigid_hydroelastic /><drake:mesh_resolution_hint value="1.5" /><drake:hunt_crossley_dissipation value="1.25" /></drake:proximity_properties></collision></link><joint name="right_wrist_yaw_link_to_right_wrist_yaw_link_sphere4" type="fixed"><parent link="right_wrist_yaw_link" /><child link="right_wrist_yaw_link_sphere4" /><origin xyz="0.04322057589888573 0.0003908132784999907 0.02535353973507881" rpy="0 0 0" /></joint><link name="L_thumb_proximal_base_sphere1"><inertial><origin xyz="0 0 0" rpy="0 0 0" /><mass value="0.01" /><inertia ixx="0.001" ixy="0" ixz="0" iyy="0.001" iyz="0" izz="0.001" /></inertial><visual><origin rpy="0 0 0" xyz="0 0 0" /><geometry><sphere radius="0.005536554381251335" /></geometry><material name="color_L_thumb_proximal_base_sphere1_0"><color rgba="0.5 0.8 0.8 1.0" /></material></visual><collision><origin rpy="0 0 0" xyz="0 0 0" /><geometry><sphere radius="0.005536554381251335" /></geometry><drake:proximity_properties><drake:rigid_hydroelastic /><drake:mesh_resolution_hint value="1.5" /><drake:hunt_crossley_dissipation value="1.25" /></drake:proximity_properties></collision></link><joint name="L_thumb_proximal_base_to_L_thumb_proximal_base_sphere1" type="fixed"><parent link="L_thumb_proximal_base" /><child link="L_thumb_proximal_base_sphere1" /><origin xyz="0.00868700910359621 0.0011472656624391675 -0.009194154292345047" rpy="0 0 0" /></joint><link name="L_thumb_proximal_base_sphere2"><inertial><origin xyz="0 0 0" rpy="0 0 0" /><mass value="0.01" /><inertia ixx="0.001" ixy="0" ixz="0" iyy="0.001" iyz="0" izz="0.001" /></inertial><visual><origin rpy="0 0 0" xyz="0 0 0" /><geometry><sphere radius="0.0032418412156403065" /></geometry><material name="color_L_thumb_proximal_base_sphere2_0"><color rgba="0.5 0.8 0.8 1.0" /></material></visual><collision><origin rpy="0 0 0" xyz="0 0 0" /><geometry><sphere radius="0.0032418412156403065" /></geometry><drake:proximity_properties><drake:rigid_hydroelastic /><drake:mesh_resolution_hint value="1.5" /><drake:hunt_crossley_dissipation value="1.25" /></drake:proximity_properties></collision></link><joint name="L_thumb_proximal_base_to_L_thumb_proximal_base_sphere2" type="fixed"><parent link="L_thumb_proximal_base" /><child link="L_thumb_proximal_base_sphere2" /><origin xyz="0.002021251944825053 0.003111585509032011 -0.011536791920661926" rpy="0 0 0" /></joint><link name="L_thumb_intermediate_sphere1"><inertial><origin xyz="0 0 0" rpy="0 0 0" /><mass value="0.01" /><inertia ixx="0.001" ixy="0" ixz="0" iyy="0.001" iyz="0" izz="0.001" /></inertial><visual><origin rpy="0 0 0" xyz="0 0 0" /><geometry><sphere radius="0.006004171911627054" /></geometry><material name="color_L_thumb_intermediate_sphere1_0"><color rgba="0.5 0.8 0.8 1.0" /></material></visual><collision><origin rpy="0 0 0" xyz="0 0 0" /><geometry><sphere radius="0.006004171911627054" /></geometry><drake:proximity_properties><drake:rigid_hydroelastic /><drake:mesh_resolution_hint value="1.5" /><drake:hunt_crossley_dissipation value="1.25" /></drake:proximity_properties></collision></link><joint name="L_thumb_intermediate_to_L_thumb_intermediate_sphere1" type="fixed"><parent link="L_thumb_intermediate" /><child link="L_thumb_intermediate_sphere1" /><origin xyz="0.003817496122792363 0.009946647100150585 -0.013364381156861782" rpy="0 0 0" /></joint><link name="L_thumb_intermediate_sphere2"><inertial><origin xyz="0 0 0" rpy="0 0 0" /><mass value="0.01" /><inertia ixx="0.001" ixy="0" ixz="0" iyy="0.001" iyz="0" izz="0.001" /></inertial><visual><origin rpy="0 0 0" xyz="0 0 0" /><geometry><sphere radius="0.005767274182289839" /></geometry><material name="color_L_thumb_intermediate_sphere2_0"><color rgba="0.5 0.8 0.8 1.0" /></material></visual><collision><origin rpy="0 0 0" xyz="0 0 0" /><geometry><sphere radius="0.005767274182289839" /></geometry><drake:proximity_properties><drake:rigid_hydroelastic /><drake:mesh_resolution_hint value="1.5" /><drake:hunt_crossley_dissipation value="1.25" /></drake:proximity_properties></collision></link><joint name="L_thumb_intermediate_to_L_thumb_intermediate_sphere2" type="fixed"><parent link="L_thumb_intermediate" /><child link="L_thumb_intermediate_sphere2" /><origin xyz="0.003709179814904928 0.01038711704313755 -0.0009459920111112297" rpy="0 0 0" /></joint><link name="L_thumb_distal_sphere1"><inertial><origin xyz="0 0 0" rpy="0 0 0" /><mass value="0.01" /><inertia ixx="0.001" ixy="0" ixz="0" iyy="0.001" iyz="0" izz="0.001" /></inertial><visual><origin rpy="0 0 0" xyz="0 0 0" /><geometry><sphere radius="0.007767129223793745" /></geometry><material name="color_L_thumb_distal_sphere1_0"><color rgba="0.5 0.8 0.8 1.0" /></material></visual><collision><origin rpy="0 0 0" xyz="0 0 0" /><geometry><sphere radius="0.007767129223793745" /></geometry><drake:proximity_properties><drake:rigid_hydroelastic /><drake:mesh_resolution_hint value="1.5" /><drake:hunt_crossley_dissipation value="1.25" /></drake:proximity_properties></collision></link><joint name="L_thumb_distal_to_L_thumb_distal_sphere1" type="fixed"><parent link="L_thumb_distal" /><child link="L_thumb_distal_sphere1" /><origin xyz="0.008056570775806904 -0.004023006651550531 -0.006005910225212574" rpy="0 0 0" /></joint><link name="L_thumb_distal_sphere2"><inertial><origin xyz="0 0 0" rpy="0 0 0" /><mass value="0.01" /><inertia ixx="0.001" ixy="0" ixz="0" iyy="0.001" iyz="0" izz="0.001" /></inertial><visual><origin rpy="0 0 0" xyz="0 0 0" /><geometry><sphere radius="0.005824663210660219" /></geometry><material name="color_L_thumb_distal_sphere2_0"><color rgba="0.5 0.8 0.8 1.0" /></material></visual><collision><origin rpy="0 0 0" xyz="0 0 0" /><geometry><sphere radius="0.005824663210660219" /></geometry><drake:proximity_properties><drake:rigid_hydroelastic /><drake:mesh_resolution_hint value="1.5" /><drake:hunt_crossley_dissipation value="1.25" /></drake:proximity_properties></collision></link><joint name="L_thumb_distal_to_L_thumb_distal_sphere2" type="fixed"><parent link="L_thumb_distal" /><child link="L_thumb_distal_sphere2" /><origin xyz="0.01580023765563965 -0.010396790690720081 -0.005743388552218676" rpy="0 0 0" /></joint><link name="L_index_intermediate_sphere1"><inertial><origin xyz="0 0 0" rpy="0 0 0" /><mass value="0.01" /><inertia ixx="0.001" ixy="0" ixz="0" iyy="0.001" iyz="0" izz="0.001" /></inertial><visual><origin rpy="0 0 0" xyz="0 0 0" /><geometry><sphere radius="0.007075049914419651" /></geometry><material name="color_L_index_intermediate_sphere1_0"><color rgba="0.5 0.8 0.8 1.0" /></material></visual><collision><origin rpy="0 0 0" xyz="0 0 0" /><geometry><sphere radius="0.007075049914419651" /></geometry><drake:proximity_properties><drake:rigid_hydroelastic /><drake:mesh_resolution_hint value="1.5" /><drake:hunt_crossley_dissipation value="1.25" /></drake:proximity_properties></collision></link><joint name="L_index_intermediate_to_L_index_intermediate_sphere1" type="fixed"><parent link="L_index_intermediate" /><child link="L_index_intermediate_sphere1" /><origin xyz="-0.000541757675819099 -0.03471282497048378 -0.005217236466705799" rpy="0 0 0" /></joint><link name="L_index_intermediate_sphere2"><inertial><origin xyz="0 0 0" rpy="0 0 0" /><mass value="0.01" /><inertia ixx="0.001" ixy="0" ixz="0" iyy="0.001" iyz="0" izz="0.001" /></inertial><visual><origin rpy="0 0 0" xyz="0 0 0" /><geometry><sphere radius="0.007323485799133778" /></geometry><material name="color_L_index_intermediate_sphere2_0"><color rgba="0.5 0.8 0.8 1.0" /></material></visual><collision><origin rpy="0 0 0" xyz="0 0 0" /><geometry><sphere radius="0.007323485799133778" /></geometry><drake:proximity_properties><drake:rigid_hydroelastic /><drake:mesh_resolution_hint value="1.5" /><drake:hunt_crossley_dissipation value="1.25" /></drake:proximity_properties></collision></link><joint name="L_index_intermediate_to_L_index_intermediate_sphere2" type="fixed"><parent link="L_index_intermediate" /><child link="L_index_intermediate_sphere2" /><origin xyz="0.0036037147510796785 -0.017388980835676193 -0.00487908162176609" rpy="0 0 0" /></joint><link name="L_middle_intermediate_sphere1"><inertial><origin xyz="0 0 0" rpy="0 0 0" /><mass value="0.01" /><inertia ixx="0.001" ixy="0" ixz="0" iyy="0.001" iyz="0" izz="0.001" /></inertial><visual><origin rpy="0 0 0" xyz="0 0 0" /><geometry><sphere radius="0.005786941386759281" /></geometry><material name="color_L_middle_intermediate_sphere1_0"><color rgba="0.5 0.8 0.8 1.0" /></material></visual><collision><origin rpy="0 0 0" xyz="0 0 0" /><geometry><sphere radius="0.005786941386759281" /></geometry><drake:proximity_properties><drake:rigid_hydroelastic /><drake:mesh_resolution_hint value="1.5" /><drake:hunt_crossley_dissipation value="1.25" /></drake:proximity_properties></collision></link><joint name="L_middle_intermediate_to_L_middle_intermediate_sphere1" type="fixed"><parent link="L_middle_intermediate" /><child link="L_middle_intermediate_sphere1" /><origin xyz="-0.0010028767865151167 -0.04066188260912895 -0.0054840585216879845" rpy="0 0 0" /></joint><link name="L_middle_intermediate_sphere2"><inertial><origin xyz="0 0 0" rpy="0 0 0" /><mass value="0.01" /><inertia ixx="0.001" ixy="0" ixz="0" iyy="0.001" iyz="0" izz="0.001" /></inertial><visual><origin rpy="0 0 0" xyz="0 0 0" /><geometry><sphere radius="0.005805103108286858" /></geometry><material name="color_L_middle_intermediate_sphere2_0"><color rgba="0.5 0.8 0.8 1.0" /></material></visual><collision><origin rpy="0 0 0" xyz="0 0 0" /><geometry><sphere radius="0.005805103108286858" /></geometry><drake:proximity_properties><drake:rigid_hydroelastic /><drake:mesh_resolution_hint value="1.5" /><drake:hunt_crossley_dissipation value="1.25" /></drake:proximity_properties></collision></link><joint name="L_middle_intermediate_to_L_middle_intermediate_sphere2" type="fixed"><parent link="L_middle_intermediate" /><child link="L_middle_intermediate_sphere2" /><origin xyz="0.0035610164050012827 -0.0025492655113339424 -0.004556798376142979" rpy="0 0 0" /></joint><link name="L_middle_intermediate_sphere3"><inertial><origin xyz="0 0 0" rpy="0 0 0" /><mass value="0.01" /><inertia ixx="0.001" ixy="0" ixz="0" iyy="0.001" iyz="0" izz="0.001" /></inertial><visual><origin rpy="0 0 0" xyz="0 0 0" /><geometry><sphere radius="0.006664490792900324" /></geometry><material name="color_L_middle_intermediate_sphere3_0"><color rgba="0.5 0.8 0.8 1.0" /></material></visual><collision><origin rpy="0 0 0" xyz="0 0 0" /><geometry><sphere radius="0.006664490792900324" /></geometry><drake:proximity_properties><drake:rigid_hydroelastic /><drake:mesh_resolution_hint value="1.5" /><drake:hunt_crossley_dissipation value="1.25" /></drake:proximity_properties></collision></link><joint name="L_middle_intermediate_to_L_middle_intermediate_sphere3" type="fixed"><parent link="L_middle_intermediate" /><child link="L_middle_intermediate_sphere3" /><origin xyz="0.0017879819497466087 -0.028675775974988937 -0.004708352964371443" rpy="0 0 0" /></joint><link name="L_middle_intermediate_sphere4"><inertial><origin xyz="0 0 0" rpy="0 0 0" /><mass value="0.01" /><inertia ixx="0.001" ixy="0" ixz="0" iyy="0.001" iyz="0" izz="0.001" /></inertial><visual><origin rpy="0 0 0" xyz="0 0 0" /><geometry><sphere radius="0.007185225374996662" /></geometry><material name="color_L_middle_intermediate_sphere4_0"><color rgba="0.5 0.8 0.8 1.0" /></material></visual><collision><origin rpy="0 0 0" xyz="0 0 0" /><geometry><sphere radius="0.007185225374996662" /></geometry><drake:proximity_properties><drake:rigid_hydroelastic /><drake:mesh_resolution_hint value="1.5" /><drake:hunt_crossley_dissipation value="1.25" /></drake:proximity_properties></collision></link><joint name="L_middle_intermediate_to_L_middle_intermediate_sphere4" type="fixed"><parent link="L_middle_intermediate" /><child link="L_middle_intermediate_sphere4" /><origin xyz="0.0036796419881284237 -0.014274682849645615 -0.004483269527554512" rpy="0 0 0" /></joint><link name="L_ring_intermediate_sphere1"><inertial><origin xyz="0 0 0" rpy="0 0 0" /><mass value="0.01" /><inertia ixx="0.001" ixy="0" ixz="0" iyy="0.001" iyz="0" izz="0.001" /></inertial><visual><origin rpy="0 0 0" xyz="0 0 0" /><geometry><sphere radius="0.006459411699324846" /></geometry><material name="color_L_ring_intermediate_sphere1_0"><color rgba="0.5 0.8 0.8 1.0" /></material></visual><collision><origin rpy="0 0 0" xyz="0 0 0" /><geometry><sphere radius="0.006459411699324846" /></geometry><drake:proximity_properties><drake:rigid_hydroelastic /><drake:mesh_resolution_hint value="1.5" /><drake:hunt_crossley_dissipation value="1.25" /></drake:proximity_properties></collision></link><joint name="L_ring_intermediate_to_L_ring_intermediate_sphere1" type="fixed"><parent link="L_ring_intermediate" /><child link="L_ring_intermediate_sphere1" /><origin xyz="0.0029192029032856226 -0.022483179345726967 -0.005016305483877659" rpy="0 0 0" /></joint><link name="L_ring_intermediate_sphere2"><inertial><origin xyz="0 0 0" rpy="0 0 0" /><mass value="0.01" /><inertia ixx="0.001" ixy="0" ixz="0" iyy="0.001" iyz="0" izz="0.001" /></inertial><visual><origin rpy="0 0 0" xyz="0 0 0" /><geometry><sphere radius="0.007130422629415989" /></geometry><material name="color_L_ring_intermediate_sphere2_0"><color rgba="0.5 0.8 0.8 1.0" /></material></visual><collision><origin rpy="0 0 0" xyz="0 0 0" /><geometry><sphere radius="0.007130422629415989" /></geometry><drake:proximity_properties><drake:rigid_hydroelastic /><drake:mesh_resolution_hint value="1.5" /><drake:hunt_crossley_dissipation value="1.25" /></drake:proximity_properties></collision></link><joint name="L_ring_intermediate_to_L_ring_intermediate_sphere2" type="fixed"><parent link="L_ring_intermediate" /><child link="L_ring_intermediate_sphere2" /><origin xyz="0.003482165979221463 -0.008629822172224522 -0.004865477327257395" rpy="0 0 0" /></joint><link name="L_ring_intermediate_sphere3"><inertial><origin xyz="0 0 0" rpy="0 0 0" /><mass value="0.01" /><inertia ixx="0.001" ixy="0" ixz="0" iyy="0.001" iyz="0" izz="0.001" /></inertial><visual><origin rpy="0 0 0" xyz="0 0 0" /><geometry><sphere radius="0.006578456610441208" /></geometry><material name="color_L_ring_intermediate_sphere3_0"><color rgba="0.5 0.8 0.8 1.0" /></material></visual><collision><origin rpy="0 0 0" xyz="0 0 0" /><geometry><sphere radius="0.006578456610441208" /></geometry><drake:proximity_properties><drake:rigid_hydroelastic /><drake:mesh_resolution_hint value="1.5" /><drake:hunt_crossley_dissipation value="1.25" /></drake:proximity_properties></collision></link><joint name="L_ring_intermediate_to_L_ring_intermediate_sphere3" type="fixed"><parent link="L_ring_intermediate" /><child link="L_ring_intermediate_sphere3" /><origin xyz="-0.0005993914091959596 -0.035857703536748886 -0.005008252337574959" rpy="0 0 0" /></joint><link name="L_pinky_intermediate_sphere1"><inertial><origin xyz="0 0 0" rpy="0 0 0" /><mass value="0.01" /><inertia ixx="0.001" ixy="0" ixz="0" iyy="0.001" iyz="0" izz="0.001" /></inertial><visual><origin rpy="0 0 0" xyz="0 0 0" /><geometry><sphere radius="0.005849827546626329" /></geometry><material name="color_L_pinky_intermediate_sphere1_0"><color rgba="0.5 0.8 0.8 1.0" /></material></visual><collision><origin rpy="0 0 0" xyz="0 0 0" /><geometry><sphere radius="0.005849827546626329" /></geometry><drake:proximity_properties><drake:rigid_hydroelastic /><drake:mesh_resolution_hint value="1.5" /><drake:hunt_crossley_dissipation value="1.25" /></drake:proximity_properties></collision></link><joint name="L_pinky_intermediate_to_L_pinky_intermediate_sphere1" type="fixed"><parent link="L_pinky_intermediate" /><child link="L_pinky_intermediate_sphere1" /><origin xyz="0.002982312347739935 -0.019591975957155228 -0.0049032471142709255" rpy="0 0 0" /></joint><link name="L_pinky_intermediate_sphere2"><inertial><origin xyz="0 0 0" rpy="0 0 0" /><mass value="0.01" /><inertia ixx="0.001" ixy="0" ixz="0" iyy="0.001" iyz="0" izz="0.001" /></inertial><visual><origin rpy="0 0 0" xyz="0 0 0" /><geometry><sphere radius="0.006009695585817099" /></geometry><material name="color_L_pinky_intermediate_sphere2_0"><color rgba="0.5 0.8 0.8 1.0" /></material></visual><collision><origin rpy="0 0 0" xyz="0 0 0" /><geometry><sphere radius="0.006009695585817099" /></geometry><drake:proximity_properties><drake:rigid_hydroelastic /><drake:mesh_resolution_hint value="1.5" /><drake:hunt_crossley_dissipation value="1.25" /></drake:proximity_properties></collision></link><joint name="L_pinky_intermediate_to_L_pinky_intermediate_sphere2" type="fixed"><parent link="L_pinky_intermediate" /><child link="L_pinky_intermediate_sphere2" /><origin xyz="0.00030097775743342936 -0.03025292046368122 -0.005065583623945713" rpy="0 0 0" /></joint><link name="R_thumb_proximal_base_sphere1"><inertial><origin xyz="0 0 0" rpy="0 0 0" /><mass value="0.01" /><inertia ixx="0.001" ixy="0" ixz="0" iyy="0.001" iyz="0" izz="0.001" /></inertial><visual><origin rpy="0 0 0" xyz="0 0 0" /><geometry><sphere radius="0.0037118580657988787" /></geometry><material name="color_R_thumb_proximal_base_sphere1_0"><color rgba="0.8 0.6 0.2 1.0" /></material></visual><collision><origin rpy="0 0 0" xyz="0 0 0" /><geometry><sphere radius="0.0037118580657988787" /></geometry><drake:proximity_properties><drake:rigid_hydroelastic /><drake:mesh_resolution_hint value="1.5" /><drake:hunt_crossley_dissipation value="1.25" /></drake:proximity_properties></collision></link><joint name="R_thumb_proximal_base_to_R_thumb_proximal_base_sphere1" type="fixed"><parent link="R_thumb_proximal_base" /><child link="R_thumb_proximal_base_sphere1" /><origin xyz="0.0016578187933191657 -0.0035305458586663008 -0.004855469800531864" rpy="0 0 0" /></joint><link name="R_thumb_proximal_base_sphere2"><inertial><origin xyz="0 0 0" rpy="0 0 0" /><mass value="0.01" /><inertia ixx="0.001" ixy="0" ixz="0" iyy="0.001" iyz="0" izz="0.001" /></inertial><visual><origin rpy="0 0 0" xyz="0 0 0" /><geometry><sphere radius="0.0033626214135438204" /></geometry><material name="color_R_thumb_proximal_base_sphere2_0"><color rgba="0.8 0.6 0.2 1.0" /></material></visual><collision><origin rpy="0 0 0" xyz="0 0 0" /><geometry><sphere radius="0.0033626214135438204" /></geometry><drake:proximity_properties><drake:rigid_hydroelastic /><drake:mesh_resolution_hint value="1.5" /><drake:hunt_crossley_dissipation value="1.25" /></drake:proximity_properties></collision></link><joint name="R_thumb_proximal_base_to_R_thumb_proximal_base_sphere2" type="fixed"><parent link="R_thumb_proximal_base" /><child link="R_thumb_proximal_base_sphere2" /><origin xyz="0.0029820601921528578 -0.003702042158693075 -0.012855712324380875" rpy="0 0 0" /></joint><link name="R_thumb_proximal_base_sphere3"><inertial><origin xyz="0 0 0" rpy="0 0 0" /><mass value="0.01" /><inertia ixx="0.001" ixy="0" ixz="0" iyy="0.001" iyz="0" izz="0.001" /></inertial><visual><origin rpy="0 0 0" xyz="0 0 0" /><geometry><sphere radius="0.006698837038129568" /></geometry><material name="color_R_thumb_proximal_base_sphere3_0"><color rgba="0.8 0.6 0.2 1.0" /></material></visual><collision><origin rpy="0 0 0" xyz="0 0 0" /><geometry><sphere radius="0.006698837038129568" /></geometry><drake:proximity_properties><drake:rigid_hydroelastic /><drake:mesh_resolution_hint value="1.5" /><drake:hunt_crossley_dissipation value="1.25" /></drake:proximity_properties></collision></link><joint name="R_thumb_proximal_base_to_R_thumb_proximal_base_sphere3" type="fixed"><parent link="R_thumb_proximal_base" /><child link="R_thumb_proximal_base_sphere3" /><origin xyz="-0.006420477293431759 0.002070806687697768 -0.008076870813965797" rpy="0 0 0" /></joint><link name="R_thumb_intermediate_sphere1"><inertial><origin xyz="0 0 0" rpy="0 0 0" /><mass value="0.01" /><inertia ixx="0.001" ixy="0" ixz="0" iyy="0.001" iyz="0" izz="0.001" /></inertial><visual><origin rpy="0 0 0" xyz="0 0 0" /><geometry><sphere radius="0.01" /></geometry><material name="color_R_thumb_intermediate_sphere1_0"><color rgba="0.8 0.6 0.2 1.0" /></material></visual><collision><origin rpy="0 0 0" xyz="0 0 0" /><geometry><sphere radius="0.01" /></geometry><drake:proximity_properties><drake:rigid_hydroelastic /><drake:mesh_resolution_hint value="1.5" /><drake:hunt_crossley_dissipation value="1.25" /></drake:proximity_properties></collision></link><joint name="R_thumb_intermediate_to_R_thumb_intermediate_sphere1" type="fixed"><parent link="R_thumb_intermediate" /><child link="R_thumb_intermediate_sphere1" /><origin xyz="0 0 0" rpy="0 0 0" /></joint><link name="R_thumb_distal_sphere1"><inertial><origin xyz="0 0 0" rpy="0 0 0" /><mass value="0.01" /><inertia ixx="0.001" ixy="0" ixz="0" iyy="0.001" iyz="0" izz="0.001" /></inertial><visual><origin rpy="0 0 0" xyz="0 0 0" /><geometry><sphere radius="0.008510958403348923" /></geometry><material name="color_R_thumb_distal_sphere1_0"><color rgba="0.8 0.6 0.2 1.0" /></material></visual><collision><origin rpy="0 0 0" xyz="0 0 0" /><geometry><sphere radius="0.008510958403348923" /></geometry><drake:proximity_properties><drake:rigid_hydroelastic /><drake:mesh_resolution_hint value="1.5" /><drake:hunt_crossley_dissipation value="1.25" /></drake:proximity_properties></collision></link><joint name="R_thumb_distal_to_R_thumb_distal_sphere1" type="fixed"><parent link="R_thumb_distal" /><child link="R_thumb_distal_sphere1" /><origin xyz="0.010340743698179722 0.00678006187081337 -0.005917908623814583" rpy="0 0 0" /></joint><link name="R_thumb_distal_sphere2"><inertial><origin xyz="0 0 0" rpy="0 0 0" /><mass value="0.01" /><inertia ixx="0.001" ixy="0" ixz="0" iyy="0.001" iyz="0" izz="0.001" /></inertial><visual><origin rpy="0 0 0" xyz="0 0 0" /><geometry><sphere radius="0.0038283427711576223" /></geometry><material name="color_R_thumb_distal_sphere2_0"><color rgba="0.8 0.6 0.2 1.0" /></material></visual><collision><origin rpy="0 0 0" xyz="0 0 0" /><geometry><sphere radius="0.0038283427711576223" /></geometry><drake:proximity_properties><drake:rigid_hydroelastic /><drake:mesh_resolution_hint value="1.5" /><drake:hunt_crossley_dissipation value="1.25" /></drake:proximity_properties></collision></link><joint name="R_thumb_distal_to_R_thumb_distal_sphere2" type="fixed"><parent link="R_thumb_distal" /><child link="R_thumb_distal_sphere2" /><origin xyz="0.00671287439763546 -0.0031002573668956757 -0.00896668341010809" rpy="0 0 0" /></joint><link name="R_thumb_distal_sphere3"><inertial><origin xyz="0 0 0" rpy="0 0 0" /><mass value="0.01" /><inertia ixx="0.001" ixy="0" ixz="0" iyy="0.001" iyz="0" izz="0.001" /></inertial><visual><origin rpy="0 0 0" xyz="0 0 0" /><geometry><sphere radius="0.0031175916083157063" /></geometry><material name="color_R_thumb_distal_sphere3_0"><color rgba="0.8 0.6 0.2 1.0" /></material></visual><collision><origin rpy="0 0 0" xyz="0 0 0" /><geometry><sphere radius="0.0031175916083157063" /></geometry><drake:proximity_properties><drake:rigid_hydroelastic /><drake:mesh_resolution_hint value="1.5" /><drake:hunt_crossley_dissipation value="1.25" /></drake:proximity_properties></collision></link><joint name="R_thumb_distal_to_R_thumb_distal_sphere3" type="fixed"><parent link="R_thumb_distal" /><child link="R_thumb_distal_sphere3" /><origin xyz="0.005214046221226454 -0.004938130732625723 -0.0032111629843711853" rpy="0 0 0" /></joint><link name="R_index_intermediate_sphere1"><inertial><origin xyz="0 0 0" rpy="0 0 0" /><mass value="0.01" /><inertia ixx="0.001" ixy="0" ixz="0" iyy="0.001" iyz="0" izz="0.001" /></inertial><visual><origin rpy="0 0 0" xyz="0 0 0" /><geometry><sphere radius="0.0074013713747262955" /></geometry><material name="color_R_index_intermediate_sphere1_0"><color rgba="0.8 0.6 0.2 1.0" /></material></visual><collision><origin rpy="0 0 0" xyz="0 0 0" /><geometry><sphere radius="0.0074013713747262955" /></geometry><drake:proximity_properties><drake:rigid_hydroelastic /><drake:mesh_resolution_hint value="1.5" /><drake:hunt_crossley_dissipation value="1.25" /></drake:proximity_properties></collision></link><joint name="R_index_intermediate_to_R_index_intermediate_sphere1" type="fixed"><parent link="R_index_intermediate" /><child link="R_index_intermediate_sphere1" /><origin xyz="0.003259508404880762 0.014889992773532867 -0.005089589860290289" rpy="0 0 0" /></joint><link name="R_index_intermediate_sphere2"><inertial><origin xyz="0 0 0" rpy="0 0 0" /><mass value="0.01" /><inertia ixx="0.001" ixy="0" ixz="0" iyy="0.001" iyz="0" izz="0.001" /></inertial><visual><origin rpy="0 0 0" xyz="0 0 0" /><geometry><sphere radius="0.007389605976641178" /></geometry><material name="color_R_index_intermediate_sphere2_0"><color rgba="0.8 0.6 0.2 1.0" /></material></visual><collision><origin rpy="0 0 0" xyz="0 0 0" /><geometry><sphere radius="0.007389605976641178" /></geometry><drake:proximity_properties><drake:rigid_hydroelastic /><drake:mesh_resolution_hint value="1.5" /><drake:hunt_crossley_dissipation value="1.25" /></drake:proximity_properties></collision></link><joint name="R_index_intermediate_to_R_index_intermediate_sphere2" type="fixed"><parent link="R_index_intermediate" /><child link="R_index_intermediate_sphere2" /><origin xyz="-0.00021555309649556875 0.03390979766845703 -0.004806546028703451" rpy="0 0 0" /></joint><link name="R_middle_intermediate_sphere1"><inertial><origin xyz="0 0 0" rpy="0 0 0" /><mass value="0.01" /><inertia ixx="0.001" ixy="0" ixz="0" iyy="0.001" iyz="0" izz="0.001" /></inertial><visual><origin rpy="0 0 0" xyz="0 0 0" /><geometry><sphere radius="0.007223579566925764" /></geometry><material name="color_R_middle_intermediate_sphere1_0"><color rgba="0.8 0.6 0.2 1.0" /></material></visual><collision><origin rpy="0 0 0" xyz="0 0 0" /><geometry><sphere radius="0.007223579566925764" /></geometry><drake:proximity_properties><drake:rigid_hydroelastic /><drake:mesh_resolution_hint value="1.5" /><drake:hunt_crossley_dissipation value="1.25" /></drake:proximity_properties></collision></link><joint name="R_middle_intermediate_to_R_middle_intermediate_sphere1" type="fixed"><parent link="R_middle_intermediate" /><child link="R_middle_intermediate_sphere1" /><origin xyz="0.00337533769197762 0.005860874429345131 -0.004673752002418041" rpy="0 0 0" /></joint><link name="R_middle_intermediate_sphere2"><inertial><origin xyz="0 0 0" rpy="0 0 0" /><mass value="0.01" /><inertia ixx="0.001" ixy="0" ixz="0" iyy="0.001" iyz="0" izz="0.001" /></inertial><visual><origin rpy="0 0 0" xyz="0 0 0" /><geometry><sphere radius="0.006898466031998396" /></geometry><material name="color_R_middle_intermediate_sphere2_0"><color rgba="0.8 0.6 0.2 1.0" /></material></visual><collision><origin rpy="0 0 0" xyz="0 0 0" /><geometry><sphere radius="0.006898466031998396" /></geometry><drake:proximity_properties><drake:rigid_hydroelastic /><drake:mesh_resolution_hint value="1.5" /><drake:hunt_crossley_dissipation value="1.25" /></drake:proximity_properties></collision></link><joint name="R_middle_intermediate_to_R_middle_intermediate_sphere2" type="fixed"><parent link="R_middle_intermediate" /><child link="R_middle_intermediate_sphere2" /><origin xyz="0.0024284184910357 0.021633455529808998 -0.0051987566985189915" rpy="0 0 0" /></joint><link name="R_middle_intermediate_sphere3"><inertial><origin xyz="0 0 0" rpy="0 0 0" /><mass value="0.01" /><inertia ixx="0.001" ixy="0" ixz="0" iyy="0.001" iyz="0" izz="0.001" /></inertial><visual><origin rpy="0 0 0" xyz="0 0 0" /><geometry><sphere radius="0.006773535627871752" /></geometry><material name="color_R_middle_intermediate_sphere3_0"><color rgba="0.8 0.6 0.2 1.0" /></material></visual><collision><origin rpy="0 0 0" xyz="0 0 0" /><geometry><sphere radius="0.006773535627871752" /></geometry><drake:proximity_properties><drake:rigid_hydroelastic /><drake:mesh_resolution_hint value="1.5" /><drake:hunt_crossley_dissipation value="1.25" /></drake:proximity_properties></collision></link><joint name="R_middle_intermediate_to_R_middle_intermediate_sphere3" type="fixed"><parent link="R_middle_intermediate" /><child link="R_middle_intermediate_sphere3" /><origin xyz="-0.0009886581683531404 0.03781169280409813 -0.005100213456898928" rpy="0 0 0" /></joint><link name="R_ring_intermediate_sphere1"><inertial><origin xyz="0 0 0" rpy="0 0 0" /><mass value="0.01" /><inertia ixx="0.001" ixy="0" ixz="0" iyy="0.001" iyz="0" izz="0.001" /></inertial><visual><origin rpy="0 0 0" xyz="0 0 0" /><geometry><sphere radius="0.006815416272729635" /></geometry><material name="color_R_ring_intermediate_sphere1_0"><color rgba="0.8 0.6 0.2 1.0" /></material></visual><collision><origin rpy="0 0 0" xyz="0 0 0" /><geometry><sphere radius="0.006815416272729635" /></geometry><drake:proximity_properties><drake:rigid_hydroelastic /><drake:mesh_resolution_hint value="1.5" /><drake:hunt_crossley_dissipation value="1.25" /></drake:proximity_properties></collision></link><joint name="R_ring_intermediate_to_R_ring_intermediate_sphere1" type="fixed"><parent link="R_ring_intermediate" /><child link="R_ring_intermediate_sphere1" /><origin xyz="0.0027469911146909 0.022965531796216965 -0.004562245681881905" rpy="0 0 0" /></joint><link name="R_ring_intermediate_sphere2"><inertial><origin xyz="0 0 0" rpy="0 0 0" /><mass value="0.01" /><inertia ixx="0.001" ixy="0" ixz="0" iyy="0.001" iyz="0" izz="0.001" /></inertial><visual><origin rpy="0 0 0" xyz="0 0 0" /><geometry><sphere radius="0.006371667608618736" /></geometry><material name="color_R_ring_intermediate_sphere2_0"><color rgba="0.8 0.6 0.2 1.0" /></material></visual><collision><origin rpy="0 0 0" xyz="0 0 0" /><geometry><sphere radius="0.006371667608618736" /></geometry><drake:proximity_properties><drake:rigid_hydroelastic /><drake:mesh_resolution_hint value="1.5" /><drake:hunt_crossley_dissipation value="1.25" /></drake:proximity_properties></collision></link><joint name="R_ring_intermediate_to_R_ring_intermediate_sphere2" type="fixed"><parent link="R_ring_intermediate" /><child link="R_ring_intermediate_sphere2" /><origin xyz="-0.00012793781934306026 0.035858701914548874 -0.005560693796724081" rpy="0 0 0" /></joint><link name="R_ring_intermediate_sphere3"><inertial><origin xyz="0 0 0" rpy="0 0 0" /><mass value="0.01" /><inertia ixx="0.001" ixy="0" ixz="0" iyy="0.001" iyz="0" izz="0.001" /></inertial><visual><origin rpy="0 0 0" xyz="0 0 0" /><geometry><sphere radius="0.007074868306517601" /></geometry><material name="color_R_ring_intermediate_sphere3_0"><color rgba="0.8 0.6 0.2 1.0" /></material></visual><collision><origin rpy="0 0 0" xyz="0 0 0" /><geometry><sphere radius="0.007074868306517601" /></geometry><drake:proximity_properties><drake:rigid_hydroelastic /><drake:mesh_resolution_hint value="1.5" /><drake:hunt_crossley_dissipation value="1.25" /></drake:proximity_properties></collision></link><joint name="R_ring_intermediate_to_R_ring_intermediate_sphere3" type="fixed"><parent link="R_ring_intermediate" /><child link="R_ring_intermediate_sphere3" /><origin xyz="0.003654032712802291 0.008867047727108002 -0.004494288470596075" rpy="0 0 0" /></joint><link name="R_pinky_intermediate_sphere1"><inertial><origin xyz="0 0 0" rpy="0 0 0" /><mass value="0.01" /><inertia ixx="0.001" ixy="0" ixz="0" iyy="0.001" iyz="0" izz="0.001" /></inertial><visual><origin rpy="0 0 0" xyz="0 0 0" /><geometry><sphere radius="0.006826937198638916" /></geometry><material name="color_R_pinky_intermediate_sphere1_0"><color rgba="0.8 0.6 0.2 1.0" /></material></visual><collision><origin rpy="0 0 0" xyz="0 0 0" /><geometry><sphere radius="0.006826937198638916" /></geometry><drake:proximity_properties><drake:rigid_hydroelastic /><drake:mesh_resolution_hint value="1.5" /><drake:hunt_crossley_dissipation value="1.25" /></drake:proximity_properties></collision></link><joint name="R_pinky_intermediate_to_R_pinky_intermediate_sphere1" type="fixed"><parent link="R_pinky_intermediate" /><child link="R_pinky_intermediate_sphere1" /><origin xyz="0.0008565954049117863 0.027646128088235855 -0.004548601806163788" rpy="0 0 0" /></joint><link name="R_pinky_intermediate_sphere2"><inertial><origin xyz="0 0 0" rpy="0 0 0" /><mass value="0.01" /><inertia ixx="0.001" ixy="0" ixz="0" iyy="0.001" iyz="0" izz="0.001" /></inertial><visual><origin rpy="0 0 0" xyz="0 0 0" /><geometry><sphere radius="0.006654818542301655" /></geometry><material name="color_R_pinky_intermediate_sphere2_0"><color rgba="0.8 0.6 0.2 1.0" /></material></visual><collision><origin rpy="0 0 0" xyz="0 0 0" /><geometry><sphere radius="0.006654818542301655" /></geometry><drake:proximity_properties><drake:rigid_hydroelastic /><drake:mesh_resolution_hint value="1.5" /><drake:hunt_crossley_dissipation value="1.25" /></drake:proximity_properties></collision></link><joint name="R_pinky_intermediate_to_R_pinky_intermediate_sphere2" type="fixed"><parent link="R_pinky_intermediate" /><child link="R_pinky_intermediate_sphere2" /><origin xyz="0.0034975861199200153 0.011010302230715752 -0.005298115313053131" rpy="0 0 0" /></joint></robot>